Workbook

Sheet FT-GEI-SO-016 Informe 2023
A1: INFORME DE AUSENTISMO POR INCAPACIDAD 2023
A2: DESCRIPCIÓN | B2: ENERO | C2: FEBRERO | D2: MARZO | E2: ABRIL | F2: MAYO | G2: JUNIO | H2: JULIO | I2: AGOSTO | J2: SEPTIEMBRE | K2: OCTUBRE | L2: NOVIEMBRE | M2: DICIEMBRE | N2: TOTAL
A3: No. de Empleados | B3: 966 | C3: 984 | D3: 959 | E3: 815 | F3: 815 | G3: 829 | H3: 831 | I3: 842 | J3: 847 | K3: 844 | L3: 843 | M3: 843 | N3: =SUM(B3:M3) -> 10418
A4: Horas Hombre Trabajadas Totales - HHTT | B4: 241301 | C4: 254274 | D4: 250972 | E4: 215081 | F4: 220213 | G4: 224539 | H4: 234920 | I4: 224539 | J4: 243827 | K4: 215592 | L4: 240139 | M4: 240139 | N4: =+SUM(B4:M4) -> 2805536
A5: No. De días progamados de trabajo (No. Empleados * días mes laborados base) | B5: =+B3*20 -> 19320 | C5: =+C3*20 -> 19680 | D5: =+D3*20 -> 19180 | E5: =+E3*20 -> 16300 | F5: =+F3*20 -> 16300 | G5: =+G3*20 -> 16580 | H5: =+H3*20 -> 16620 | I5: =+I3*20 -> 16840 | ... N5: =+N3*20 -> 208360
A6: Total de días de Incapacidad EG - AC | B6: =278+30+3+14+2+37+10 -> 374 | C6: =229+3+30+9+20 -> 291 | D6: =177+15+30 -> 222 | E6: =191+4+15+30 -> 240 | F6: =174+10+2+15 -> 201 | G6: 255 | H6: 234 | I6: 182 | J6: 330 | K6: 152 | L6: 175 | M6: 71 | N6: =+SUM(B6:M6) -> 2727
A7: Número de Personal Incapacitado en el periodo por Incapacidad Común (EG -AC) | B7: =16+1+1+1+1+1 -> 21 | C7: =19+1+1+1+1 -> 23 | D7: =16+1+1 -> 18 | E7: =17+1+1+1 -> 20 | F7: =16+1+1+1 -> 19 | G7: 20 | H7: 21 | I7: 19 | J7: 17 | K7: 18 | L7: 19 | M7: 8 | N7: =+SUM(B7:M7) -> 223
A8: Total de días de Incapacidad AT | B8: 19 | C8: 0 | D8: 22 | E8: 0 | F8: 3 | G8: 0 | H8: 0 | I8: 0 | J8: 41 | K8: 0 | L8: 1 | M8: 0 | N8: =+SUM(B8:M8) -> 86
A9: Número de Personal Incapacitado en el periodo por Incapacidad laboral (AT) | B9: 1 | C9: 0 | D9: 2 | E9: 0 | F9: 1 | G9: 0 | H9: 0 | I9: 0 | J9: 1 | K9: 0 | L9: 20 | M9: 0 | N9: =+SUM(B9:M9) -> 25
A10: No. de Personas Fallecidas por EG - AC | B10: 0 | C10: 0 | D10: 0 | E10: 0 | F10: 0 | G10: 0 | H10: 0 | I10: 0 | J10: 0 | K10: 0 | L10: 0 | M10: 0 | N10: =+SUM(B10:M10) -> 0
A11: Número de casos reportados de Enfermedad Laboral | B11: 0 | C11: 0 | D11: 0 | E11: 0 | F11: 0 | G11: 0 | H11: 0 | I11: 0 | J11: 0 | K11: 0 | L11: 0 | M11: 0 | N11: 0
A12: Número de casos aprobados por la ARL como Enfermedad Laboral | B12: 0 | C12: 0 | D12: 0 | E12: 0 | F12: 0 | G12: 0 | H12: 0 | I12: 0 | J12: 0 | K12: 0 | L12: 0 | M12: 0 | N12: 0
A13: Número de casos existentes (antiguios) de Enfermedad Laboral | B13: 0 | C13: 0 | D13: 0 | E13: 0 | F13: 0 | G13: 0 | H13: 0 | I13: 0 | J13: 0 | K13: 0 | L13: 0 | M13: 0 | N13: 0
A14: Total de días de incapacidad de Enfermedad Laboral | B14: 0 | C14: 0 | D14: 0 | E14: 0 | F14: 0 | G14: 0 | H14: 0 | I14: 0 | J14: 0 | K14: 0 | L14: 0 | M14: 0 | N14: 0
A15: Tasa Global de ausentismo (EG+AC+AT+EL) | B15: =IFERROR(((B6+B8+B14)/B5),0) -> 0.020341615 | C15: =IFERROR(((C6+C8+C14)/C5),0) -> 0.014786585 | D15: =IFERROR(((D6+D8+D14)/D5),0) -> 0.012721585 | E15: =IFERROR(((E6+E8+E14)/E5),0) -> 0.014723926 | F15: =IFERROR(((F6+F8+F14)/F5),0) -> 0.012515337 | G15: =IFERROR(((G6+G8+G14)/G5),0) -> 0.015379976 | H15: =IFERROR(((H6+H8+H14)/H5),0) -> 0.014079422 | I15: =IFERROR(((I6+I8+I14)/I5),0) -> 0.010807601 | ... N15: =IFERROR(((N6+N8+N14)/N5),0) -> 0.013500672 | O15: 1072
A16: Tasa Global de ausentismo Enfermedad General o Accidente Común | B16: =IFERROR((B6/B5),0) -> 0.019358178 | C16: =IFERROR((C6/C5),0) -> 0.014786585 | D16: =IFERROR((D6/D5),0) -> 0.011574557 | E16: =IFERROR((E6/E5),0) -> 0.014723926 | F16: =IFERROR((F6/F5),0) -> 0.012331288 | G16: =IFERROR((G6/G5),0) -> 0.015379976 | H16: =IFERROR((H6/H5),0) -> 0.014079422 | I16: =IFERROR((I6/I5),0) -> 0.010807601 | ... N16: =IFERROR((N6/N5),0) -> 0.013087925
A17: Indice de Frecuencia Ausentismo | B17: =IFERROR(((B7/B4)*20000),0) -> 1.7405647 | C17: =IFERROR(((C7/C4)*20000),0) -> 1.8090721 | D17: =IFERROR(((D7/D4)*20000),0) -> 1.434423 | E17: =IFERROR(((E7/E4)*20000),0) -> 1.8597645 | F17: =IFERROR(((F7/F4)*20000),0) -> 1.725602 | G17: =IFERROR(((G7/G4)*20000),0) -> 1.7814277 | H17: =IFERROR(((H7/H4)*20000),0) -> 1.7878427 | I17: =IFERROR(((I7/I4)*20000),0) -> 1.6923563 | ... M17: =IFERROR(((M7/M4)*20000),0) -> 0.66628078 | N17: =IFERROR(((N7/N4)*240000),0) -> 19.076569
A18: Indice de Severidad Ausentismo | B18: =IFERROR(((B6/B4)*20000),0) -> 30.998628 | C18: =IFERROR(((C6/C4)*20000),0) -> 22.888695 | D18: =IFERROR(((D6/D4)*20000),0) -> 17.691217 | E18: =IFERROR(((E6/E4)*20000),0) -> 22.317174 | F18: =IFERROR(((F6/F4)*20000),0) -> 18.255053 | G18: =IFERROR(((G6/G4)*20000),0) -> 22.713203 | H18: =IFERROR(((H6/H4)*20000),0) -> 19.921675 | I18: =IFERROR(((I6/I4)*20000),0) -> 16.210992 | ... M18: =IFERROR(((M6/M4)*20000),0) -> 5.9132419 | N18: =IFERROR(((N6/N4)*240000),0) -> 233.28163
A19: Indice de General de Ausentismo | B19: =IFERROR((B7/B3),0) -> 0.02173913 | C19: =IFERROR((C7/C3),0) -> 0.023373984 | D19: =IFERROR((D7/D3),0) -> 0.018769552 | E19: =IFERROR((E7/E3),0) -> 0.024539877 | F19: =IFERROR((F7/F3),0) -> 0.023312883 | G19: =IFERROR((G7/G3),0) -> 0.024125452 | H19: =IFERROR((H7/H3),0) -> 0.025270758 | I19: =IFERROR((I7/I3),0) -> 0.022565321 | ... N19: =IFERROR((N7/N3),0) -> 0.02140526
A20: Tasa de Mortalidad por EG - AC | B20: =IFERROR(((B10/B3)*1000),0) -> 0 | C20: =IFERROR(((C10/C3)*1000),0) -> 0 | D20: =IFERROR(((D10/D3)*1000),0) -> 0 | E20: =IFERROR(((E10/E3)*1000),0) -> 0 | F20: =IFERROR(((F10/F3)*1000),0) -> 0 | G20: =IFERROR(((G10/G3)*1000),0) -> 0 | H20: =IFERROR(((H10/H3)*1000),0) -> 0 | I20: =IFERROR(((I10/I3)*1000),0) -> 0 | ... N20: =IFERROR(((N10/N3)*1000),0) -> 0
A21: Ausentismo por Cauda medica | B21: =IFERROR((((B6+B8)/B5)),0) -> 0.020341615 | C21: =IFERROR((((C6+C8)/C5)),0) -> 0.014786585 | D21: =IFERROR((((D6+D8)/D5)),0) -> 0.012721585 | E21: =IFERROR((((E6+E8)/E5)),0) -> 0.014723926 | F21: =IFERROR((((F6+F8)/F5)),0) -> 0.012515337 | G21: =IFERROR((((G6+G8)/G5)),0) -> 0.015379976 | H21: =IFERROR((((H6+H8)/H5)),0) -> 0.014079422 | I21: =IFERROR((((I6+I8)/I5)),0) -> 0.010807601 | ... M21: =IFERROR((((M6+M8)/M5)),0) -> 0.0042111507 | N21: =IFERROR((((N7+N9)/N5)),0) -> 0.0011902476 | O21: 312
A22: Incidencia por Enfermedad Laboral | B22: =IFERROR((B12/B3)*100000,0) -> 0 | C22: =IFERROR((C12/C3)*100000,0) -> 0 | D22: =IFERROR((D12/D3)*100000,0) -> 0 | E22: =IFERROR((E12/E3)*100000,0) -> 0 | F22: =IFERROR((F12/F3)*100000,0) -> 0 | G22: =IFERROR((G12/G3)*100000,0) -> 0 | H22: =IFERROR((H12/H3)*100000,0) -> 0 | I22: =IFERROR((I12/I3)*100000,0) -> 0 | ... N22: =IFERROR((N12/N3)*100000,0) -> 0 | O22: 312
A23: Prevalencia por Enfermedad Laboral | B23: =IFERROR(((B12+B13)/B3)*100000,0) -> 0 | C23: =IFERROR(((C12+C13)/C3)*100000,0) -> 0 | D23: =IFERROR(((D12+D13)/D3)*100000,0) -> 0 | E23: =IFERROR(((E12+E13)/E3)*100000,0) -> 0 | F23: =IFERROR(((F12+F13)/F3)*100000,0) -> 0 | G23: =IFERROR(((G12+G13)/G3)*100000,0) -> 0 | H23: =IFERROR(((H12+H13)/H3)*100000,0) -> 0 | I23: =IFERROR(((I12+I13)/I3)*100000,0) -> 0 | ... N23: =IFERROR(((N12+N13)/N3)*100000,0) -> 0 | O23: 312
A24: Severidad por Enfermedad Laboral | B24: =IFERROR(#REF!(B19/#REF!),0) -> 0 | C24: =IFERROR((C19/#REF!),0) -> 0 | D24: =IFERROR((D19/#REF!),0) -> 0 | E24: =IFERROR((E19/#REF!),0) -> 0 | F24: =IFERROR((F19/#REF!),0) -> 0 | G24: =IFERROR((G19/#REF!),0) -> 0 | H24: =IFERROR((H19/#REF!),0) -> 0 | I24: =IFERROR((I19/#REF!),0) -> 0 | J24: =IFERROR((J19/#REF!),0) -> 0 | ... M24: =IFERROR((M19/#REF!),0) -> 0 | N24: 1 | O24: 1072
A25: Peligros asociados al ausentismo | B25: Virus | C25: Virus | D25: Virus | E25: Virus | F25: Virus | G25: Virus
A29: ANALISIS DE INDICADORES
A30: Enero: | B30: En el mes de enero de 2023 no se presentaron casos de mortalidad por enfermedad general, ni casos de enfermedad laboral, el ausentismo por causa medica esta en 2,03% en los 19320 dias de trabajo programados al personal de la empresa para este mes. De 21 personas se presentaron incapaciad se genera un total de 374 días de ausentismo por enfermedad general o accidente común
A31: Febrero: | B31: En el mes de febrero de 2023 no se presentaron casos de mortalidad por enfermedad general, ni casos de enfermedad laboral, el ausentismo por causa medica esta en 1,48% en los 19680 dias de trabajo programados al personal de la empresa para este mes. De 23 personas se presentaron incapaciad se genera un total de 291 días de ausentismo por enfermedad general o accidente común
A32: Marzo: | B32: En el mes de marzo de 2023 no se presentaron casos de mortalidad por enfermedad general, ni casos de enfermedad laboral, el ausentismo por causa medica esta en 1,27% en los 19180 dias de trabajo programados al personal de la empresa para este mes. De 18 personas se presentaron incapaciad se genera un total de 222 días de ausentismo por enfermedad general o accidente común
A33: Abril: | B33: En el mes de abril de 2023 no se presentaron casos de mortalidad por enfermedad general, ni casos de enfermedad laboral, el ausentismo por causa medica esta en 1,47% en los 16300 dias de trabajo programados al personal de la empresa para este mes. De 20 personas se presentaron incapaciad se genera un total de 240 días de ausentismo por enfermedad general o accidente común
A34: Mayo: | B34: En el mes de mayo de 2023 no se presentaron casos de mortalidad por enfermedad general, ni casos de enfermedad laboral, el ausentismo por causa medica esta en 1,25% en los 16300 dias de trabajo programados al personal de la empresa para este mes. De 19 personas se presentaron incapaciad se genera un total de 201 días de ausentismo por enfermedad general o accidente común
A35: Junio: | B35: En el mes de junio de 2023 no se presentaron casos de mortalidad por enfermedad general, ni casos de enfermedad laboral, el ausentismo por causa medica esta en 1,54% en los 16580 dias de trabajo programados al personal de la empresa para este mes. De 20 personas se presentaron incapaciad se genera un total de 255 días de ausentismo por enfermedad general o accidente común
A36: Julio: | B36: En el mes de julio de 2023 no se presentaron casos de mortalidad por enfermedad general, ni casos de enfermedad laboral, el ausentismo por causa medica esta en 1,41% en los 16620 dias de trabajo programados al personal de la empresa para este mes. De 21 personas se presentaron incapaciad se genera un total de 234 días de ausentismo por enfermedad general o accidente común
A37: Agosto: | B37: En el mes de agosto de 2023 no se presentaron casos de mortalidad por enfermedad general, ni casos de enfermedad laboral, el ausentismo por causa medica esta en 1,08% en los 16840 dias de trabajo programados al personal de la empresa para este mes. De 19 personas se presentaron incapaciad se genera un total de 182 días de ausentismo por enfermedad general o accidente común
A38: Septiembre: | B38: En el mes de septiembre de 2023 no se presentaron casos de mortalidad por enfermedad general, ni casos de enfermedad laboral, el ausentismo por causa medica esta en 2,19% en los 16940 dias de trabajo programados al personal de la empresa para este mes. De 17 personas se presentaron incapaciad se genera un total de 330 días de ausentismo por enfermedad general o accidente común
A39: Octubre: | B39: En el mes de ooctubre de 2023 no se presentaron casos de mortalidad por enfermedad general, ni casos de enfermedad laboral, el ausentismo por causa medica esta en 0,90% en los 16880 dias de trabajo programados al personal de la empresa para este mes. De 18 personas se presentaron incapaciad se genera un total de 152 días de ausentismo por enfermedad general o accidente común
A40: Noviembre: | B40: En el mes de noviembre de 2023 no se presentaron casos de mortalidad por enfermedad general, ni casos de enfermedad laboral, el ausentismo por causa medica esta en 1,04% en los 16860 dias de trabajo programados al personal de la empresa para este mes. De 19 personas se presentaron incapaciad se genera un total de 175 días de ausentismo por enfermedad general o accidente común
A41: Diciembre: | B41: En el mes de noviembre de 2023 no se presentaron casos de mortalidad por enfermedad general, ni casos de enfermedad laboral, el ausentismo por causa medica esta en 0,42% en los 16860 dias de trabajo programados al personal de la empresa para este mes. De 8 personas se presentaron incapaciad se genera un total de 71 días de ausentismo por enfermedad general o accidente común
B50: 2021 | C50: 2020 | D50: 2019 | E50: 2018 | F50: 2017
A51: Tasa Global de ausentismo | B51: =N15 -> 0.013500672 | C51: 0.0096270062 | D51: =+N15 -> 0.013500672 | E51: 0.38 | F51: 0.14
...

Sheet FT-GEI-SO-016 Informe 2024
A1: INFORME DE AUSENTISMO POR INCAPACIDAD 2024
A2: DESCRIPCIÓN | B2: ENERO | C2: FEBRERO | D2: MARZO | E2: ABRIL | F2: MAYO | G2: JUNIO | H2: JULIO | I2: AGOSTO | J2: SEPTIEMBRE | K2: OCTUBRE | L2: NOVIEMBRE | M2: DICIEMBRE | N2: TOTAL
A3: No. de Empleados | B3: 827 | C3: 817 | D3: 795 | E3: 794 | F3: 798 | G3: 774 | H3: 824 | I3: 782 | J3: 780 | K3: 785 | L3: 775 | M3: 734 | N3: =SUM(B3:M3) -> 9485
A4: Horas Hombre Trabajadas Totales - HHTT | B4: 195263 | C4: 203265 | D4: 194562 | E4: =20445+182590 -> 203035 | F4: 202195 | G4: 187853 | H4: 194571 | I4: 199736 | J4: 196502 | K4: 196699 | L4: 185922 | M4: 196300 | N4: =+SUM(B4:M4) -> 2355903
A5: No. De días progamados de trabajo (No. Empleados * días mes laborados base) | B5: =+B3*26 -> 21502 | C5: =+C3*26 -> 21242 | D5: =+D3*26 -> 20670 | E5: =+E3*26 -> 20644 | F5: =+F3*26 -> 20748 | G5: =+G3*26 -> 20124 | H5: =+H3*26 -> 21424 | I5: =+I3*26 -> 20332 | ... M5: =+M3*26 -> 19084 | N5: =+N3*20 -> 189700
A6: Total de días de Incapacidad EG - AC | B6: 201 | C6: 168 | D6: 251 | E6: 245 | F6: 315 | G6: 255 | H6: 130 | I6: 171 | J6: 175 | K6: 179 | L6: 178 | M6: 108 | N6: =+SUM(B6:M6) -> 2376
A7: Número de Personal Incapacitado en el periodo por Incapacidad Común (EG -AC) | B7: 22 | C7: 15 | D7: 14 | E7: 22 | F7: 28 | G7: 16 | H7: 16 | I7: 12 | J7: 20 | K7: 23 | L7: 21 | M7: 13 | N7: =+SUM(B7:M7) -> 222
A8: Total de días de Incapacidad AT | B8: 0 | C8: 0 | D8: 0 | E8: 30 | F8: 37 | G8: 78 | H8: 50 | I8: 10 | J8: 8 | K8: 6 | L8: 0 | M8: 6 | N8: =+SUM(B8:M8) -> 225
A9: Número de Personal Incapacitado en el periodo por Incapacidad laboral (AT) | B9: 0 | C9: 0 | D9: 0 | E9: 1 | F9: 2 | G9: 3 | H9: 2 | I9: 1 | J9: 1 | K9: 2 | L9: 0 | M9: 1 | N9: =+SUM(B9:M9) -> 13
A10: No. de Personas Fallecidas por EG - AC | B10: 0 | C10: 0 | D10: 0 | E10: 0 | F10: 0 | G10: 0 | H10: 0 | I10: 0 | J10: 0 | K10: 0 | L10: 0 | M10: 0 | N10: =+SUM(B10:M10) -> 0
A11: Número de casos reportados de Enfermedad Laboral | B11: 0 | C11: 0 | D11: 0 | E11: 0 | F11: 0 | G11: 0 | H11: 0 | I11: 0 | J11: 0 | K11: 0 | L11: 0 | M11: 0 | N11: 0
A12: Número de casos aprobados por la ARL como Enfermedad Laboral | B12: 0 | C12: 0 | D12: 0 | E12: 0 | F12: 0 | G12: 0 | H12: 0 | I12: 0 | J12: 0 | K12: 0 | L12: 0 | M12: 0 | N12: 0
A13: Número de casos existentes (antiguios) de Enfermedad Laboral | B13: 0 | C13: 0 | D13: 0 | E13: 0 | F13: 0 | G13: 0 | H13: 0 | I13: 0 | J13: 0 | K13: 0 | L13: 0 | M13: 0 | N13: 0
A14: Total de días de incapacidad de Enfermedad Laboral | B14: 0 | C14: 0 | D14: 0 | E14: 0 | F14: 0 | G14: 0 | H14: 0 | I14: 0 | J14: 0 | K14: 0 | L14: 0 | M14: 0 | N14: 0
A15: Tasa Global de ausentismo (EG+AC+AT+EL) | B15: =IFERROR(((B6+B8+B14)/B5),0) -> 0.0093479676 | C15: =IFERROR(((C6+C8+C14)/C5),0) -> 0.0079088598 | D15: =IFERROR(((D6+D8+D14)/D5),0) -> 0.012143203 | E15: =IFERROR(((E6+E8+E14)/E5),0) -> 0.013321062 | F15: =IFERROR(((F6+F8+F14)/F5),0) -> 0.016965491 | G15: =IFERROR(((G6+G8+G14)/G5),0) -> 0.016547406 | H15: =IFERROR(((H6+H8+H14)/H5),0) -> 0.0084017924 | I15: =IFERROR(((I6+I8+I14)/I5),0) -> 0.0089022231 | ... N15: =IFERROR(((N6+N8+N14)/N5),0) -> 0.013711123 | O15: 1072
A16: Tasa Global de ausentismo Enfermedad General o Accidente Común | B16: =IFERROR((B6/B5),0) -> 0.0093479676 | C16: =IFERROR((C6/C5),0) -> 0.0079088598 | D16: =IFERROR((D6/D5),0) -> 0.012143203 | E16: =IFERROR((E6/E5),0) -> 0.011867855 | F16: =IFERROR((F6/F5),0) -> 0.015182186 | G16: =IFERROR((G6/G5),0) -> 0.012671437 | H16: =IFERROR((H6/H5),0) -> 0.0060679612 | I16: =IFERROR((I6/I5),0) -> 0.0084103876 | ... N16: =IFERROR((N6/N5),0) -> 0.01252504
A17: Indice de Frecuencia Ausentismo | B17: =IFERROR(((B7/B4)*20000),0) -> 2.2533711 | C17: =IFERROR(((C7/C4)*20000),0) -> 1.4759058 | D17: =IFERROR(((D7/D4)*20000),0) -> 1.4391299 | E17: =IFERROR(((E7/E4)*20000),0) -> 2.167114 | F17: =IFERROR(((F7/F4)*20000),0) -> 2.7696036 | G17: =IFERROR(((G7/G4)*20000),0) -> 1.7034596 | H17: =IFERROR(((H7/H4)*20000),0) -> 1.6446439 | I17: =IFERROR(((I7/I4)*20000),0) -> 1.2015861 | ... M17: =IFERROR(((M7/M4)*20000),0) -> 1.3245033 | N17: =IFERROR(((N7/N4)*240000),0) -> 22.615532
A18: Indice de Severidad Ausentismo | B18: =IFERROR(((B6/B4)*20000),0) -> 20.587618 | C18: =IFERROR(((C6/C4)*20000),0) -> 16.530145 | D18: =IFERROR(((D6/D4)*20000),0) -> 25.801544 | E18: =IFERROR(((E6/E4)*20000),0) -> 24.13377 | F18: =IFERROR(((F6/F4)*20000),0) -> 31.158041 | G18: =IFERROR(((G6/G4)*20000),0) -> 27.148888 | H18: =IFERROR(((H6/H4)*20000),0) -> 13.362731 | I18: =IFERROR(((I6/I4)*20000),0) -> 17.122602 | ... M18: =IFERROR(((M6/M4)*20000),0) -> 11.003566 | N18: =IFERROR(((N6/N4)*240000),0) -> 242.04732
A19: Indice de General de Ausentismo | B19: =IFERROR((B7/B3),0) -> 0.026602177 | C19: =IFERROR((C7/C3),0) -> 0.018359853 | D19: =IFERROR((D7/D3),0) -> 0.017610063 | E19: =IFERROR((E7/E3),0) -> 0.027707809 | F19: =IFERROR((F7/F3),0) -> 0.035087719 | G19: =IFERROR((G7/G3),0) -> 0.020671835 | H19: =IFERROR((H7/H3),0) -> 0.019417476 | I19: =IFERROR((I7/I3),0) -> 0.015345269 | ... N19: =IFERROR((N7/N3),0) -> 0.023405377
A20: Tasa de Mortalidad por EG - AC | B20: =IFERROR(((B10/B3)*1000),0) -> 0 | C20: =IFERROR(((C10/C3)*1000),0) -> 0 | D20: =IFERROR(((D10/D3)*1000),0) -> 0 | E20: =IFERROR(((E10/E3)*1000),0) -> 0 | F20: =IFERROR(((F10/F3)*1000),0) -> 0 | G20: =IFERROR(((G10/G3)*1000),0) -> 0 | H20: =IFERROR(((H10/H3)*1000),0) -> 0 | I20: =IFERROR(((I10/I3)*1000),0) -> 0 | ... N20: =IFERROR(((N10/N3)*1000),0) -> 0
A21: Ausentismo por Cauda medica | B21: =IFERROR((((B6+B8)/B5)),0) -> 0.0093479676 | C21: =IFERROR((((C6+C8)/C5)),0) -> 0.0079088598 | D21: =IFERROR((((D6+D8)/D5)),0) -> 0.012143203 | E21: =IFERROR((((E6+E8)/E5)),0) -> 0.013321062 | F21: =IFERROR((((F6+F8)/F5)),0) -> 0.016965491 | G21: =IFERROR((((G6+G8)/G5)),0) -> 0.016547406 | H21: =IFERROR((((H6+H8)/H5)),0) -> 0.0084017924 | I21: =IFERROR((((I6+I8)/I5)),0) -> 0.0089022231 | ... M21: =IFERROR((((M6+M8)/M5)),0) -> 0.0059735904 | N21: =IFERROR((((N7+N9)/N5)),0) -> 0.0012387981 | O21: 312
A22: Incidencia por Enfermedad Laboral | B22: =IFERROR((B12/B3)*100000,0) -> 0 | C22: =IFERROR((C12/C3)*100000,0) -> 0 | D22: =IFERROR((D12/D3)*100000,0) -> 0 | E22: =IFERROR((E12/E3)*100000,0) -> 0 | F22: =IFERROR((F12/F3)*100000,0) -> 0 | G22: =IFERROR((G12/G3)*100000,0) -> 0 | H22: =IFERROR((H12/H3)*100000,0) -> 0 | I22: =IFERROR((I12/I3)*100000,0) -> 0 | ... N22: =IFERROR((N12/N3)*100000,0) -> 0 | O22: 312 | T22: 1.7405647 | U22: 1.8090721 | V22: 1.434423 | W22: 1.8597645 | X22: 1.725602 | Y22: 1.7814277 | Z22: 1.7878427 | AA22: 1.6923563 | AB22: 1.3944313 | AC22: 1.6698208 | AD22: 1.5824169 | AE22: 0.66628078
A23: Prevalencia por Enfermedad Laboral | B23: =IFERROR(((B12+B13)/B3)*100000,0) -> 0 | C23: =IFERROR(((C12+C13)/C3)*100000,0) -> 0 | D23: =IFERROR(((D12+D13)/D3)*100000,0) -> 0 | E23: =IFERROR(((E12+E13)/E3)*100000,0) -> 0 | F23: =IFERROR(((F12+F13)/F3)*100000,0) -> 0 | G23: =IFERROR(((G12+G13)/G3)*100000,0) -> 0 | H23: =IFERROR(((H12+H13)/H3)*100000,0) -> 0 | I23: =IFERROR(((I12+I13)/I3)*100000,0) -> 0 | ... N23: =IFERROR(((N12+N13)/N3)*100000,0) -> 0 | O23: 312
A24: Severidad por Enfermedad Laboral | B24: =IFERROR(#REF!(B19/#REF!),0) -> 0 | C24: =IFERROR((C19/#REF!),0) -> 0 | D24: =IFERROR((D19/#REF!),0) -> 0 | E24: =IFERROR((E19/#REF!),0) -> 0 | F24: =IFERROR((F19/#REF!),0) -> 0 | G24: =IFERROR((G19/#REF!),0) -> 0 | H24: =IFERROR((H19/#REF!),0) -> 0 | I24: =IFERROR((I19/#REF!),0) -> 0 | J24: =IFERROR((J19/#REF!),0) -> 0 | ... M24: =IFERROR((M19/#REF!),0) -> 0 | N24: =IFERROR(((N13+N14)/N4)*100000,0) -> 0 | O24: 1072
A25: Peligros asociados al ausentismo | B25: Virus | C25: Virus | D25: Virus | E25: Virus | F25: Virus | G25: Virus
A29: ANALISIS DE INDICADORES
A30: Enero: | B30: En el mes de enero de 2024 no se presentaron casos de mortalidad por enfermedad general, ni casos de enfermedad laboral, el ausentismo por causa medica esta en 0,935% en los 21502 dias de trabajo programados al personal de la empresa para este mes. De 22 personas se presentaron incapacidad se genera un total de 201días de ausentismo por enfermedad general o accidente común
A31: Febrero: | B31: En el mes de febrero de 2024 no se presentaron casos de mortalidad por enfermedad general, ni casos de enfermedad laboral, el ausentismo por causa medica esta en 0,791% en los 21242 dias de trabajo programados al personal de la empresa para este mes. De 15 personas se presentaron incapacidad se genera un total de 168 días de ausentismo por enfermedad general o accidente común
A32: Marzo: | B32: En el mes de marzo de 2024 no se presentaron casos de mortalidad por enfermedad general, ni casos de enfermedad laboral, el ausentismo por causa medica esta en 1,214% en los 20670 dias de trabajo programados al personal de la empresa para este mes. De 14 personas se presentaron incapacidad se genera un total de 251 días de ausentismo por enfermedad general o accidente común
A33: Abril: | B33: En el mes de abril de 2024 no se presentaron casos de mortalidad por enfermedad general, ni casos de enfermedad laboral, el ausentismo por causa medica esta en 1,332% en los 20644 dias de trabajo programados al personal de la empresa para este mes. De 22 personas se presentaron incapacidad se genera un total de 245 días de ausentismo por enfermedad general o accidente común
A34: Mayo: | B34: En el mes de mayo de 2024 no se presentaron casos de mortalidad por enfermedad general, ni casos de enfermedad laboral, el ausentismo por causa medica esta en 1,697% en los 20740 dias de trabajo programados al personal de la empresa para este mes. De 28 personas se presentaron incapacidad se genera un total de 315 días de ausentismo por enfermedad general o accidente común
A35: Junio: | B35: En el mes de junio de 2024 no se presentaron casos de mortalidad por enfermedad general, ni casos de enfermedad laboral, el ausentismo por causa medica esta en 1,655% en los 20124 dias de trabajo programados al personal de la empresa para este mes. De 16 personas se presentaron incapacidad se genera un total de 255 días de ausentismo por enfermedad general o accidente común
A36: Julio: | B36: En el mes de julio de 2024 no se presentaron casos de mortalidad por enfermedad general, ni casos de enfermedad laboral, el ausentismo por causa medica esta en 0,840% en los 21424 dias de trabajo programados al personal de la empresa para este mes. De 16 personas se presentaron incapacidad se genera un total de 130 días de ausentismo por enfermedad general o accidente común
A37: Agosto: | B37: En el mes de agosto de 2024 no se presentaron casos de mortalidad por enfermedad general, ni casos de enfermedad laboral, el ausentismo por causa medica esta en 0,890% en los 20332 dias de trabajo programados al personal de la empresa para este mes. De 12 personas se presentaron incapacidad se genera un total de 171 días de ausentismo por enfermedad general o accidente común
A38: Septiembre: | B38: En el mes de septiembre de 2024 no se presentaron casos de mortalidad por enfermedad general, ni casos de enfermedad laboral, el ausentismo por causa medica esta en 0,902% en los 20280 dias de trabajo programados al personal de la empresa para este mes. De 20 personas se presentaron incapacidad se genera un total de 175 días de ausentismo por enfermedad general o accidente común
A39: Octubre: | B39: En el mes de octubre de 2024 no se presentaron casos de mortalidad por enfermedad general, ni casos de enfermedad laboral, el ausentismo por causa medica esta en 0,906% en los 20410 dias de trabajo programados al personal de la empresa para este mes. De 23 personas se presentaron incapacidad se genera un total de 179 días de ausentismo por enfermedad general o accidente común
A40: Noviembre: | B40: En el mes de noviembre de 2024 no se presentaron casos de mortalidad por enfermedad general, ni casos de enfermedad laboral, el ausentismo por causa medica esta en 0,883% en los 20150 dias de trabajo programados al personal de la empresa para este mes. De 21 personas se presentaron incapacidad se genera un total de 178 días de ausentismo por enfermedad general o accidente común
A41: Diciembre: | B41: En el mes de diciembre de 2024 no se presentaron casos de mortalidad por enfermedad general, ni casos de enfermedad laboral, el ausentismo por causa medica esta en 0,597% en los 19084 dias de trabajo programados al personal de la empresa para este mes. De 13 personas se presentaron incapacidad se genera un total de 108 días de ausentismo por enfermedad general o accidente común
B50: 2021 | C50: 2020 | D50: 2019 | E50: 2018 | F50: 2017
A51: Tasa Global de ausentismo | B51: =N15 -> 0.013711123 | C51: 0.0096270062 | D51: =+N15 -> 0.013711123 | E51: 0.38 | F51: 0.14
...

Sheet FT-GEI-SO-016 Informe 2025
A1: INFORME DE AUSENTISMO POR INCAPACIDAD 2025
A2: DESCRIPCIÓN | B2: 45658 | C2: 45689 | D2: MARZO | E2: ABRIL | F2: MAYO | G2: JUNIO | H2: JULIO | I2: AGOSTO | J2: SEPTIEMBRE | K2: OCTUBRE | L2: NOVIEMBRE | M2: DICIEMBRE | N2: TOTAL
A3: No. de Empleados | B3: 748 | C3: 708 | D3: 736 | E3: 746 | F3: 750 | G3: 733 | H3: 709 | I3: 702 | J3: 703 | K3: 728 | L3: 743 | M3: 715 | N3: =SUM(B3:M3) -> 8721
A4: Horas Hombre Trabajadas Totales - HHTT | B4: 180888 | C4: =17932+40318+120618 -> 178868 | D4: =17403+41056+173988 -> 232447 | E4: 232803 | F4: 187499 | G4: 187499 | H4: 187499 | I4: 187499 | J4: 172688 | K4: 172894 | L4: 177040 | M4: 176488 | N4: =+SUM(B4:M4) -> 2274112
A5: No. De días progamados de trabajo (No. Empleados * días mes laborados base) | B5: =21*B3 -> 15708 | C5: =20*C3 -> 14160 | D5: =D3*24 -> 17664 | E5: =E3*20 -> 14920 | F5: =F3*26 -> 19500 | G5: =G3*22 -> 16126 | H5: =H3*27 -> 19143 | I5: =I3*24 -> 16848 | J5: =J3*24 -> 16872 | K5: =K3*26 -> 18928 | L5: =L3*23 -> 17089 | M5: =M3*25 -> 17875 | N5: =+N3*20 -> 174420
A6: Total de días de Incapacidad EG - AC | B6: 158 | C6: 93 | D6: 178 | E6: 136 | F6: 111 | G6: 106 | H6: 119 | I6: 54 | J6: 341 | K6: 190 | L6: 321 | M6: 130 | N6: =+SUM(B6:M6) -> 1937
A7: Número de Personal Incapacitado en el periodo por Incapacidad Común (EG -AC) | B7: 16 | C7: 12 | D7: 15 | E7: 11 | F7: 11 | G7: 12 | H7: 19 | I7: 7 | J7: 20 | K7: 20 | L7: 31 | M7: 19 | N7: =+SUM(B7:M7) -> 193
A8: Total de días de Incapacidad AT | B8: 0 | C8: 2 | D8: 3 | E8: 0 | F8: 14 | G8: 0 | H8: 0 | I8: 0 | J8: 5 | K8: 33 | L8: 30 | M8: 10 | N8: =+SUM(B8:M8) -> 97
A9: Número de Personal Incapacitado en el periodo por Incapacidad laboral (AT) | B9: 0 | C9: 1 | D9: 1 | E9: 0 | F9: 1 | G9: 0 | H9: 1 | I9: 0 | J9: 1 | K9: 2 | L9: 1 | M9: 1 | N9: =+SUM(B9:M9) -> 9
A10: No. de Personas Fallecidas por EG - AC | B10: 0 | C10: 0 | D10: 0 | E10: 0 | F10: 0 | G10: 0 | H10: 0 | I10: 0 | J10: 0 | K10: 0 | L10: 0 | M10: 0 | N10: =+SUM(B10:M10) -> 0
A11: Número de casos reportados de Enfermedad Laboral | B11: 0 | C11: 0 | D11: 0 | E11: 0 | F11: 0 | G11: 0 | H11: 0 | I11: 0 | J11: 0 | K11: 0 | L11: 0 | M11: 0 | N11: 0
A12: Número de casos aprobados por la ARL como Enfermedad Laboral | B12: 0 | C12: 0 | D12: 0 | E12: 0 | F12: 0 | G12: 0 | H12: 0 | I12: 0 | J12: 0 | K12: 0 | L12: 0 | M12: 0 | N12: 0
A13: Número de casos existentes (antiguios) de Enfermedad Laboral | B13: 0 | C13: 0 | D13: 0 | E13: 0 | F13: 0 | G13: 0 | H13: 0 | I13: 0 | J13: 0 | K13: 0 | L13: 0 | M13: 0 | N13: 0
A14: Total de días de incapacidad de Enfermedad Laboral | B14: 0 | C14: 0 | D14: 0 | E14: 0 | F14: 0 | G14: 0 | H14: 0 | I14: 0 | J14: 0 | K14: 0 | L14: 0 | M14: 0 | N14: 0
A15: Tasa Global de ausentismo (EG+AC+AT+EL) | B15: =IFERROR(((B6+B8+B14)/B5),0) -> 0.010058569 | C15: =IFERROR(((C6+C8+C14)/C5),0) -> 0.0067090395 | D15: =IFERROR(((D6+D8+D14)/D5),0) -> 0.01024683 | E15: =IFERROR(((E6+I14E8+E14)/E5),0) -> 0 | F15: =IFERROR(((F6+F8+F14)/F5),0) -> 0.0064102564 | G15: =IFERROR(((G6+G8+G14)/G5),0) -> 0.0065732358 | H15: =IFERROR(((H6+H8+H14)/H5),0) -> 0.0062163715 | I15: =IFERROR(((I6+I8+I14)/I5),0) -> 0.0032051282 | J15: =IFERROR(((J6+J8+J14)/J5),0) -> 0.020507349 | K15: =IFERROR(((K6+K8+K14)/K5),0) -> 0.011781488 | L15: =IFERROR(((L6+L8+L14)/L5),0) -> 0.020539528 | M15: =IFERROR(((M6+M8+M14)/M5),0) -> 0.0078321678 | N15: =IFERROR(((N6+N8+N14)/N5),0) -> 0.011661507
A16: Tasa Global de ausentismo Enfermedad General o Accidente Común | B16: =IFERROR((B6/B5),0) -> 0.010058569 | C16: =IFERROR((C6/C5),0) -> 0.0065677966 | D16: =IFERROR((D6/D5),0) -> 0.010076993 | E16: =IFERROR((E6/E5),0) -> 0.0091152815 | F16: =IFERROR((F6/F5),0) -> 0.0056923077 | G16: =IFERROR((G6/G5),0) -> 0.0065732358 | H16: =IFERROR((H6/H5),0) -> 0.0062163715 | I16: =IFERROR((I6/I5),0) -> 0.0032051282 | ... N16: =IFERROR((N6/N5),0) -> 0.011105378
A17: Indice de Frecuencia Ausentismo | B17: =IFERROR(((B7/B4)*20000),0) -> 1.7690505 | C17: =IFERROR(((C7/C4)*20000),0) -> 1.3417716 | D17: =IFERROR(((D7/D4)*20000),0) -> 1.2906168 | E17: =IFERROR(((E7/E4)*20000),0) -> 0.945005 | F17: =IFERROR(((F7/F4)*20000),0) -> 1.1733396 | G17: =IFERROR(((G7/G4)*20000),0) -> 1.2800068 | H17: =IFERROR(((H7/H4)*20000),0) -> 2.0266775 | I17: =IFERROR(((I7/I4)*20000),0) -> 0.74667065 | ... M17: =IFERROR(((M7/M4)*20000),0) -> 2.1531209 | N17: =IFERROR(((N7/N4)*240000),0) -> 20.36839
A18: Indice de Severidad Ausentismo | B18: =IFERROR(((B6/B4)*20000),0) -> 17.469373 | C18: =IFERROR(((C6/C4)*20000),0) -> 10.39873 | D18: =IFERROR(((D6/D4)*20000),0) -> 15.315319 | E18: =IFERROR(((E6/E4)*20000),0) -> 11.683698 | F18: =IFERROR(((F6/F4)*20000),0) -> 11.840063 | G18: =IFERROR(((G6/G4)*20000),0) -> 11.306727 | H18: =IFERROR(((H6/H4)*20000),0) -> 12.693401 | I18: =IFERROR(((I6/I4)*20000),0) -> 5.7600307 | ... M18: =IFERROR(((M6/M4)*20000),0) -> 14.73188 | N18: =IFERROR(((N6/N4)*240000),0) -> 204.42265
A19: Indice de General de Ausentismo | B19: =IFERROR((B7/B3),0) -> 0.021390374 | C19: =IFERROR((C7/C3),0) -> 0.016949153 | D19: =IFERROR((D7/D3),0) -> 0.020380435 | E19: =IFERROR((E7/E3),0) -> 0.014745308 | F19: =IFERROR((F7/F3),0) -> 0.014666667 | G19: =IFERROR((G7/G3),0) -> 0.016371078 | H19: =IFERROR((H7/H3),0) -> 0.026798307 | I19: =IFERROR((I7/I3),0) -> 0.00997151 | ... N19: =IFERROR((N7/N3),0) -> 0.02213049
A20: Tasa de Mortalidad por EG - AC | B20: =IFERROR(((B10/B3)*1000),0) -> 0 | C20: =IFERROR(((C10/C3)*1000),0) -> 0 | D20: =IFERROR(((D10/D3)*1000),0) -> 0 | E20: =IFERROR(((E10/E3)*1000),0) -> 0 | F20: =IFERROR(((F10/F3)*1000),0) -> 0 | G20: =IFERROR(((G10/G3)*1000),0) -> 0 | H20: =IFERROR(((H10/H3)*1000),0) -> 0 | I20: =IFERROR(((I10/I3)*1000),0) -> 0 | ... N20: =IFERROR(((N10/N3)*1000),0) -> 0
A21: Ausentismo por Cauda medica | B21: =IFERROR((((B6+B8)/B5)),0) -> 0.010058569 | C21: =IFERROR((((C6+C8)/C5)),0) -> 0.0067090395 | D21: =IFERROR((((D6+D8)/D5)),0) -> 0.01024683 | E21: =IFERROR((((E6+E8)/E5)),0) -> 0.0091152815 | F21: =IFERROR((((F6+F8)/F5)),0) -> 0.0064102564 | G21: =IFERROR((((G6+G8)/G5)),0) -> 0.0065732358 | H21: =IFERROR((((H6+H8)/H5)),0) -> 0.0062163715 | I21: =IFERROR((((I6+I8)/I5)),0) -> 0.0032051282 | ... M21: =IFERROR((((M6+M8)/M5)),0) -> 0.0078321678 | N21: =IFERROR((((N7+N9)/N5)),0) -> 0.0011581241
A22: Incidencia por Enfermedad Laboral | B22: =IFERROR((B12/B3)*100000,0) -> 0 | C22: =IFERROR((C12/C3)*100000,0) -> 0 | D22: =IFERROR((D12/D3)*100000,0) -> 0 | E22: =IFERROR((E12/E3)*100000,0) -> 0 | F22: =IFERROR((F12/F3)*100000,0) -> 0 | G22: =IFERROR((G12/G3)*100000,0) -> 0 | H22: =IFERROR((H12/H3)*100000,0) -> 0 | I22: =IFERROR((I12/I3)*100000,0) -> 0 | ... N22: =IFERROR((N12/N3)*100000,0) -> 0
A23: Prevalencia por Enfermedad Laboral | B23: =IFERROR(((B12+B13)/B3)*100000,0) -> 0 | C23: =IFERROR(((C12+C13)/C3)*100000,0) -> 0 | D23: =IFERROR(((D12+D13)/D3)*100000,0) -> 0 | E23: =IFERROR(((E12+E13)/E3)*100000,0) -> 0 | F23: =IFERROR(((F12+F13)/F3)*100000,0) -> 0 | G23: =IFERROR(((G12+G13)/G3)*100000,0) -> 0 | H23: =IFERROR(((H12+H13)/H3)*100000,0) -> 0 | I23: =IFERROR(((I12+I13)/I3)*100000,0) -> 0 | ... N23: =IFERROR(((N12+N13)/N3)*100000,0) -> 0
A24: Severidad por Enfermedad Laboral | B24: =IFERROR(#REF!(B19/#REF!),0) -> 0 | C24: =IFERROR((C19/#REF!),0) -> 0 | D24: =IFERROR((D19/#REF!),0) -> 0 | E24: =IFERROR((E19/#REF!),0) -> 0 | F24: =IFERROR((F19/#REF!),0) -> 0 | G24: =IFERROR((G19/#REF!),0) -> 0 | H24: =IFERROR((H19/#REF!),0) -> 0 | I24: =IFERROR((I19/#REF!),0) -> 0 | J24: =IFERROR((J19/#REF!),0) -> 0 | ... M24: =IFERROR((M19/#REF!),0) -> 0 | N24: =IFERROR(((N13+N14)/N4)*100000,0) -> 0
A25: Peligros asociados al ausentismo | B25: Virus | C25: Virus | D25: Virus | E25: Virus | F25: Virus | G25: Virus
A29: ANALISIS DE INDICADORES
A30: Enero: | B30: En el mes de enero de 2025 no se presentaron casos de mortalidad por enfermedad general, ni casos de enfermedad laboral, el ausentismo por causa medica esta en 1,024% en los 15435 dias de trabajo programados al personal de la empresa para este mes. De 16 personas se presentaron incapacidad se genera un total de 158 días de ausentismo por enfermedad general o accidente común
A31: Febrero: | B31: En el mes de febrero de 2025 no se presentaron casos de mortalidad por enfermedad general, ni casos de enfermedad laboral, el ausentismo por causa medica esta en 0,581% en los 16340 dias de trabajo programados al personal de la empresa para este mes. De 12 personas se presentaron incapacidad se genera un total de 93 días de ausentismo por enfermedad general o accidente común
A32: Marzo: | B32: En el mes de marzo de 2025 no se presentaron casos de mortalidad por enfermedad general, ni casos de enfermedad laboral, el ausentismo por causa medica esta en 1,025% en los 17664 dias de trabajo programados al personal de la empresa para este mes. De 15 personas se presentaron incapacidad se genera un total de 178 días de ausentismo por enfermedad general o accidente común
A33: Abril: | B33: En el mes de abril de 2025 no se presentaron casos de mortalidad por enfermedad general, ni casos de enfermedad laboral, el ausentismo por causa medica esta en 0,912% en los 14920 dias de trabajo programados al personal de la empresa para este mes. De 11 personas se presentaron incapacidad se genera un total de 136 días de ausentismo por enfermedad general o accidente común
A34: Mayo: | B34: En el mes de mayo de 2025 no se presentaron casos de mortalidad por enfermedad general, ni casos de enfermedad laboral, el ausentismo por causa medica esta en 0,694% en los 18000 dias de trabajo programados al personal de la empresa para este mes. De 11 personas se presentaron incapacidad se genera un total de 111 días de ausentismo por enfermedad general o accidente común
A35: Junio: | B35: En el mes de junio de 2025 no se presentaron casos de mortalidad por enfermedad general, ni casos de enfermedad laboral, el ausentismo por causa medica esta en 0,669% en los 15840 dias de trabajo programados al personal de la empresa para este mes. De 12 personas se presentaron incapacidad se genera un total de 106 días de ausentismo por enfermedad general o accidente común
A36: Julio: | B36: En el mes de julio de 2025 no se presentaron casos de mortalidad por enfermedad general, ni casos de enfermedad laboral, el ausentismo por causa medica esta en 0,632% en los 18819 dias de trabajo programados al personal de la empresa para este mes. De 19 personas se presentaron incapacidad se genera un total de 95 días de ausentismo por enfermedad general o accidente común.
A37: Agosto: | B37: En el mes de Agosto de 2025 no se presentaron casos de mortalidad por enfermedad general, ni casos de enfermedad laboral, el ausentismo por causa medica esta en 0,326% en los 16560 dias de trabajo programados al personal de la empresa para este mes. De 7 personas se presentaron incapacidad se genera un total de 54 días de ausentismo por enfermedad general o accidente común.
A38: Septiembre: | B38: En el mes de Septiembre de 2025 no se presentaron casos de mortalidad por enfermedad general, ni casos de enfermedad laboral, el ausentismo por causa medica esta en 2,051% en los 16872 dias de trabajo programados al personal de la empresa para este mes. De 20 personas se presentaron incapacidad se genera un total de 341 días de ausentismo por enfermedad general o accidente común.
A39: Octubre: | B39: En el mes de Octubre de 2025 no se presentaron casos de mortalidad por enfermedad general, ni casos de enfermedad laboral, el ausentismo por causa medica esta en 1,178% en los 18928 dias de trabajo programados al personal de la empresa para este mes. De 20 personas se presentaron incapacidad se genera un total de 190 días de ausentismo por enfermedad general o accidente común.
A40: Noviembre: | B40: En el mes de Noviembre de 2025 no se presentaron casos de mortalidad por enfermedad general, ni casos de enfermedad laboral, el ausentismo por causa medica esta en 2,054% en los 17089 dias de trabajo programados al personal de la empresa para este mes. De 31 personas se presentaron incapacidad se genera un total de 321 días de ausentismo por enfermedad general o accidente común.
A41: Diciembre: | B41: En el mes de Diciembre de 2025 no se presentaron casos de mortalidad por enfermedad general, ni casos de enfermedad laboral, el ausentismo por causa medica esta en 0,783% en los 17875 dias de trabajo programados al personal de la empresa para este mes. De 19 personas se presentaron incapacidad se genera un total de 130 días de ausentismo por enfermedad general o accidente común.
B50: 2021 | C50: 2020 | D50: 2019 | E50: 2018 | F50: 2017
A51: Tasa Global de ausentismo | B51: =N15 -> 0.011661507 | C51: 0.0096270062 | D51: =+N15 -> 0.011661507 | E51: 0.38 | F51: 0.14
...

Sheet FT-GEI-SO-016 Informe 2026
A1: INFORME DE AUSENTISMO POR INCAPACIDAD 2026
A2: DESCRIPCIÓN | B2: 45658 | C2: 45689 | D2: MARZO | E2: ABRIL | F2: MAYO | G2: JUNIO | H2: JULIO | I2: AGOSTO | J2: SEPTIEMBRE | K2: OCTUBRE | L2: NOVIEMBRE | M2: DICIEMBRE | N2: TOTAL
A3: No. de Empleados | B3: 714 | C3: 713 | D3: 698 | E3: 710 | F3: 688 | N3: =SUM(B3:M3) -> 3523
A4: Horas Hombre Trabajadas Totales - HHTT | B4: =17159+43383+101180 -> 161722 | C4: =17804+44116+107946 -> 169866 | D4: =17804+44116+107946 -> 169866 | E4: =17804+44116+107946 -> 169866 | F4: 166597 | N4: =+SUM(B4:M4) -> 837917
A5: No. De días progamados de trabajo (No. Empleados * días mes laborados base) | B5: =25*B3 -> 17850 | C5: =24*C3 -> 17112 | D5: =D3*25 -> 17450 | E5: =24*E3 -> 17040 | F5: =F3*23 -> 15824 | N5: =+N3*20 -> 70460
A6: Total de días de Incapacidad EG - AC | B6: 137 | C6: =195 + 69 -> 264 | D6: =178+80 -> 258 | E6: =134+95 -> 229 | F6: =92+86 -> 178 | N6: =+SUM(B6:M6) -> 1066 | Q6: ANALIZO COLUMNA N Incapacidad DEJANDO SOLO LOS QUE Inc. Enfermedad general, ANALIZO COLUMAN V Periodo inicial y COLUMNA Y Periodo final Y SUMO LOS DATOS NUMERICOS QUE ESTAN EN LA COLUMNA W Dias Y COLUMNA Z Dias
A7: Número de Personal Incapacitado en el periodo por Incapacidad Común (EG -AC) | B7: 19 | C7: 23 | D7: 20 | E7: 18 | F7: 20 | N7: =+SUM(B7:M7) -> 100 | Q7: ANALIZO COLUMNA N Incapacidad DEJANDO SOLO LOS QUE Inc. Enfermedad general Y VOY LA COLUMNA D Cedula PARA IDENTIFICAR LA REPETITIVIDAD EN CEDULAS Y SUPRIMIR LAS REPETIDAS PARA CONTAR EL NUMERO DE TRABAJADORES QUE REPORTARON INCAPACIDAD
A8: Total de días de Incapacidad AT | B8: 24 | C8: 27 | D8: =8+27 -> 35 | E8: 1 | F8: 4 | N8: =+SUM(B8:M8) -> 91 | Q8: ANALIZO COLUMNA N Incapacidad DEJANDO SOLO LOS QUE Inc. Accidente Trabajo, ANALIZO COLUMAN V Periodo inicial y COLUMNA Y Periodo final Y SUMO LOS DATOS NUMERICOS QUE ESTAN EN LA COLUMNA W Dias Y COLUMNA Z Dias
A9: Número de Personal Incapacitado en el periodo por Incapacidad laboral (AT) | B9: 3 | C9: 2 | D9: 3 | E9: 1 | F9: 1 | N9: =+SUM(B9:M9) -> 10 | Q9: ANALIZO COLUMNA N Incapacidad DEJANDO SOLO LOS QUE Inc. Accidente Trabajo Y VOY LA COLUMNA D Cedula PARA IDENTIFICAR LA REPETITIVIDAD EN CEDULAS Y SUPRIMIR LAS REPETIDAS PARA CONTAR EL NUMERO DE TRABAJADORES QUE REPORTARON INCAPACIDAD
A10: No. de Personas Fallecidas por EG - AC | B10: 0 | C10: 0 | D10: 0 | E10: 0 | F10: 0 | N10: =+SUM(B10:M10) -> 0 | Q10: COLUMAN T ( TIPO INCAPACIDAD) | R10: Agregar a item en web FALLECIDO
A11: Número de casos reportados de Enfermedad Laboral | B11: 0 | C11: 0 | D11: 0 | E11: 0 | F11: 0 | N11: 0 | Q11: COLUMAN N (INCAPACIDAD) | R11: Agregar a item en web Inc. Enfermedad Laboral
A12: Número de casos aprobados por la ARL como Enfermedad Laboral | B12: 0 | C12: 0 | D12: 0 | E12: 0 | F12: 0 | N12: 0 | Q12: EDITABLES
A13: Número de casos existentes (antiguios) de Enfermedad Laboral | B13: 0 | C13: 0 | D13: 0 | E13: 0 | F13: 0 | N13: 0 | Q13: EDITABLES
A14: Total de días de incapacidad de Enfermedad Laboral | B14: 0 | C14: 0 | D14: 0 | E14: 0 | F14: 0 | N14: 0 | Q14: COLUMAN N (INCAPACIDAD) SALE DE LA SUMATORIA DE Nro. Dias Incapacidad QUE ESTA EN LA COLUMNA O | R14: Agregar a item en web Inc. Enfermedad Laboral
A15: Tasa Global de ausentismo (EG+AC+AT+EL) | B15: =IFERROR(((B6+B8+B14)/B5),0) -> 0.0090196078 | C15: =IFERROR(((C6+C8+C14)/C5),0) -> 0.01700561 | D15: =IFERROR(((D6+D8+D14)/D5),0) -> 0.016790831 | E15: =IFERROR(((E6+I14E8+E14)/E5),0) -> 0 | F15: =IFERROR(((F6+F8+F14)/F5),0) -> 0.011501517 | G15: =IFERROR(((G6+G8+G14)/G5),0) -> 0 | H15: =IFERROR(((H6+H8+H14)/H5),0) -> 0 | I15: =IFERROR(((I6+I8+I14)/I5),0) -> 0 | J15: =IFERROR(((J6+J8+J14)/J5),0) -> 0 | K15: =IFERROR(((K6+K8+K14)/K5),0) -> 0 | L15: =IFERROR(((L6+L8+L14)/L5),0) -> 0 | M15: =IFERROR(((M6+M8+M14)/M5),0) -> 0 | N15: =IFERROR(((N6+N8+N14)/N5),0) -> 0.016420664
A16: Tasa Global de ausentismo Enfermedad General o Accidente Común | B16: =IFERROR((B6/B5),0) -> 0.00767507 | C16: =IFERROR((C6/C5),0) -> 0.01542777 | D16: =IFERROR((D6/D5),0) -> 0.0147851 | E16: =IFERROR((E6/E5),0) -> 0.013438967 | F16: =IFERROR((F6/F5),0) -> 0.011248736 | G16: =IFERROR((G6/G5),0) -> 0 | H16: =IFERROR((H6/H5),0) -> 0 | I16: =IFERROR((I6/I5),0) -> 0 | ... N16: =IFERROR((N6/N5),0) -> 0.015129151
A17: Indice de Frecuencia Ausentismo | B17: =IFERROR(((B7/B4)*20000),0) -> 2.3497112 | C17: =IFERROR(((C7/C4)*20000),0) -> 2.7080169 | D17: =IFERROR(((D7/D4)*20000),0) -> 2.3547973 | E17: =IFERROR(((E7/E4)*20000),0) -> 2.1193176 | F17: =IFERROR(((F7/F4)*20000),0) -> 2.4010036 | G17: =IFERROR(((G7/G4)*20000),0) -> 0 | H17: =IFERROR(((H7/H4)*20000),0) -> 0 | I17: =IFERROR(((I7/I4)*20000),0) -> 0 | ... M17: =IFERROR(((M7/M4)*20000),0) -> 0 | N17: =IFERROR(((N7/N4)*240000),0) -> 28.642455
A18: Indice de Severidad Ausentismo | B18: =IFERROR(((B6/B4)*20000),0) -> 16.942655 | C18: =IFERROR(((C6/C4)*20000),0) -> 31.083325 | D18: =IFERROR(((D6/D4)*20000),0) -> 30.376885 | E18: =IFERROR(((E6/E4)*20000),0) -> 26.962429 | F18: =IFERROR(((F6/F4)*20000),0) -> 21.368932 | G18: =IFERROR(((G6/G4)*20000),0) -> 0 | H18: =IFERROR(((H6/H4)*20000),0) -> 0 | I18: =IFERROR(((I6/I4)*20000),0) -> 0 | ... M18: =IFERROR(((M6/M4)*20000),0) -> 0 | N18: =IFERROR(((N6/N4)*240000),0) -> 305.32857
A19: Indice de General de Ausentismo | B19: =IFERROR((B7/B3),0) -> 0.026610644 | C19: =IFERROR((C7/C3),0) -> 0.032258065 | D19: =IFERROR((D7/D3),0) -> 0.028653295 | E19: =IFERROR((E7/E3),0) -> 0.025352113 | F19: =IFERROR((F7/F3),0) -> 0.029069767 | G19: =IFERROR((G7/G3),0) -> 0 | H19: =IFERROR((H7/H3),0) -> 0 | I19: =IFERROR((I7/I3),0) -> 0 | ... N19: =IFERROR((N7/N3),0) -> 0.028384899
A20: Tasa de Mortalidad por EG - AC | B20: =IFERROR(((B10/B3)*1000),0) -> 0 | C20: =IFERROR(((C10/C3)*1000),0) -> 0 | D20: =IFERROR(((D10/D3)*1000),0) -> 0 | E20: =IFERROR(((E10/E3)*1000),0) -> 0 | F20: =IFERROR(((F10/F3)*1000),0) -> 0 | G20: =IFERROR(((G10/G3)*1000),0) -> 0 | H20: =IFERROR(((H10/H3)*1000),0) -> 0 | I20: =IFERROR(((I10/I3)*1000),0) -> 0 | ... N20: =IFERROR(((N10/N3)*1000),0) -> 0
A21: Ausentismo por Cauda medica | B21: =IFERROR((((B6+B8)/B5)),0) -> 0.0090196078 | C21: =IFERROR((((C6+C8)/C5)),0) -> 0.01700561 | D21: =IFERROR((((D6+D8)/D5)),0) -> 0.016790831 | E21: =IFERROR((((E6+E8)/E5)),0) -> 0.013497653 | F21: =IFERROR((((F6+F8)/F5)),0) -> 0.011501517 | G21: =IFERROR((((G6+G8)/G5)),0) -> 0 | H21: =IFERROR((((H6+H8)/H5)),0) -> 0 | I21: =IFERROR((((I6+I8)/I5)),0) -> 0 | ... M21: =IFERROR((((M6+M8)/M5)),0) -> 0 | N21: =IFERROR((((N7+N9)/N5)),0) -> 0.0015611695
A22: Incidencia por Enfermedad Laboral | B22: =IFERROR((B12/B3)*100000,0) -> 0 | C22: =IFERROR((C12/C3)*100000,0) -> 0 | D22: =IFERROR((D12/D3)*100000,0) -> 0 | E22: =IFERROR((E12/E3)*100000,0) -> 0 | F22: =IFERROR((F12/F3)*100000,0) -> 0 | G22: =IFERROR((G12/G3)*100000,0) -> 0 | H22: =IFERROR((H12/H3)*100000,0) -> 0 | I22: =IFERROR((I12/I3)*100000,0) -> 0 | ... N22: =IFERROR((N12/N3)*100000,0) -> 0
A23: Prevalencia por Enfermedad Laboral | B23: =IFERROR(((B12+B13)/B3)*100000,0) -> 0 | C23: =IFERROR(((C12+C13)/C3)*100000,0) -> 0 | D23: =IFERROR(((D12+D13)/D3)*100000,0) -> 0 | E23: =IFERROR(((E12+E13)/E3)*100000,0) -> 0 | F23: =IFERROR(((F12+F13)/F3)*100000,0) -> 0 | G23: =IFERROR(((G12+G13)/G3)*100000,0) -> 0 | H23: =IFERROR(((H12+H13)/H3)*100000,0) -> 0 | I23: =IFERROR(((I12+I13)/I3)*100000,0) -> 0 | ... N23: =IFERROR(((N12+N13)/N3)*100000,0) -> 0
A24: Severidad por Enfermedad Laboral | B24: =IFERROR(#REF!(B19/#REF!),0) -> 0 | C24: =IFERROR((C19/#REF!),0) -> 0 | D24: =IFERROR((D19/#REF!),0) -> 0 | E24: =IFERROR((E19/#REF!),0) -> 0 | F24: =IFERROR((F19/#REF!),0) -> 0 | G24: =IFERROR((G19/#REF!),0) -> 0 | H24: =IFERROR((H19/#REF!),0) -> 0 | I24: =IFERROR((I19/#REF!),0) -> 0 | J24: =IFERROR((J19/#REF!),0) -> 0 | ... M24: =IFERROR((M19/#REF!),0) -> 0 | N24: =IFERROR(((N13+N14)/N4)*100000,0) -> 0
A25: Peligros asociados al ausentismo | B25: Virus | C25: Virus | D25: Virus | E25: Virus | F25: Virus | G25: Virus
A29: ANALISIS DE INDICADORES
A30: Enero: | B30: En el mes de enero de 2026 no se presentaron casos de mortalidad por enfermedad general, ni casos de enfermedad laboral, el ausentismo por causa medica esta en 1,434% en los 17850 dias de trabajo programados al personal de la empresa para este mes. De 26 personas se presentaron incapacidad se genera un total de 206 días de ausentismo por enfermedad general o accidente común
A31: Febrero: | B31: En el mes de febrero de 2026 no se presentaron casos de mortalidad por enfermedad general, ni casos de enfermedad laboral, el ausentismo por causa medica esta en 1,484% en los 17112 dias de trabajo programados al personal de la empresa para este mes. De 21 personas se presentaron incapacidad se genera un total de 207 días de ausentismo por enfermedad general o accidente común
A32: Marzo: | B32: En el mes de marzo de 2026 no se presentaron casos de mortalidad por enfermedad general, ni casos de enfermedad laboral, el ausentismo por causa medica esta en 1,885% en los 17450 dias de trabajo programados al personal de la empresa para este mes. De 26 personas se presentaron incapacidad se genera un total de 282 días de ausentismo por enfermedad general o accidente común
A33: Abril: | B33: En el mes de abril de 2026 no se presentaron casos de mortalidad por enfermedad general, ni casos de enfermedad laboral, el ausentismo por causa medica esta en 1,015% en los 17040 dias de trabajo programados al personal de la empresa para este mes. De 19 personas se presentaron incapacidad se genera un total de 172 días de ausentismo por enfermedad general o accidente común
A34: Mayo:
A35: Junio:
A36: Julio:
A37: Agosto:
A38: Septiembre:
A39: Octubre:
A40: Noviembre:
A41: Diciembre:
B50: 2021 | C50: 2020 | D50: 2019 | E50: 2018 | F50: 2017
A51: Tasa Global de ausentismo | B51: =N15 -> 0.016420664 | C51: 0.0096270062 | D51: =+N15 -> 0.016420664 | E51: 0.38 | F51: 0.14
...

Sheet BD Reporte Incapacidades
A1: Fecha de incapacidad | B1: Mes | C1: Año | D1: Cedula | E1: Nombre del Empleado | F1: Genero | G1: Entidad salud que cubre la atención | H1: ENTIDAD QUE PAGA LA INCAPACIDAD | I1: Tipo de Contrato | J1: Cargo | K1: fecha de ingreso a la empresa | L1: Contrato / Cliente | M1: Ciudad de Agencia | N1: Incapacidad | O1: Nro. Dias Incapacidad | P1: Fecha Inicio | Q1: Fecha Fin | R1: DX CIE10 | S1: Descripción DX | T1: Tipo incapacidad | U1: Periodo Efectivo | V1: Periodo inicial | W1: dias | X1: Periodo siguiente | Y1: Periodo final | Z1: dias | AA1: REQUISITO PARA RETOOMA DE LABORES
A2: 44197 | B2: =+MONTH(A2) -> 1 | C2: =+YEAR(A2) -> 2021 | D2: 8458969 | E2: GUILLERMO ALONSO URIBE RIVERA | F2: Masculino | G2: SALUD TOTAL | H2: La EPS | I2: TERCEROS | J2: Conductor | K2: 43082 | L2: EMTELCO MEDELLIN | M2: MEDELLIN | N2: Inc. Enfermedad general | O2: 7 | P2: 44197 | Q2: 44203 | R2: U071 | S2: =VLOOKUP($R2,DX!$A$1:$B$13005,2,FALSE) -> COVID-19 (virus identificado) | T2: PRORROGA
A3: 44197 | B3: =+MONTH(A3) -> 1 | C3: =+YEAR(A3) -> 2021 | D3: 10029456 | E3: ERNESTO DE JESUS TANGARIFE TABARES | F3: Masculino | G3: SALUD TOTAL | H3: La Empresa 2 días el resto de días la EPS | I3: TERCEROS | J3: Conductor | K3: 44092 | L3: EMTELCO PEREIRA | M3: PEREIRA | N3: Inc. Enfermedad general | O3: 6 | P3: 44197 | Q3: 44202 | R3: Z208 | S3: =VLOOKUP($R3,DX!$A$1:$B$13005,2,FALSE) -> Contacto con y exposición a otras enfermedades transmisibles | T3: INICIAL
A4: 44197 | B4: =+MONTH(A4) -> 1 | C4: =+YEAR(A4) -> 2021 | D4: 1020423463 | E4: HENRY DE JESUS HIDALGO MENDEZ | F4: Masculino | G4: EPS SURA | H4: La Empresa 2 días el resto de días la EPS | I4: TERCEROS | J4: Conductor | K4: 43983 | L4: JARDIN BOTANICO | M4: MEDELLIN | N4: Inc. Enfermedad general | O4: 5 | P4: 44197 | Q4: 44317 | R4: U071 | S4: =VLOOKUP($R4,DX!$A$1:$B$13005,2,FALSE) -> COVID-19 (virus identificado) | T4: INICIAL
A5: 44200 | B5: =+MONTH(A5) -> 1 | C5: =+YEAR(A5) -> 2021 | D5: 71654020 | E5: WILSON ANIBAL GARCIA ROJAS | F5: Masculino | G5: EPS SURA | H5: La Empresa | I5: FLOTA PROPIA | J5: Conductor | K5: 42079 | L5: FLOTA PROPIA | M5: MEDELLIN | N5: Inc. Enfermedad general | O5: 1 | P5: 44200 | Q5: 44200 | R5: H811 | S5: =VLOOKUP($R5,DX!$A$1:$B$13005,2,FALSE) -> VERTIGO PAROXISTICO BENIGNO | T5: INICIAL
A6: 44200 | B6: =+MONTH(A6) -> 1 | C6: =+YEAR(A6) -> 2021 | D6: 71669266 | E6: GIOVANY RESTREPO ROLDAN | F6: Masculino | G6: EPS SURA | H6: La Empresa 2 días el resto de días la EPS | I6: FLOTA PROPIA | J6: Conductor | K6: 42780 | L6: FLOTA PROPIA | M6: MEDELLIN | N6: Inc. Enfermedad general | O6: 3 | P6: 44200 | Q6: 44202 | R6: U072 | S6: =VLOOKUP($R6,DX!$A$1:$B$13005,2,FALSE) -> COVID-19 (virus no identificado) | T6: INICIAL
A7: 44200 | B7: =+MONTH(A7) -> 1 | C7: =+YEAR(A7) -> 2021 | D7: 1020407916 | E7: LUIS ANGEL PATIÑO AGUDELO | F7: Masculino | G7: NUEVA EPS | H7: La EPS | I7: TERCEROS | J7: Conductor | K7: 43274 | L7: EPM | M7: MEDELLIN | N7: Inc. Enfermedad general | O7: 30 | P7: 44200 | Q7: 44229 | R7: M179 | S7: =VLOOKUP($R7,DX!$A$1:$B$13005,2,FALSE) -> GONARTROSIS, NO ESPECIFICADA | T7: PRORROGA | AA7: REQUIERE POST INCAPACIDAD
A8: 44202 | B8: =+MONTH(A8) -> 1 | C8: =+YEAR(A8) -> 2021 | D8: 43382074 | E8: LILIANA ISABEL OROZCO OSSA | F8: Femenino | G8: EPS SURA | H8: La Empresa 2 días el resto de días la EPS | I8: ADMINISTRATIVOS | J8: Servicios Generales | K8: 43564 | L8: ADMINISTRATIVOS EMPRESTUR | M8: PEREIRA | N8: Inc. Enfermedad general | O8: 3 | P8: 44202 | Q8: 44204 | R8: U072 | S8: =VLOOKUP($R8,DX!$A$1:$B$13005,2,FALSE) -> COVID-19 (virus no identificado) | T8: INICIAL | AA8: NO REQUIERE POST INCAPACIDAD
A9: 44202 | B9: =+MONTH(A9) -> 1 | C9: =+YEAR(A9) -> 2021 | D9: 1040045426 | E9: YULIANA SERNA OCAMPO | F9: Masculino | G9: EPS SURA | H9: La Empresa 2 días el resto de días la EPS | I9: ADMINISTRATIVOS | J9: Servicios Generales | K9: 44110 | L9: ADMINISTRATIVOS EMPRESTUR | M9: MEDELLIN | N9: Inc. Enfermedad general | O9: 3 | P9: 44202 | Q9: 44204 | R9: U072 | S9: =VLOOKUP($R9,DX!$A$1:$B$13005,2,FALSE) -> COVID-19 (virus no identificado) | T9: INICIAL | AA9: NO REQUIERE POST INCAPACIDAD
A10: 44204 | B10: =+MONTH(A10) -> 1 | C10: =+YEAR(A10) -> 2021 | D10: 98584332 | E10: JIMY EDISON DURANGO OSORIO | F10: Masculino | G10: COOMEVA EPS | H10: La Empresa 2 días el resto de días la EPS | I10: TERCEROS | J10: Conductor | K10: 43626 | L10: EPM | M10: MEDELLIN | N10: Inc. Enfermedad general | O10: 5 | P10: 44204 | Q10: 44208 | R10: U072 | S10: =VLOOKUP($R10,DX!$A$1:$B$13005,2,FALSE) -> COVID-19 (virus no identificado) | T10: INICIAL | AA10: NO REQUIERE POST INCAPACIDAD
A11: 44205 | B11: =+MONTH(A11) -> 1 | C11: =+YEAR(A11) -> 2021 | D11: 15451683 | E11: DANIEL DARIO RODRIGUEZ SALCEDO | F11: Masculino | G11: SAVIA SALUD | H11: La Empresa 2 días el resto de días la EPS | I11: TERCEROS | J11: Conductor | K11: 44068 | L11: EPM | M11: MEDELLIN | N11: Inc. Enfermedad general | O11: 14 | P11: 44205 | Q11: 44218 | R11: U071 | S11: =VLOOKUP($R11,DX!$A$1:$B$13005,2,FALSE) -> COVID-19 (virus identificado) | T11: INICIAL | AA11: NO REQUIERE POST INCAPACIDAD
A12: 44205 | B12: =+MONTH(A12) -> 1 | C12: =+YEAR(A12) -> 2021 | D12: 43382074 | E12: LILIANA ISABEL OROZCO OSSA | F12: Femenino | G12: EPS SURA | H12: La EPS | I12: ADMINISTRATIVOS | J12: Servicios Generales | K12: 43564 | L12: ADMINISTRATIVOS EMPRESTUR | M12: MEDELLIN | N12: Inc. Enfermedad general | O12: 6 | P12: 44205 | Q12: 44210 | R12: U071 | S12: =VLOOKUP($R12,DX!$A$1:$B$13005,2,FALSE) -> COVID-19 (virus identificado) | T12: PRORROGA | AA12: NO REQUIERE POST INCAPACIDAD
A13: 44205 | B13: =+MONTH(A13) -> 1 | C13: =+YEAR(A13) -> 2021 | D13: 71002658 | E13: WILSON DE JESUS BURITICA BUITRAGO | F13: Masculino | G13: SAVIA SALUD | H13: La Empresa 2 días el resto de días la EPS | I13: TERCEROS | J13: Conductor | K13: 43626 | L13: EPM | M13: MEDELLIN | N13: Licencia Paternidad | O13: 8 | P13: 44205 | Q13: 44212 | R13: 2 | S13: =VLOOKUP($R13,DX!$A$1:$B$13005,2,FALSE) -> Licencia Paternidad | T13: INICIAL | AA13: NO REQUIERE POST INCAPACIDAD
A14: 44207 | B14: =+MONTH(A14) -> 1 | C14: =+YEAR(A14) -> 2021 | D14: 8431066 | E14: JOHN FREDY CASTAÑEDA BEDOYA | F14: Masculino | G14: EPS SURA | H14: La Empresa 2 días el resto de días la EPS | I14: FLOTA PROPIA | J14: Conductor | K14: 43787 | L14: FLOTA PROPIA | M14: MEDELLIN | N14: Inc. Enfermedad general | O14: 3 | P14: 44207 | Q14: 44209 | R14: S518 | S14: =VLOOKUP($R14,DX!$A$1:$B$13005,2,FALSE) -> HERIDA DE OTRAS PARTES DEL ANTEBRAZO | T14: INICIAL | AA14: NO REQUIERE POST INCAPACIDAD
A15: 44208 | B15: =+MONTH(A15) -> 1 | C15: =+YEAR(A15) -> 2021 | D15: 71639035 | E15: JHON FREDY HERNANDEZ TEJADA | F15: Masculino | G15: EPS SURA | H15: La Empresa 2 días el resto de días la EPS | I15: TERCEROS | J15: Conductor | K15: 44097 | L15: CORPORACIÓN AYUDA HUMANITARIA | M15: MEDELLIN | N15: Inc. Enfermedad general | O15: 3 | P15: 44208 | Q15: 44210 | R15: U072 | S15: =VLOOKUP($R15,DX!$A$1:$B$13005,2,FALSE) -> COVID-19 (virus no identificado) | T15: INICIAL | AA15: NO REQUIERE POST INCAPACIDAD
A16: 44209 | B16: =+MONTH(A16) -> 1 | C16: =+YEAR(A16) -> 2021 | D16: 1053808794 | E16: ANGELITA REINOSA VILLA | F16: Masculino | G16: EPS SURA | H16: La Empresa 2 días el resto de días la EPS | I16: ADMINISTRATIVOS | J16: Coodinadora de Operaciones Manizales | K16: 42948 | L16: ADMINISTRATIVOS EMPRESTUR | M16: MEDELLIN | N16: Inc. Enfermedad general | O16: 3 | P16: 44209 | Q16: 44211 | R16: N879 | S16: =VLOOKUP($R16,DX!$A$1:$B$13005,2,FALSE) -> DISPLASIA DEL CUELLO DEL UTERO, NO ESPECIFICADA | T16: INICIAL | AA16: NO REQUIERE POST INCAPACIDAD
A17: 44210 | B17: =+MONTH(A17) -> 1 | C17: =+YEAR(A17) -> 2021 | D17: 8431066 | E17: JOHN FREDY CASTAÑEDA BEDOYA | F17: Masculino | G17: EPS SURA | H17: La EPS | I17: FLOTA PROPIA | J17: Conductor | K17: 43787 | L17: FLOTA PROPIA | M17: MEDELLIN | N17: Inc. Enfermedad general | O17: 3 | P17: 44210 | Q17: 44212 | R17: S518 | S17: =VLOOKUP($R17,DX!$A$1:$B$13005,2,FALSE) -> HERIDA DE OTRAS PARTES DEL ANTEBRAZO | T17: PRORROGA | AA17: NO REQUIERE POST INCAPACIDAD
A18: 44211 | B18: =+MONTH(A18) -> 1 | C18: =+YEAR(A18) -> 2021 | D18: 7543791 | E18: GILDARDO ANTONIO CANO MONTOYA | F18: Masculino | G18: MEDIMAS | H18: La Empresa 2 días el resto de días la EPS | I18: TERCEROS | J18: Conductor | K18: 43875 | L18: EMTELCO ARMENIA | M18: ARMENIA | N18: Inc. Enfermedad general | O18: 5 | P18: 44211 | Q18: 44215 | R18: U072 | S18: =VLOOKUP($R18,DX!$A$1:$B$13005,2,FALSE) -> COVID-19 (virus no identificado) | T18: INICIAL | AA18: NO REQUIERE POST INCAPACIDAD
A19: 44212 | B19: =+MONTH(A19) -> 1 | C19: =+YEAR(A19) -> 2021 | D19: 3400128 | E19: JUAN CAMILO GOMEZ TORO | F19: Masculino | G19: EPS SURA | H19: La Empresa 2 días el resto de días la EPS | I19: ADMINISTRATIVOS | J19: Director Talento humano | K19: 41526 | L19: ADMINISTRATIVOS EMPRESTUR | M19: MEDELLIN | N19: Inc. Enfermedad general | O19: 3 | P19: 44212 | Q19: 44214 | R19: U072 | S19: =VLOOKUP($R19,DX!$A$1:$B$13005,2,FALSE) -> COVID-19 (virus no identificado) | T19: INICIAL | AA19: NO REQUIERE POST INCAPACIDAD
A20: 44213 | B20: =+MONTH(A20) -> 1 | C20: =+YEAR(A20) -> 2021 | D20: 71661278 | E20: CARLOS HUMBERTO MUÑOZ CANO | F20: Masculino | G20: EPS SURA | H20: La Empresa 2 días el resto de días la EPS | I20: TERCEROS | J20: Conductor | K20: 43640 | L20: ARGOS | M20: MEDELLIN | N20: Inc. Enfermedad general | O20: 3 | P20: 44213 | Q20: 44215 | R20: U072 | S20: =VLOOKUP($R20,DX!$A$1:$B$13005,2,FALSE) -> COVID-19 (virus no identificado) | T20: INICIAL | AA20: NO REQUIERE POST INCAPACIDAD
A21: 44214 | B21: =+MONTH(A21) -> 1 | C21: =+YEAR(A21) -> 2021 | D21: 8028387 | E21: ANDRES MAURICIO ZAPATA GIRALDO | F21: Masculino | G21: EPS SURA | H21: La Empresa 2 días el resto de días la EPS | I21: TERCEROS | J21: Conductor | K21: 43657 | L21: EPM | M21: MEDELLIN | N21: Inc. Enfermedad general | O21: 3 | P21: 44214 | Q21: 44216 | R21: Z038 | S21: =VLOOKUP($R21,DX!$A$1:$B$13005,2,FALSE) -> OBSERVACION POR SOSPECHA DE OTRAS ENFERMEDADES Y AFECCIONES | T21: INICIAL | AA21: NO REQUIERE POST INCAPACIDAD
A22: 44214 | B22: =+MONTH(A22) -> 1 | C22: =+YEAR(A22) -> 2021 | D22: 8431066 | E22: JOHN FREDY CASTAÑEDA BEDOYA | F22: Masculino | G22: EPS SURA | H22: La EPS | I22: FLOTA PROPIA | J22: Conductor | K22: 43787 | L22: FLOTA PROPIA | M22: MEDELLIN | N22: Inc. Enfermedad general | O22: 1 | P22: 44214 | Q22: 44214 | R22: S518 | S22: =VLOOKUP($R22,DX!$A$1:$B$13005,2,FALSE) -> HERIDA DE OTRAS PARTES DEL ANTEBRAZO | T22: PRORROGA | AA22: NO REQUIERE POST INCAPACIDAD
A23: 44215 | B23: =+MONTH(A23) -> 1 | C23: =+YEAR(A23) -> 2021 | D23: 3400128 | E23: JUAN CAMILO GOMEZ TORO | F23: Masculino | G23: EPS SURA | H23: La EPS | I23: ADMINISTRATIVOS | J23: Director Talento humano | K23: 41526 | L23: ADMINISTRATIVOS EMPRESTUR | M23: MEDELLIN | N23: Inc. Enfermedad general | O23: 4 | P23: 44215 | Q23: 44218 | R23: U071 | S23: =VLOOKUP($R23,DX!$A$1:$B$13005,2,FALSE) -> COVID-19 (virus identificado) | T23: PRORROGA | AA23: NO REQUIERE POST INCAPACIDAD
A24: 44216 | B24: =+MONTH(A24) -> 1 | C24: =+YEAR(A24) -> 2021 | D24: 7543791 | E24: GILDARDO ANTONIO CANO MONTOYA | F24: Masculino | G24: MEDIMAS | H24: La EPS | I24: TERCEROS | J24: Conductor | K24: 43875 | L24: EMTELCO ARMENIA | M24: ARMENIA | N24: Inc. Enfermedad general | O24: 4 | P24: 44216 | Q24: 44219 | R24: U072 | S24: =VLOOKUP($R24,DX!$A$1:$B$13005,2,FALSE) -> COVID-19 (virus no identificado) | T24: PRORROGA | AA24: NO REQUIERE POST INCAPACIDAD
A25: 44216 | B25: =+MONTH(A25) -> 1 | C25: =+YEAR(A25) -> 2021 | D25: 71661278 | E25: CARLOS HUMBERTO MUÑOZ CANO | F25: Masculino | G25: EPS SURA | H25: La EPS | I25: TERCEROS | J25: Conductor | K25: 43640 | L25: ARGOS | M25: MEDELLIN | N25: Inc. Enfermedad general | O25: 5 | P25: 44216 | Q25: 44221 | R25: U071 | S25: =VLOOKUP($R25,DX!$A$1:$B$13005,2,FALSE) -> COVID-19 (virus identificado) | T25: PRORROGA | AA25: NO REQUIERE POST INCAPACIDAD
