Workbook

Sheet report
A1: Hora de inicio | B1: Hora de finalización | C1: Correo electrónico | D1: Nombre | E1: Jefe directo responsable del reporte | F1: Fecha de la novedad o accidente | G1: A que horas le reportan que ocurrieron los hechos | H1: Placa del vehículo (si es administrativo colocar NO APLICA) | I1: Contrato o cliente | J1: Los hechos ocurrieron durante la prestación del servicio | K1: Código Servicio | L1: Nombre de Empleado que presenta el accidente o la novedad | M1: Cedula del Empleado que presenta el accidente o la novedad | N1: Número Celular del Empleado que presenta el accidente o la novedad | O1: Identifique que tipo de novedad o accidente le indican en el reporte inicial, y describa si fue: | P1: Que Afectación identifica usted inicialmente en la versión dada en el reporte | Q1: Causa que genera el evento | R1: Lesionados | S1: Nombre y teléfono de Funcionario (Empleado del Cliente) lesionado | T1: Nombre y teléfono de Tercero (otro actor vial) lesionado | U1: Por favor, DESCRIBA la versión de los hechos que le da el empleado en el reporte inicial | V1: ACCIONES TOMADAS POR EL JEFE DIRECTO DE EMPRESTUR S.A.S.: Se reemplaza el servicio | W1: ACCIONES TOMADAS POR EL JEFE DIRECTO DE EMPRESTUR S.A.S.: Se informa al cliente verbalmente | X1: ACCIONES TOMADAS POR EL JEFE DIRECTO DE EMPRESTUR S.A.S.: Se dan indicaciones al conductor (llamar tránsito, ambulancia) | Y1: ACCIONES TOMADAS POR EL JEFE DIRECTO DE EMPRESTUR S.A.S.: Realiza acompañamiento en sitio | Z1: ACCIONES TOMADAS POR EL JEFE DIRECTO DE EMPRESTUR S.A.S.: Se reporta inmediatamente a SSTA de Emprestur | AA1: Acciones adicionales realizadas por el Gestor logístico de Emprestur o Jefe Directo | AB1: Registro Fotográfico Características del registro fotográfico: Frente, laterales, panorámica de los vehículos implicados; afectación a tercero foto escenario completo; Posición bosquejo o zona lugar d | AC1: SOPORTES PARA ANEXAR (Registro fotográfico, preoperacional de la ultima semana, bimestral vigente, soportes de mantenimiento, Reporte de GPS, planilla de servicio o asignación del servicio, Ficha del
A2: 45743.363 | B2: 45743.373 | C2: anonymous | E2: JUAN DAVID BLANDON ARENAS | F2: 45736 | G2: 08:51 | H2: NNM056 | I2: FUNDACION EPM | J2: Si | K2: SE008805 | L2: DIEGO ALEXIS MONGUA GARCIA | M2: 98702123 | N2: 311 7137391 | O2: Incidente de trabajo (Se pudo presentar una lesión en el trabajador) | P2: Daño Material a Tercero | Q2: Acto inseguro de Tercero | R2: N/A | S2: N/A | T2: N/A | U2: JUAN DAVID BLANDON Logistico de Transporte Emprestur Asunto: Informe de Novedad Vehiculo NNM 056 Respetuosamente me dirijo a usted con e fin de poner en conocimiento los hechos ocurridos el dia de hoy 20 de marzo del presente año, en las instalaciones de la UVA Pedregal de EPM. Siendo aproximadamente las 05:45 am me dispuse a recoger a la señorita Laura Llanos funcionaria de la Fundacion EPM en el sector de la terminal de transporte del Norte de Medellin, seguid a esto aproximadamente las 06: 00 horas me dirigi a la uva pederegal de acuerdo a lo coordinado con la funcionaria, ingresamos a las instalaciones luego de cumplir con los requisitos de seguridad. Siendo las 08:45 am la funcionaria luego de realizar sus labores en las instalaciones, nos dispusimos a continuar la ruta establecida, al momento de llegar a la porteria pase la tarjeta chip para abrir la talanquera de salida, en este punto se encontrba el vigilante de turno al cual le entregue el carnet de chip luego de pasar la talanquera, en este punto la funcionaria descendio del vehiculo para salir por el sector peatonal y marcar la salida, al pasar por el torniquete nuevamente ingreso a vehiculo e iniciamos la marcha para continuar con la ruta, cuando el heiculo a la altura de los espejos retrovisores cruza el porton siento un golpe al lado derecho del vehiculo, observo y me percato que la puerta del lado derecho del porton habia golpeado el vehiculo ya que habia iniciado a cerrarse. Al ver lo que estaba sucendiendo busco visualmente al vigilante la para que detuviera la puerta que intentaba cerrase y al ver que esto no paraba y seguia golpenando el vehiculo lo lleve hacia adelante para evitar algun daño. Luego de esto deciendo del vehiculo para verificar el vehiculo y encuentro que el retrovisor en la punta estaba tallado y otro en el centro, la presion tambien habia sacado el borde de la tapa del retrovisor del marco del espejo, ya en la puerta derecha tenia un tallon a lo lago de la puerta que saco un trapo del carro para mirara si solo eran residuos de la puerta del porton. Pero cuando veo que no desaparece procedo a pasar la mano sobre el sitio afectado y al tacto siento que tiene un sumido a lo largo del tallon siendo un poco mas profundo al inicio tomandolo de arriba hacia abajo. Al ver lo anterior mecinado me dirijo hacia la caseta donde se encuentra el vigilante y le informo que al cerrar la puerta golpeo el carro ya que no dejo que el carro saliera en su totalidad, quien respondio lo siguiente cito “que el penso que ya habia salido y que ademas la puerta tenia sensores y que si eso paso fue que habian fallado los sensores”, ha esto le respondi que el deberia estar pendiente que el carro salga, el señor responde “yo debo mantener la puerta cerrada” e ingreso a la caseta. Aunque es de logica y politicas de seguridad de la empresa, tambien es de logica que debe estar pendiente y cumplir las demas medidas de seguridad, como verificar que los carros crusen la linea amarilla que delimita el alcance de la puerta asi como se debe verificar que los carros que van a ingresar no sobre pasen la linea ya que los puede golpear tal cual como lo advierte el letrero que esta instalado en el porton. Al escuchar estas respuestas y ver la actitud poco consiliadora y falta de interes por lo sucedido decido informarle a don Juan logistico Emprestur y al señor Andres Ramirez dueño del vehiculo con el fin de dar a conocer lo sucedido en tiempo real. Quiero resaltar que todo lo anterior puede ser verificado con la funcionaria Laura Llanos y dentro de lo posible en los vedeos de las camaras de seguridad que vigilan el sector asi mismo en las ayudas fotograficas y audiovisuales que anexo al presente documento como tambien la cotizacion del costo de la correccion de las novedades presentadas al vehiculo la cual es algo modesta teniendo en cuenta que no se realizo atraves del consecionario ya que alli los costo puede ser mas elevado. | V2: NO | W2: SI | X2: NO | Y2: NO | Z2: SI | AA2: Se reporta vía telefónica al cliente y luego se envía el correo, explicando lo sucedido y se adjuntan registros fotográficos y la cotización de la reparación de los daños. | AB2: SI | AC2: https://emprestur-my.sharepoint.com/personal/alejandra_betancur_emprestur_com/Documents/Aplicaciones/Microsoft%20Forms/INFORMACI%C3%93N%20NOVEDAD%20_%20ACCIDENTES%2026042022%20(2)/SOPORTES%20PARA%20ANEXAR/WhatsApp%20Image%202025-03-20%20at%209.14.39%20AM_anonymous.jpeg; https://emprestur-my.sharepoint.com/personal/alejandra_betancur_emprestur_com/Documents/Aplicaciones/Microsoft%20Forms/INFORMACI%C3%93N%20NOVEDAD%20_%20ACCIDENTES%2026042022%20(2)/SOPORTES%20PARA%20ANEXAR/WhatsApp%20Video%202025-03-20%20at%2010.01.49%20PM_anonymous.mp4; https://emprestur-my.sharepoint.com/personal/alejandra_betancur_emprestur_com/Documents/Aplicaciones/Microsoft%20Forms/INFORMACI%C3%93N%20NOVEDAD%20_%20ACCIDENTES%2026042022%20(2)/SOPORTES%20PARA%20ANEXAR/WhatsApp%20Image%202025-03-20%20at%2010.01.49%20PM_anonymous.jpeg; https://emprestur-my.sharepoint.com/personal/alejandra_betancur_emprestur_com/Documents/Aplicaciones/Microsoft%20Forms/INFORMACI%C3%93N%20NOVEDAD%20_%20ACCIDENTES%2026042022%20(2)/SOPORTES%20PARA%20ANEXAR/WhatsApp%20Video%202025-03-20%20at%2010.01.48%20PM_anonymous.mp4; https://emprestur-my.sharepoint.com/personal/alejandra_betancur_emprestur_com/Documents/Aplicaciones/Microsoft%20Forms/INFORMACI%C3%93N%20NOVEDAD%20_%20ACCIDENTES%2026042022%20(2)/SOPORTES%20PARA%20ANEXAR/WhatsApp%20Image%202025-03-20%20at%209.55.20%20PM_anonymous.jpeg; https://emprestur-my.sharepoint.com/personal/alejandra_betancur_emprestur_com/Documents/Aplicaciones/Microsoft%20Forms/INFORMACI%C3%93N%20NOVEDAD%20_%20ACCIDENTES%2026042022%20(2)/SOPORTES%20PARA%20ANEXAR/WhatsApp%20Image%202025-03-20%20at%209.55.19%20PM_anonymous.jpeg; https://emprestur-my.sharepoint.com/personal/alejandra_betancur_emprestur_com/Documents/Aplicaciones/Microsoft%20Forms/INFORMACI%C3%93N%20NOVEDAD%20_%20ACCIDENTES%2026042022%20(2)/SOPORTES%20PARA%20ANEXAR/Cotizaci%C3%B3n%20NNM%20056_anonymous.pdf
A3: 45743.417 | B3: 45743.421 | C3: anonymous | E3: Diego Mendez | F3: 45737 | G3: 12 del dia | H3: EQX451 | I3: EPM | J3: Si | K3: 0 | L3: LUIS EDUARDO AGUDELO SALAS | M3: 98545061 | N3: 3046399455 | O3: Accidente de tránsito y transporte dentro del desarrollo de la labor (Si ocurre en la vía con otros vehículos o con otros actores viales implicados) | P3: Afectación a Personas (lesionados) | Q3: Acto inseguro propio (conductor) | R3: Tercero (Comunidad) | S3: 0 | T3: CAMILO MESA 3207078251 | U3: El día 21/03/2025 siendo las 12:00m, salía del del Campamento Tacuí con 3 funcionarios de EPM, durante el recorrido ninguna anomalía, vinimos a parar en Betania almorzar y a descansar un poco, al salir de Betania directo a Medellín justo después del Peaje de Don Matías en la recta después de estadero mm me encontré un mula a baja velocidad que iba aproximadamente 40 km/h y en uno de esos espacios identifiqué de que podía hacer el adelantamiento de ella, procedí hacer el adelantamiento ya que vi que no venía ningún vehículo, pero cuando estaba terminando de adelantar la mula, ella saca el cabezote para esquivar un vehículo que se encontraba estacionado entre la berma y la vía. Al ver la maniobra de la tractomula, me dispongo a parar en el carril contrario y en ese momento veo un ciclista que venía en el carril contrario mirando hacía atrás y al ver que la camioneta estaba parada logra esquivar y colisiona con el lado izquierdo del vehículo. Después de eso, procedo a estacionar el vehículo en el carril derecho para identificar lo que había sucedido y auxiliar el ciclista. Cuando nos bajamos del vehículo, el ciclista ya venía hacia el vehículo, se logra identificar unos leves raspones en los codos, en la cabeza y en la palma de la mano, se le presto la atención correspondiente y se realizo el traslado hacía el Hospital de Don Matías. Cuando llegamos al hospital le realizaron el proceso de ingreso y revisión para descartar lesiones de gravedad, yo procedo a entregar lo documento del vehículo para que fuera atendido. Mientras realizaban el proceso de atención del ciclista llegaron los agentes de tránsito de Don Matías, pero indican que el proceso no era con ellos y proceden a llamar al policía de carretera, este llega y damos versión de lo sucedido, pero en común acuerdo con el ciclista logramos conciliar y llegar a un acuerdo, ya que el policía de carretera indica que no hay necesidad de hacer algún procedimiento legal, ya que el ciclista se encontraba bien. El ciclista y su mamá todo el tiempo estuvo en buena actitud, agradeciendo todo el acompañamiento en el momento del evento. Incluso el ciclista en todo momento se declaraba culpable ya que venía mirando hacia atrás." | V3: NO | W3: NO | X3: SI | Y3: NO | Z3: SI | AA3: Se le indica que debe de hacer acompañamiento a la tercero lesionado y estar atento a instrucciones del area SST | AB3: NO
A4: 45743.471 | B4: 45743.48 | C4: anonymous | E4: JOHN FREDY CALLE RESTREPO | F4: 45742 | G4: 17:30 HORAS | H4: GDZ164 | I4: ISAGEN | J4: Si | K4: NO APLICA | L4: ACOSTA RODAS GUILLERMO LEON | M4: 98586405 | N4: 3146393071 | O4: Accidente de tránsito y transporte dentro del desarrollo de la labor (Si ocurre en la vía con otros vehículos o con otros actores viales implicados) | P4: Daño Material propio | Q4: Condición insegura | R4: N/A | S4: NO APLICA | T4: NO APLICA | U4: Siendo las 17:20 horas aproximadamente mientras el conductor en mención realizaba maniobra de reversa (sin usuarios) en Casa de Maquinas para colocar el bus en posición de salida golpeo con la parte superior trasera derecha del bus el ducto de ventilación que esta en la "Y" ocasionando que el vidrio de la ventanilla se agrietara. | V4: NO | W4: SI | X4: NO | Y4: SI | Z4: SI | AA4: Se informa al SST de ISAGEN Oscar Cano y también al Coordinador Administrativo Alejandro Berrio. | AB4: SI | AC4: https://emprestur-my.sharepoint.com/personal/alejandra_betancur_emprestur_com/Documents/Aplicaciones/Microsoft%20Forms/INFORMACI%C3%93N%20NOVEDAD%20_%20ACCIDENTES%2026042022%20(2)/SOPORTES%20PARA%20ANEXAR/WhatsApp%20Image%202025-03-27%20at%2011.19.21%20AM%20(1)_anonymous.jpeg; https://emprestur-my.sharepoint.com/personal/alejandra_betancur_emprestur_com/Documents/Aplicaciones/Microsoft%20Forms/INFORMACI%C3%93N%20NOVEDAD%20_%20ACCIDENTES%2026042022%20(2)/SOPORTES%20PARA%20ANEXAR/WhatsApp%20Image%202025-03-27%20at%2011.19.21%20AM_anonymous.jpeg; https://emprestur-my.sharepoint.com/personal/alejandra_betancur_emprestur_com/Documents/Aplicaciones/Microsoft%20Forms/INFORMACI%C3%93N%20NOVEDAD%20_%20ACCIDENTES%2026042022%20(2)/SOPORTES%20PARA%20ANEXAR/WhatsApp%20Image%202025-03-27%20at%2011.19.18%20AM%20(1)_anonymous.jpeg; https://emprestur-my.sharepoint.com/personal/alejandra_betancur_emprestur_com/Documents/Aplicaciones/Microsoft%20Forms/INFORMACI%C3%93N%20NOVEDAD%20_%20ACCIDENTES%2026042022%20(2)/SOPORTES%20PARA%20ANEXAR/WhatsApp%20Image%202025-03-27%20at%2011.19.18%20AM_anonymous.jpeg; https://emprestur-my.sharepoint.com/personal/alejandra_betancur_emprestur_com/Documents/Aplicaciones/Microsoft%20Forms/INFORMACI%C3%93N%20NOVEDAD%20_%20ACCIDENTES%2026042022%20(2)/SOPORTES%20PARA%20ANEXAR/WhatsApp%20Image%202025-03-27%20at%2011.18.44%20AM_anonymous.jpeg; https://emprestur-my.sharepoint.com/personal/alejandra_betancur_emprestur_com/Documents/Aplicaciones/Microsoft%20Forms/INFORMACI%C3%93N%20NOVEDAD%20_%20ACCIDENTES%2026042022%20(2)/SOPORTES%20PARA%20ANEXAR/WhatsApp%20Image%202025-03-27%20at%2011.18.43%20AM_anonymous.jpeg
A5: 45749.338 | B5: 45749.372 | C5: anónimo | E5: EDWIN AGUIRRE | F5: 45748 | G5: 14:30 | H5: ESR437 | I5: CHEMICAL | J5: Si | K5: 758 | L5: ZAPATA GUZMAN HECTOR ELI | M5: 70128434 | N5: 314 7701452 | O5: Incidente de trabajo (Se pudo presentar una lesión en el trabajador) | P5: Afectación al Cliente | Q5: Acto inseguro propio (conductor) | R5: Funcionario de cliente | S5: Karina Silgado Silgado - 310 4043694 | T5: n/a | U5: Conductor al momento de dar reversa atrapa funcionaria contra cajas de icopor que se encuentran contra la pared, aprisionando las dos rodillas provocando un leve dolor en la rodilla derecha, | V5: SI | W5: SI | X5: NO | Y5: NO | Z5: SI | AA5: En compañía de Daniela Vergara, se llama al conductor para a hondar un poco mas en lo sucedido. Me comunico con la funcionaria me expresa que no es grave que se tomara un par un par de antibióticos, se le ofrece vehículo para llevarle a un centro medico, me dice que no es necesario que se tomara un par de pastillas | AB5: SI | AC5: https://emprestur-my.sharepoint.com/personal/alejandra_betancur_emprestur_com/Documents/Aplicaciones/Microsoft%20Forms/INFORMACI%C3%93N%20NOVEDAD%20_%20ACCIDENTES%2026042022%20(2)/SOPORTES%20PARA%20ANEXAR/WhatsApp%20Image%202025-04-01%20at%203.17.01%20PM_anonymous.jpeg
A6: 45754.559 | B6: 45754.565 | C6: anónimo | E6: DAYHANA SOSSA GIRALDO | F6: 45748 | G6: 3:00 PM | H6: N/A | I6: JARDIN BOTANICO | J6: Si | K6: 01046 | L6: DENNIS VILLA | M6: 98571216 | N6: 305 2656118 | O6: Incidente de trabajo (Se pudo presentar una lesión en el trabajador) | P6: Daño Material a Tercero | Q6: Acto inseguro propio (conductor) | R6: N/A | S6: N/A | T6: N/A | U6: El ing a cargo del proyecto le solicito trasladar un maquina podadora, y el conductor la sube a la camioneta sin amarrarla ni asegurarla. | V6: SI | W6: SI | X6: SI | Y6: SI | Z6: SI | AA6: N/A | AB6: SI | AC6: https://emprestur-my.sharepoint.com/personal/alejandra_betancur_emprestur_com/Documents/Aplicaciones/Microsoft%20Forms/INFORMACI%C3%93N%20NOVEDAD%20_%20ACCIDENTES%2026042022%20(2)/SOPORTES%20PARA%20ANEXAR/WhatsApp%20Video%202025-04-01%20at%203.43.18%20PM_anonymous.mp4
A7: 45761.39 | B7: 45761.406 | C7: anónimo | E7: DIANA ALVAREZ | F7: 45758 | G7: 14:50 | H7: GDY059 | I7: ISAGEN | J7: Si | K7: N/A | L7: MANUEL ANTONIO CARMONA MONTAÑO | M7: 70568599 | N7: 3212583021 | O7: Accidente de tránsito y transporte dentro del desarrollo de la labor (Si ocurre en la vía con otros vehículos o con otros actores viales implicados) | P7: Daño Material propio | Q7: Condición insegura | R7: N/A | S7: N/A | T7: N/A | U7: El conductor iba en masivo de JAGUAS, pasando por la vía de SAN RAFAEL hacia MEDELLIN, el conductor da paso a un camión que llevaba una maquina, luego el conductor saca un poco el carro para continuar con la marcha, pero con la parte trasera del bus, toca una moto en el manubrio, el conductor se baja del carro para organizar con el dueño de la moto, (la cual se encontraba mal parqueada, ya que es un espacio de vía principal), en ese momento pasaron 3 volquetas, dos de ellas pasaron normal, pero la tercera, pasó y tenia un tornillo en el volco y con ese daño el espejo del bus. se hizo presencia el transito, evidenciaron que ninguno de los dos implicados externos tenían documentos, hicieron mover los vehículos para no obstaculizar el paso y se retiran sin dar solución. | V7: NO | W7: NO | X7: NO | Y7: NO | Z7: NO | AA7: Solicitar fotos e informe de lo sucedido | AB7: SI | AC7: https://emprestur-my.sharepoint.com/personal/alejandra_betancur_emprestur_com/Documents/Aplicaciones/Microsoft%20Forms/INFORMACI%C3%93N%20NOVEDAD%20_%20ACCIDENTES%2026042022%20(2)/SOPORTES%20PARA%20ANEXAR/WhatsApp%20Image%202025-04-11%20at%207.53.06%20PM_anonymous.jpeg; https://emprestur-my.sharepoint.com/personal/alejandra_betancur_emprestur_com/Documents/Aplicaciones/Microsoft%20Forms/INFORMACI%C3%93N%20NOVEDAD%20_%20ACCIDENTES%2026042022%20(2)/SOPORTES%20PARA%20ANEXAR/WhatsApp%20Image%202025-04-11%20at%207.53.05%20PM%20(3)_anonymous.jpeg; https://emprestur-my.sharepoint.com/personal/alejandra_betancur_emprestur_com/Documents/Aplicaciones/Microsoft%20Forms/INFORMACI%C3%93N%20NOVEDAD%20_%20ACCIDENTES%2026042022%20(2)/SOPORTES%20PARA%20ANEXAR/WhatsApp%20Image%202025-04-11%20at%207.53.05%20PM%20(2)_anonymous.jpeg; https://emprestur-my.sharepoint.com/personal/alejandra_betancur_emprestur_com/Documents/Aplicaciones/Microsoft%20Forms/INFORMACI%C3%93N%20NOVEDAD%20_%20ACCIDENTES%2026042022%20(2)/SOPORTES%20PARA%20ANEXAR/WhatsApp%20Image%202025-04-11%20at%207.53.05%20PM%20(1)_anonymous.jpeg; https://emprestur-my.sharepoint.com/personal/alejandra_betancur_emprestur_com/Documents/Aplicaciones/Microsoft%20Forms/INFORMACI%C3%93N%20NOVEDAD%20_%20ACCIDENTES%2026042022%20(2)/SOPORTES%20PARA%20ANEXAR/WhatsApp%20Image%202025-04-11%20at%207.53.05%20PM_anonymous.jpeg; https://emprestur-my.sharepoint.com/personal/alejandra_betancur_emprestur_com/Documents/Aplicaciones/Microsoft%20Forms/INFORMACI%C3%93N%20NOVEDAD%20_%20ACCIDENTES%2026042022%20(2)/SOPORTES%20PARA%20ANEXAR/WhatsApp%20Image%202025-04-11%20at%207.53.04%20PM_anonymous.jpeg
A8: 45770.631 | B8: 45770.635 | C8: anónimo | E8: JUAN DAVID BLANDÓN | F8: 45770 | G8: 14:20 | H8: NLW531 | I8: TELEMEDELLIN | J8: Si | K8: 995 | L8: YAMID SERNA | M8: 8005509 | N8: 310 4688172 | O8: Accidente de tránsito y transporte dentro del desarrollo de la labor (Si ocurre en la vía con otros vehículos o con otros actores viales implicados) | P8: Daño Material propio | Q8: Acto inseguro de Tercero | R8: N/A | S8: N/A | T8: N/A | U8: Siendo las 13:10 aproximadamente del día 23-04-2025 se presenta novedad con vehículo tipo jaula, éste se presentó sobre la Carrera 43F con 18, al frente del Canal de Televisión Telemedellín. Me dirigía en sentido Norte-Sur y antes de llegar al retorno había fila para regresar, así que procedo a detenerme, estando ya quieto esperando el avance de los carros de adelante siento el impacto por detrás del otro vehículo. Desciendo del carro, se revisa el estado de los daños, el Presentador y Camarografo del canal deciden descender, cruzar la calle y llegar al canal a pie. Yo continuo con el registro fotográfico, el otro conductor acepta la responsabilidad y asume los gastos del ése daño. Hablando con Alejandro Gomez autoriza llevar el vehículo afectado al taller, donde se cotiza el daño y la persona responsable paga el total, quedando pendiente el arreglo para el día 24-04-2025 a las 8:00 am. | V8: NO | W8: NO | X8: NO | Y8: NO | Z8: SI | AA8: N/A | AB8: SI | AC8: https://emprestur-my.sharepoint.com/personal/alejandra_betancur_emprestur_com/Documents/Aplicaciones/Microsoft%20Forms/INFORMACI%C3%93N%20NOVEDAD%20_%20ACCIDENTES%2026042022%20(2)/SOPORTES%20PARA%20ANEXAR/WhatsApp%20Image%202025-04-23%20at%202.49.52%20PM%20(1)_anonymous.jpeg; https://emprestur-my.sharepoint.com/personal/alejandra_betancur_emprestur_com/Documents/Aplicaciones/Microsoft%20Forms/INFORMACI%C3%93N%20NOVEDAD%20_%20ACCIDENTES%2026042022%20(2)/SOPORTES%20PARA%20ANEXAR/WhatsApp%20Image%202025-04-23%20at%202.49.52%20PM_anonymous.jpeg
A9: 45776.582 | B9: 45776.588 | C9: anónimo | E9: JONATHAN GIRALDO ORREGO | F9: 45771 | G9: 06:12 AM | H9: JYO404 | I9: ISAGEN | J9: Si | K9: RUTA METRO | L9: CRISTIAN ANDRES TABORDA TABORDA | M9: 1128438613 | N9: 3124601727 | O9: Accidente de tránsito y transporte dentro del desarrollo de la labor (Si ocurre en la vía con otros vehículos o con otros actores viales implicados) | P9: Afectación a Personas (lesionados) | Q9: Acto inseguro de Tercero | R9: Conductor y/o Empleado | S9: CRISTIAN ANDRES TABORDA TABORDA 3124601727 | T9: N/A | U9: El conductor CRISTIAN ANDRES TABORDA TABORDA se encontraba realizando la ruta Metro el día 24 de abril, y sale de la estación del metro siendo aproximadamente las 6:10 am. saliendo con el personal de ISAGEN, cuando mas o menos a las 6:12 am antes de llegar al semáforo de la glorieta de Monterrey (Carrera48c con la calle 10 cerca del rompoy de Monterrey) se me atraviesa un taxista y se baja del taxi a agredirme diciendo que yo lo había cerrado cosa que no fue así ya que desde que salí del punto de recogida salí por el carril izquierdo ya que el costado derecho se encontraban los taxis estacionados. el taxista abrió la puerta de mi carro y me agredió físicamente. | V9: NO | W9: SI | X9: NO | Z9: NO | AA9: se toma versión de los hechos, se revisa la novedad en cámaras de video y se le comparten al cliente. | AB9: SI
A10: 45782.242 | B10: 45782.245 | C10: anónimo | E10: JONATHAN GIRALDO ORREGO | F10: 45780 | G10: 07:37 AM | H10: GTW934 | I10: AYUDA HUMANITARIA | J10: No | K10: EMERGENCIA 123 | L10: JUAN MANUEL GALINDO GOMEZ | M10: 1000644388 | N10: 3019029552 - 3128810679 | O10: Accidente de tránsito (se produce en las vías y fuera de horario laboral) | P10: Daño Material propio | Q10: Acto inseguro propio (conductor) | R10: N/A | S10: N/A | T10: N/A | U10: "El conductor JUAN MANUEL GALINDO GOMEZ con cedula de ciudadanía numero 1000644388 y número de teléfono 3019029552 - 3128810679, quien se encuentra asignado al vehículo de flota propia de placas GTW934 para el contrato de AYUDA HUMANITARIA - Componente Emergencias 123, el día sábado 3 de mayo del 2025 siendo las 7:37 de la mañana aproximadamente el conductor se dirigía hacia la corporación para iniciar turno; el conductor iba en el carro bajando por la avenida Ferrocarril a la altura del puente peatonal de plaza mayor (para entrar a la alpujarra), transitaba por carril del medio y enciende direccional para pasar al carril de la derecha y voltear para coger la calle 42 (plaza de la libertad), cuando se pasa al carril derecho una moto que venia muy rápido golpea contra el carro en un costado del vehículo al lado derecho, el conductor Juan Manuel Galindo al decirle al conductor de la moto que iba a llamar al transito, este le contesta que la culpa era de nuestro conductor por meterse así en el carril, nuestro conductor le dice que llamaran ambulancia que si estaba aporreado y este le contesta que no que porque le quitaban la porque no tenía papeles y salió y se fue del lugar. El conductor de los nervios que tenia por el accidente, no alcanza a tomar la placa de la moto ni los datos de la persona, realiza el reporte de la novedad al coordinador Edwin y al día siguiente nos realiza el reporte a Flota propia (Director). Al momento de los hechos no se tenia presencia de funcionarios en el vehículo. Para hacer el análisis del accidente le solicito al conductor que me haga el reporte de lo ocurrido y me envié las fotos del evento, donde se evidencia que el carro sufre daños en nave trasera derecha y rin de la llanta trasera lado derecho. Teniendo en cuenta que en el reporte, el conductor indica que va por el carril del medio y se pasa al carril derecho para voltear en la calle 42, asumo una presunta invasión del carril por lo que reviso el GPS y puedo evidenciar que a la altura del carril donde el conductor hace el giro hacia el lado derecho ya había una línea blanca continua en la via lo que me ratificaba lo que estaba pensando, por lo cual le escalo la pregunta al conductor Juan Manuel donde le consulto que si el era consciente que debía haber buscado pasar al carril derecho mucho antes lo que este me contesta ""Si jefe mirando el retrovisor de pronto no vi que cambiaba la línea descontinúa ahi, Si hay tuve el error"". en el momento de los hechos no se realiza reporte a la aseguradora ya que como lo indique solo hasta el día siguiente el conductor reporta a Flota." | V10: NO | W10: NO | X10: NO | Y10: NO | Z10: NO | AA10: Se realiza reporte del accidente de transito con la informacion que el conductor nos suministra al area de SST, Juridica, Talento humano y agencia de seguros para realiza el reporte a la aseguradora." | AB10: SI | AC10: https://emprestur-my.sharepoint.com/personal/alejandra_betancur_emprestur_com/Documents/Aplicaciones/Microsoft%20Forms/INFORMACI%C3%93N%20NOVEDAD%20_%20ACCIDENTES%2026042022%20(2)/SOPORTES%20PARA%20ANEXAR/ACIDENTE%20DE%20TRANSITO%20VEHICULO%20GTW934%20-%20JUAN%20M_anonymous.pdf
A11: 45793.71 | B11: 45793.719 | C11: anónimo | E11: Alejandra Velasquez | F11: 45793 | G11: 4:30 pm | H11: WCQ263 | I11: Mejia y Acevedo | J11: Si | K11: 0 | L11: Ronald Graterol Quintero | M11: 1434177 | N11: 3011414949 | O11: Accidente de trabajo (Empleado de Emprestur Lesionado) | P11: Afectación a Personas (lesionados) | Q11: Condición insegura | R11: Conductor y/o Empleado | S11: Ronald Graterol Quintero 3011414949 | T11: No | U11: El conductor de emprestur Ronal graterol reporta sufrió una caida el dia de hoy mientras cargaba un balde con agua, refiere mucho dolor en hombro y pierna. | V11: NO | W11: SI | X11: SI | Y11: NO | Z11: SI | AA11: Se informa a SST emprestur, se comunica y da indicaciones al conductor implicado y se indica información solicitada con el cliente Mejia y Acevedo | AB11: NO
A12: 45803.292 | B12: 45803.308 | C12: anónimo | E12: Ramon Andres Quintero Cardona | F12: 45800 | G12: 23:36 | H12: NLW559 | I12: Corporación Ayuda Humanitaria | J12: Si | K12: OS0305496 | L12: JUAN JOSE ROA GARCIA | M12: 1062088177 | N12: 3245030239 | O12: Accidente de tránsito y transporte dentro del desarrollo de la labor (Si ocurre en la vía con otros vehículos o con otros actores viales implicados) | P12: Daño Material a Tercero | Q12: Acto inseguro de Tercero | R12: N/A | S12: N/A | T12: N/A | U12: Venía por la avenida regional lado derecho y en el instante se me atraviesa un motociclista sin casco y sin ningúna señalización como la direccional afortunadamente no hubo perdidas humanas ni lecciones personales solo hubieron perdidas materiales, El siniestro ocurrió debido al mal manejo del motociclista y condiciones climáticas, Realicé varias llamadas a la aseguradora en diferentes momentos, pero lamentablemente no obtuve respuesta en ninguna de ellas, y el motociclista no contaba con documentación y fue inmovilizado | V12: NO | W12: SI | X12: NO | Y12: NO | Z12: NO | AA12: Debido a que el incidente de transito fue a altas horas de la noche, se toma la versión de los acontecimientos del conductor al otro día y se reporta al área encargada | AB12: SI | AC12: https://emprestur-my.sharepoint.com/personal/alejandra_betancur_emprestur_com/Documents/Aplicaciones/Microsoft%20Forms/INFORMACI%C3%93N%20NOVEDAD%20_%20ACCIDENTES%2026042022%20(2)/SOPORTES%20PARA%20ANEXAR/Evidencia%20Fotografica_anonymous.pdf
A13: 45805.267 | B13: 45805.273 | C13: anónimo | E13: Julián david Valencia Ballesteros | F13: 45804 | G13: 12:36 | H13: ETL617 | I13: CHEC | J13: No | K13: TR2509173 | L13: DEYDI LEANDRO HEANO | M13: 1053863471 | N13: +57 324 4539219 | O13: Accidente de tránsito (se produce en las vías y fuera de horario laboral) | P13: Daño Material propio | Q13: Condición insegura | R13: Conductor y/o Empleado | S13: NO IBA FUNCIONARIO | T13: NO IBA FUNCIONARIO | U13: El conductor informa que el funcionario lo despacho a la 8 pm saliendo de victoria caldas hacia Manizales, después de pasar el sector el 8, el conductor informa sobre las 11:23 pm al coger una curva pierde el control y golpea el contra borde de la vía, se activó el airbag, el conductor indica no presentar lesiones. | V13: SI | W13: SI | X13: NO | Y13: NO | Z13: NO | AA13: se reemplaza el servicio del dia 28 de mayo, se comunica con el conductor para solicitar desplazarse a revisión medica independiente de sentirse bien | AB13: SI | AC13: https://emprestur-my.sharepoint.com/personal/alejandra_betancur_emprestur_com/Documents/Aplicaciones/Microsoft%20Forms/INFORMACI%C3%93N%20NOVEDAD%20_%20ACCIDENTES%2026042022%20(2)/SOPORTES%20PARA%20ANEXAR/Imagen%20de%20WhatsApp%202025-05-28%20a%20las%2006.01.07__anonymous.jpg; https://emprestur-my.sharepoint.com/personal/alejandra_betancur_emprestur_com/Documents/Aplicaciones/Microsoft%20Forms/INFORMACI%C3%93N%20NOVEDAD%20_%20ACCIDENTES%2026042022%20(2)/SOPORTES%20PARA%20ANEXAR/Imagen%20de%20WhatsApp%202025-05-28%20a%20las%2006.01.00__anonymous.jpg
A14: 45805.4 | B14: 45805.426 | C14: anónimo | E14: Ramon Andres Quintero Cardona | F14: 45804 | G14: 13:22 | H14: SNW912 | I14: EPM | J14: Si | K14: ID86 | L14: JONATHAN ATEHORTUA USME | M14: 1001452215 | N14: 310 7272289 | O14: Accidente de tránsito y transporte dentro del desarrollo de la labor (Si ocurre en la vía con otros vehículos o con otros actores viales implicados) | P14: Afectación a Personas (lesionados) | Q14: Acto inseguro de Tercero | R14: Tercero (Comunidad) | S14: N/A | T14: Wilson Alesis Marin Marin - 3239729782 | U14: Me desplazada en la vía peñol marinilla los vehículos de adelante se detuvieron por la presencia de una animal en la vía yo me detuve detrás iba una motocicleta de placas RBG03F conducida por el sr. Wilson Alesis Marin Marin cel. 3239729782 la cual no estaba respetando la distancia establecida no alcanzo a frenar me golpeó por la parte trasera del vehículo | V14: SI | W14: SI | X14: SI | Y14: NO | Z14: SI | AA14: Se entregan orientaciones via telefonica al conductor para proceder frente al desarrollo del evento, con respecto al reporte a la aseguradora y juridica de la compañia. | AB14: SI | AC14: https://emprestur-my.sharepoint.com/personal/alejandra_betancur_emprestur_com/Documents/Aplicaciones/Microsoft%20Forms/INFORMACI%C3%93N%20NOVEDAD%20_%20ACCIDENTES%2026042022%20(2)/SOPORTES%20PARA%20ANEXAR/Evidencia%20Fotografica_anonymous%201.pdf
A15: 45808.885 | B15: 45808.891 | C15: anónimo | E15: JONATHAN GIRALDO ORREGO | F15: 45807 | G15: 09:30 Pm | H15: FWK341 | I15: CORPORACION AYUA HUMANITARIA | J15: No | K15: 123 EMERGENCIA | L15: MIGUEL ANGEL BEDOYA CASTAÑEDA | M15: 1018229452 | N15: 3205182447 | O15: Accidente de tránsito y transporte dentro del desarrollo de la labor (Si ocurre en la vía con otros vehículos o con otros actores viales implicados) | P15: Afectación a Personas (lesionados) | Q15: Condición insegura | R15: N/A | S15: N/A | T15: N/A | U15: Buenas tardes a todos Espero estén muy bien. Quiero informar que el día de ayer viernes 30 de mayo, el conductor de flota propia MIGUEL ANGEL BEDOYA CASTAÑEDA cc 1018229452 asignado al vehículo de placas FWK341 y quien labora para el contrato de la corporación Ayuda humanitaria, se encoraba cubriendo le turno de 10 de la mañana a 9 de la noche. luego de descargar a la funcionaria en su casa, siendo aproximadamente las 9:30 de la noche, ya se dirigía para el parqueadero de la empresa cuando en la Avenida 80 Con calle 78 Sentido norte-sur, el conductor venia por el carril derecho a 40 Km/h (según informa el conductor), el piso se encontraba mojado porque estaba lloviendo, cuando al momento de frenar el carro cuando transitaba sobre una de las demarcaciones (pintura) que tiene en la vía para las paradas del metro plus, el vehículo pierde la tracción y el conductor pierde el control del vehículo lo cual genera que el carro le haga una especie de trompo he imparte contra dos vehículo y al final contra el separador (baranda tubos) ocasionando daños a los dos vehículos terceros, un carro de comidas rápidas que estaba siendo halado en esos momentos por uno de los vehículos con que se colisiona y el carro propio quien lleva la peor parte en el accidente por haber golpeado contra el separador. los datos de los vehículos afectados son: VEHICULO # 1 PLACA: IOV085 TIPO DE VEHICULO: Renault Logan NOMBRE: Juan Santiago Velasco TELÉFONO: 3014047238 DAÑO: Afectación en bómper delantero derecho VEHICULO # 2 PLACA: ISS752 TIPO DE VEHICULO: Renault Duster NOMBRE: Jorge andres onofre TELEFONO: 3216840974 DAÑOS: Afectacion en parte trasera y daños al carro de comidas rapidas en general. El conductor se pone en contacto conmigo, y le pregunto si en el evento se presentan lesionados a lo que este me informa que ni el ni los tripulantes de los dos carros afectados estaban lesionados y que el accidente solo habia sido daños materiales, de inmediato le solicito que se ponga en contacto con la aseguradora SBS al #360 para que le presten la asistencia juridica en el sitio, ademas de servicio de grua y asignacion de taller para la reparacion del vehiculo propios. El abogado de la aseguradora, llega al sitio y le explica a los terceros afectados como pueden realizar el proceso de reclamacion ante la aseguradora para la reparacion de los daños ocacionados por nuestro vehiculo. ademas se comunica tambien conmigo el abogado quien me informa el proceso que realizo con los terceros y que explica que debemos solicitar cita en el taller Multimarca de Envigado para que reciban el carro y valoren lo daños; por la hora del evento nos vimos en la necesidad de trasladar el carro en grua hasta nuestras intalaciones para ya el martes solicitar la cita en el taller que nos designo la aseguradora. El día de hoy analice el accidente teniendo en cuenta las imágenes y el reportes del conductor donde evidencio por reporte de GPS que el conductor nuestro segundos antes de accidente iba a una velocidad de 52,2 Km/h. y la velocidad máxima permitida en la via por donde transitaba es de 50Km/H. | V15: SI | W15: NO | X15: SI | Y15: NO | Z15: SI | AA15: Se llama al conductor y le dan las infracciones de llamar a la aseguradora y se reporta a SST y abogadas. | AB15: SI
A16: 45808.978 | B16: 45808.98 | C16: anónimo | E16: Jonathan Giraldo Orrego | F16: 45808 | G16: 5:20 am | H16: FWK341 | I16: CORPORACION | J16: Si | K16: CONHYDRA | L16: EDUAR ALEXANDER LONDOÑO CARO | M16: 98710320 | N16: 3022234175 | O16: Accidente de trabajo (Empleado de Emprestur Lesionado) | P16: Afectación a Personas (lesionados) | Q16: Acto inseguro propio (conductor) | R16: N/A | S16: N/A | T16: N/A | U16: Quiero informar que el día de hoy sábado 31 de mayo, el conductor de flota propia EDUAR ALEXANDER LONDOÑO CARO cc 98710320 asignado al vehículo de placas SNR611 y quien labora para el contrato de la CONHYDRA, se encoraba cubriendo le turno de la noche de 9 Pm hasta las 5 de la mañana. El conductor siendo aproximadamente las 5:20 de la mañana me llama y me informa que ya había terminado el turno de trabajo y que cuando iba por la calle 62 A en el sector de fuente clara con destino para su casa, indica que le dio un micro sueño y que por ello se había chocado contra una motocicleta que estaba estacionada y que además se había golpeado el contra el timón del carro por lo que se había reventado un poco la boca. informa también que no hubieron más afectaciones ni heridos en el accidente. De inmediato le doy indicación al conductor de que se ponga en contacto con nuestra aseguradora SBS en el #360 para que solicite asistencia de grúa y de abogado en sitio para que se atendiera la moto afectada y el tránsito. Pasados más o menos 30 minutos me comunico con el conductor nuevamente ya que no me respondía los mensajes para consultarle que si ya había solicitado la asistencia y que le habían respondido, a lo que este me informa que ya estaba por llegar el abogado de la aseguradora, también me indico que no solicitaría transito porque no habían lesionados, de inmediato le pido al conductor que llame al tránsito pues el cómo conductor si estaba lastimado por el golpe en la boca. Paso seguido y como acción tomada por mi parte fue enviar dos conductores de la flota al sitio para que realizaran el acompañamiento a Aduar Londoño ya que como había trasnochado y había reportado micro sueño lo ms prudente era llevarlo a la casa y que los compañeros terminaran el proceso con la aseguradora; no obstante, cuando los conductores de apoyo llegaron al lugar encontraron un escenario muy diferente a lo que el conductor aduar había reportado, resulta que nuestro conductor choco primero a una camioneta que estaba estacionada a un lado de la vía y luego golpeo dos motos que estaban estacionadas. Los daños de los carros fueron CARRO PROPIO SNR611: Daños en bómper delantero farola izquierda - persiana - boca llantas delantero izquierdo, guardabarros, capot MOTO # 1 Bóxer 100: la moto se ve muy deteriorada y acabada, no se puede determinar si es que esta moto estaba desvalijada o en que estado estaba. MOTO # 2 QWD19G: la moto se ve muy deteriorada y acabada, no se puede determinar si es que esta moto estaba desvalijada o en que estado estaba. CAMIONETA PARTICULAR KHS242: El carro tiene daños en bómper lado izquierdo, nave delantero, persiana. Cuando llego el tránsito y el abogado de la aseguradora, se realizaron los procesos correspondientes, el abogado informó a todos los propietarios de los afectados que debían realizar la reclamación a la aseguradora, también me llamo y me informo que el transito se llevaría el carro para los patios pues debían realizar prueba de alcohol al conductor, pues se evidenciaba que estaba embriagado, por lo cual procedí a solicitarle a los conductores que envié, que se fueran con ellos para el transito y luego pudiera transportar al conductor a su casa. Luego del procedimiento de prueba de alcohol el abogado me contacta y me informa que la prueba había salido positiva con grado 3 de alcalemia, le informe al conductor que se viniera para la empresa junto con los conductores para tomarle la versión de los hechos , no obstante, este se negó y dijo que no vendría a la empresa. El abogado me informa que el carro debe quedar retenido en patios hasta 10 días hábiles (17 de junio) y que al conductor le debían suspender la licencia de conducción. Le escribí al conductor aduar para solicitarle que llegara a la empresa para que nos contara lo ocurrido y me dijo que estaba muy apenado que el si se había tomado una cerveza que le había ofrecido uno de los contratistas y que luego lo venció el sueño. el conductor no llego a | V16: SI | W16: NO | X16: SI | Y16: SI | Z16: SI | AA16: Se hace presencia en sitio, se hace investigacion., se reporta a operaciones | AB16: SI | AC16: https://emprestur-my.sharepoint.com/personal/alejandra_betancur_emprestur_com/Documents/Aplicaciones/Microsoft%20Forms/INFORMACI%C3%93N%20NOVEDAD%20_%20ACCIDENTES%2026042022%20(2)/SOPORTES%20PARA%20ANEXAR/FOTOS%20DEL%20ACCIDENTE%20-%20SNR611_anonymous.pdf
A17: 45809.576 | B17: 45809.584 | C17: anónimo | E17: JHON HAWER MURCIA OROZCO | F17: 45809 | G17: 12:27 PM | H17: LKL437 | I17: SALUD EN CASA (SURA) | J17: Si | K17: le solicitan el soat al vehículo por que la funcionaria fua a la clinica para ser atendida | L17: ANDRES DE JESUS TABORDA BOTERO | M17: 71222989 | N17: 324 2433112 | O17: Accidente de tránsito y transporte dentro del desarrollo de la labor (Si ocurre en la vía con otros vehículos o con otros actores viales implicados) | P17: Afectación al Cliente | Q17: Acto inseguro de Tercero | R17: Funcionario de cliente | S17: 3115209242 | T17: YADIT REQUEME | U17: Dirección Calle 30 # 136-106 Belén aguas frías En camino se interpone motorizado el cual esquivó para ebitar incidente. Por lo tanto la llanta trasera del lado derecho del vehículo pasa una piedra por encima. | V17: NO | W17: SI | X17: NO | Y17: NO | Z17: SI | AA17: comunicarme con el conductor para saber que sucedió y ayudarlo en lo que necesitaba | AB17: NO
A18: 45817.379 | B18: 45817.38 | C18: anónimo | E18: ANDRES QUINTERO CARDONA | F18: 45814 | G18: 13:17 | H18: EXU714 | I18: TELEMEDELLIN | J18: Si | K18: OS0321710 | L18: EDISON STIVEN SALDARRIAGA HENAO | M18: 1007669856 | N18: 3226609827 | O18: Accidente de tránsito y transporte dentro del desarrollo de la labor (Si ocurre en la vía con otros vehículos o con otros actores viales implicados) | P18: Daño Material a Tercero | Q18: Acto inseguro de Tercero | R18: N/A | S18: N/A | T18: N/A | U18: vehículo tercero realiza giro a la izquierda en una vía doble sentido, frena de manera repentina por dar paso a peatón en la vía, frene tambien inmediatamente pero alcance a impactarlo en la parte de atras, Ocasionando solo pintura pequeña en ambos vehículos Sin heridos ni afectados | V18: NO | W18: SI | X18: SI | Y18: NO | Z18: NO | AA18: Se acompaña telefónicamente al conductor hasta finalizar el proceso. | AB18: SI | AC18: https://emprestur-my.sharepoint.com/personal/alejandra_betancur_emprestur_com/Documents/Aplicaciones/Microsoft%20Forms/INFORMACI%C3%93N%20NOVEDAD%20_%20ACCIDENTES%2026042022%20(2)/SOPORTES%20PARA%20ANEXAR/Registro%20fotografico_anonymous.pdf
A19: 45818.347 | B19: 45818.36 | C19: anónimo | E19: Carlos Franco | F19: 45815 | G19: 10:00 am | H19: NNM458 | I19: EPM | J19: Si | K19: SDT. 111166 | L19: ALEJANDRO LOPERA BEDOYA | M19: 1007243076 | N19: 3173471864 | O19: Accidente de tránsito y transporte dentro del desarrollo de la labor (Si ocurre en la vía con otros vehículos o con otros actores viales implicados) | P19: Daño Material propio | Q19: Acto inseguro propio (conductor) | R19: N/A | S19: CESAR ALFONSO TOVAR ARIAS Teléfono 3015182469 | T19: N/A | U19: "Yo venía por la autopista norte, sentido sur - norte a la altura de la feria de ganado, específicamente donde se realizan las subastas. Al rededor de las 10 de la mañana, venía delante de mi un vehículo tipo furgón el cual frena repentinamente por otro vehículo que frena delante de él ocasionando que yo impacte en la parte trasera del furgón" | V19: SI | W19: NO | X19: SI | Y19: NO | Z19: SI | AA19: Se establece conversación con el funcionario donde manifiesta que no les pasó nada y que sólo fue el susto para que se le asigne vehículo de reemplazo y continuar con el recorrido programado | AB19: SI | AC19: https://emprestur-my.sharepoint.com/personal/alejandra_betancur_emprestur_com/Documents/Aplicaciones/Microsoft%20Forms/INFORMACI%C3%93N%20NOVEDAD%20_%20ACCIDENTES%2026042022%20(2)/SOPORTES%20PARA%20ANEXAR/WhatsApp%20Image%202025-06-08%20at%2020.26.17_anonymous.jpeg; https://emprestur-my.sharepoint.com/personal/alejandra_betancur_emprestur_com/Documents/Aplicaciones/Microsoft%20Forms/INFORMACI%C3%93N%20NOVEDAD%20_%20ACCIDENTES%2026042022%20(2)/SOPORTES%20PARA%20ANEXAR/WhatsApp%20Image%202025-06-08%20at%2020.26.18_anonymous.jpeg; https://emprestur-my.sharepoint.com/personal/alejandra_betancur_emprestur_com/Documents/Aplicaciones/Microsoft%20Forms/INFORMACI%C3%93N%20NOVEDAD%20_%20ACCIDENTES%2026042022%20(2)/SOPORTES%20PARA%20ANEXAR/WhatsApp%20Image%202025-06-08%20at%2020.26.20_anonymous.jpeg; https://emprestur-my.sharepoint.com/personal/alejandra_betancur_emprestur_com/Documents/Aplicaciones/Microsoft%20Forms/INFORMACI%C3%93N%20NOVEDAD%20_%20ACCIDENTES%2026042022%20(2)/SOPORTES%20PARA%20ANEXAR/WhatsApp%20Image%202025-06-08%20at%2020.26.20%20(1)_anonymous.jpeg; https://emprestur-my.sharepoint.com/personal/alejandra_betancur_emprestur_com/Documents/Aplicaciones/Microsoft%20Forms/INFORMACI%C3%93N%20NOVEDAD%20_%20ACCIDENTES%2026042022%20(2)/SOPORTES%20PARA%20ANEXAR/WhatsApp%20Image%202025-06-08%20at%2020.26.21_anonymous.jpeg; https://emprestur-my.sharepoint.com/personal/alejandra_betancur_emprestur_com/Documents/Aplicaciones/Microsoft%20Forms/INFORMACI%C3%93N%20NOVEDAD%20_%20ACCIDENTES%2026042022%20(2)/SOPORTES%20PARA%20ANEXAR/WhatsApp%20Image%202025-06-09%20at%2013.55.09_anonymous.jpeg
A20: 45828.572 | B20: 45828.575 | C20: anónimo | E20: Jeiner Morales | F20: 45828 | G20: 1 pm | H20: SNV726 | I20: EEP | J20: Si | K20: NA | L20: Wilder Ramos | M20: 18516706 | N20: +57 318 5094343 | O20: Accidente Ambienta (afectación al ecosistema por derrames, impacto con animal en la vía) | P20: Afectación al medio ambiente | Q20: Acto inseguro de Tercero | R20: Tercero (Comunidad) | S20: na | T20: na | U20: Sobre el medio día el conductor es chocado por un perro que se lanzo a la carretera generándole lesiones al perro | V20: NO | W20: NO | X20: SI | Y20: NO | Z20: SI | AA20: Se reporta a SST | AB20: NO
A21: 45842.585 | B21: 45842.585 | C21: anónimo | E21: JONATHAN GIRALDO ORREGO | F21: 45840 | G21: 10:51 AM | H21: SNV729 | I21: CHEC | J21: Si | K21: CHEC | L21: FABIAN GENARO CARDENAS SANCHEZ | M21: 1053849967 | N21: 3117672947 | O21: Accidente de tránsito y transporte dentro del desarrollo de la labor (Si ocurre en la vía con otros vehículos o con otros actores viales implicados) | P21: Daño Material propio | Q21: Condición insegura | R21: N/A | S21: N/A | T21: N/A | U21: Quiero realizar el reporte del accidente ocurrido el pasado miércoles 2 de julio del 2025; donde el conductor del vehículo administrado de placas SNV729 quien es conducido por nuestro colaborador FABIAN GENARO CARDENAS SANCHEZ CC 1053849967, teléfono 3117672947,se encontraba prestando servicio para el cliente CHEC. estando en inmediaciones de la base militar Montezuma - parque nacional natural Tatamá y que queda a mas o menos 2 horas y media de Pueblo rico Risaralda; los funcionarios descienden del vehículo, puesto que debían hacer unos trabajos de reconocimiento del terreno y este recorrido lo realizaban caminando; mientras tanto nuestro conductor seguía a los funcionarios montado en el vehículo a un una baja velocidad (7Km/h aproximadamente). siendo aproximadamente las 10:51 mientras iban bajando por una pendiente, el conductor siente que el pedal del freno no le responde y su reacción fue recostar el carro contra el barranco lo cual genera que el vehículo sufra un volcamiento, el conductor no sufre lesiones y los funcionarios al estar un poco retirados del vehículo tampoco sufren lesiones. al lugar de los hechos, llegaron unos soldados quienes ayudaron a nuevamente voltear el vehículo y ponerlo sobre las ruedas; dado que el carro permaneció por un buen rato con las llantas hacia arriba, este no se debía encender pues podría generar afectaciones significativas dado que el aceite del vehículo pudo ingresar a las recamaras del motor; además el carro quedaba No operativo por las afectaciones que tenia. Luego de que el carro estuvo sobre las Ruedas solicite al conductor que me realizara un video donde se evidenciara que el freno estaba "blandito" y no cogía, a lo que el conductor me informa "Jefe el freno está duro pero cuando yo empecé a bajar el pedal se fue a fondo". por lo que mi hipótesis es que el carro si le freno pero al ser un terreno de lodo amarrillo el carro se le fue resbalado, desde operaciones Manizales activaron el protocolo de mandar un carro de remplazo pero mientras llegaba el vehículo, tanto los funcionarios como el conductor se bajaron en un jeep para Pueblo Rico dejando el vehículo en el lugar de los hechos. Se activo el protocolo de reporte de la novedad a la aseguradora SBS el cual quedo bajo el radicado (1708033), donde nos informan que debido a que donde quedo el carro es una zona roja y por lo inclinado del terreno y ser destapado, la grúa no entraba por el vehículo lo que nos llevo a tener que pagarle a un señor de un jeep para que subiera y arrastrara el carro hasta la entrada al parque nacional (pueblo rico) el cual nos cobro 600.000 mil pesos. luego de que sacaron el carro de la zona lo recogió la grúa de la aseguradora y lo traslado a Manizales para el taller casa López el cual nos designo la aseguradora para la reparación. Esta novedad se le informo al propietario del vehículo (Juan Jose Roa) y el protocolo que esto tenia. | V21: SI | W21: SI | X21: SI | Y21: NO | Z21: SI | AA21: desde operaciones Manizales activaron el protocolo de mandar un carro de remplazo pero mientras llegaba el vehículo, tanto los funcionarios como el conductor se bajaron en un jeep para Pueblo Rico dejando el vehículo en el lugar de los hechos. Se activo el protocolo de reporte de la novedad a la aseguradora SBS el cual quedo bajo el radicado (1708033), donde nos informan que debido a que donde quedo el carro es una zona roja y por lo inclinado del terreno y ser destapado, la grúa no entraba por el vehículo lo que nos llevo a tener que pagarle a un señor de un jeep para que subiera y arrastrara el carro hasta la entrada al parque nacional (pueblo rico) el cual nos cobro 600.000 mil pesos. luego de que sacaron el carro de la zona lo recogió la grúa de la aseguradora y lo traslado a Manizales para el taller casa López el cual nos designo la aseguradora para la reparación. Se envia notificacion a las areas encargadas para el proceso de investigacion del evento. | AB21: SI | AC21: https://emprestur-my.sharepoint.com/personal/alejandra_betancur_emprestur_com/Documents/Aplicaciones/Microsoft%20Forms/INFORMACI%C3%93N%20NOVEDAD%20_%20ACCIDENTES%2026042022%20(2)/SOPORTES%20PARA%20ANEXAR/FOTOS%20DEL%20ACCIDENTE%20SNV729%20-%20REPORTE%20GPS_anonymous.pdf
A22: 45856.62 | B22: 45856.621 | C22: anónimo | E22: Julian Davi Valencia Ballesteros | F22: 45856 | G22: 12:50 pm | H22: EXU705 | I22: CHEC | J22: Si | K22: TR2512634 | L22: Milton Stivel Cardona Castaño | M22: 1060650008 | N22: +573165799327 | O22: Accidente Ambienta (afectación al ecosistema por derrames, impacto con animal en la vía) | P22: Daño Material a Tercero | Q22: Acto inseguro de Tercero | R22: Tercero (Comunidad) | S22: n/a | T22: No se tiene contacto | U22: El día 18/07/2025, el conductor se dirigía a la residencia del funcionario para finalizar el servicio asignado. Al ingresar a la calle donde se encuentra la vivienda, observó que había varios caninos en el sector, por lo cual redujo la velocidad y continuó avanzando con precaución. En ese momento, sintió un golpe en la llanta trasera del vehículo, acompañado de un chillido. Al detenerse y descender del vehículo, una vecina se acercó y le preguntó si había atropellado a un perro, a lo que el conductor respondió que no lo sabía con certeza. Seguidamente, observó que un canino de gran tamaño salía por la parte delantera del vehículo, y al revisar por debajo, notó que había un canino más pequeño que estaba lesionado. El conductor procedió a retroceder el vehículo ligeramente para observar con mayor claridad el estado del animal. En ese momento, un menor salió de una vivienda cercana, recogió al perro y lo ingresó a la casa. Posteriormente, una joven salió y preguntó por el estado del perro. Desde el interior de la vivienda se escuchaban llantos, pero ninguna otra persona salió a atender la situación. Tanto el funcionario como algunos vecinos que presenciaron lo ocurrido le manifestaron al conductor que no había tenido la culpa y que podía retirarse del lugar. El conductor intentó hacer señas a los dueños del perro para obtener algún tipo de respuesta, pero no obtuvo ninguna y se retiro del sitio. | V22: NO | W22: NO | X22: NO | Y22: NO | Z22: SI | AA22: Se le solicito al conductor evidencia fotografica del lugar del incidente. | AB22: SI | AC22: https://emprestur-my.sharepoint.com/personal/alejandra_betancur_emprestur_com/Documents/Aplicaciones/Microsoft%20Forms/INFORMACI%C3%93N%20NOVEDAD%20_%20ACCIDENTES%2026042022%20(2)/SOPORTES%20PARA%20ANEXAR/IMG-20250718-WA0017_anonymous.jpg; https://emprestur-my.sharepoint.com/personal/alejandra_betancur_emprestur_com/Documents/Aplicaciones/Microsoft%20Forms/INFORMACI%C3%93N%20NOVEDAD%20_%20ACCIDENTES%2026042022%20(2)/SOPORTES%20PARA%20ANEXAR/IMG-20250718-WA0018_anonymous.jpg; https://emprestur-my.sharepoint.com/personal/alejandra_betancur_emprestur_com/Documents/Aplicaciones/Microsoft%20Forms/INFORMACI%C3%93N%20NOVEDAD%20_%20ACCIDENTES%2026042022%20(2)/SOPORTES%20PARA%20ANEXAR/IMG-20250718-WA0016_anonymous.jpg; https://emprestur-my.sharepoint.com/personal/alejandra_betancur_emprestur_com/Documents/Aplicaciones/Microsoft%20Forms/INFORMACI%C3%93N%20NOVEDAD%20_%20ACCIDENTES%2026042022%20(2)/SOPORTES%20PARA%20ANEXAR/IMG-20250718-WA0014_anonymous.jpg; https://emprestur-my.sharepoint.com/personal/alejandra_betancur_emprestur_com/Documents/Aplicaciones/Microsoft%20Forms/INFORMACI%C3%93N%20NOVEDAD%20_%20ACCIDENTES%2026042022%20(2)/SOPORTES%20PARA%20ANEXAR/IMG-20250718-WA0015_anonymous.jpg; https://emprestur-my.sharepoint.com/personal/alejandra_betancur_emprestur_com/Documents/Aplicaciones/Microsoft%20Forms/INFORMACI%C3%93N%20NOVEDAD%20_%20ACCIDENTES%2026042022%20(2)/SOPORTES%20PARA%20ANEXAR/IMG-20250718-WA0013_anonymous.jpg
A23: 45868.659 | B23: 45868.698 | C23: anónimo | E23: Adriana Castillo | F23: 45868 | G23: 13:30 p.m. | H23: NNN344 | I23: SURA | J23: No | K23: N/A | L23: YEISON ACEVEDO ARIAS | M23: 1007567428 | N23: 3052001475 | O23: Accidente de tránsito y transporte dentro del desarrollo de la labor (Si ocurre en la vía con otros vehículos o con otros actores viales implicados) | P23: Daño Material propio | Q23: Acto inseguro propio (conductor) | R23: N/A | S23: N/A | T23: 3003456544 Juan Pablo Sanchez | U23: Yo Yeison Acevedo Arias El día 30 de julio del 2025 A las 13:45 en la calle 14 me dirigía a la empresa a entregar el vehículo al frente de la terminal del Sur ingresando a la glorieta del aeropuerto Olaya Herrera tuve un choque simple contra otro automóvil. Lo que paso fue que el señor conductor arrancó a incorporace y yo también arranque en ese momento paso una motocicleta por la glorieta y el conductor del particulat se frenó de forma brusca no tuve tiempo de reacción y lo choque con el bomper delantero lado derecho en la parte izquierda trasera del otro vehículo | V23: NO | W23: NO | X23: SI | Y23: NO | Z23: SI | AA23: Se le indica que llame a la aseguradora, toma de fotograficas y traer el vehículo al parqueadero | AB23: SI | AC23: https://emprestur-my.sharepoint.com/personal/alejandra_betancur_emprestur_com/Documents/Aplicaciones/Microsoft%20Forms/INFORMACI%C3%93N%20NOVEDAD%20_%20ACCIDENTES%2026042022%20(2)/SOPORTES%20PARA%20ANEXAR/REGISTRO%20FOTOGRAFICO%20NNN344_anonymous.pdf
A24: 45869.302 | B24: 45869.306 | C24: anónimo | E24: JONATHAN GIRALDO ORREGO | F24: 45865 | G24: 7:40 AM | H24: FWL446 | I24: FLOTA PROPIA | J24: No | K24: CARAVANA RUTA 2025 | L24: JUAN CAMILO SEPULVEDA MORALES | M24: 1037618189 | N24: 3019640447 | O24: Accidente de tránsito y transporte dentro del desarrollo de la labor (Si ocurre en la vía con otros vehículos o con otros actores viales implicados) | P24: Daño Material propio | Q24: Acto inseguro propio (conductor) | R24: Conductor y/o Empleado | S24: Angie Arzuza | T24: N/A | U24: Quiero oficializar el reporte del accidente que ocurrió el pasado domingo 27 de julio del 2025. En el evento llamado caravana Ruta 2025 que la empresa organizo como parte de la celebración del día del conductor y la familia; 5 minutos luego de haber iniciado la caravana que salió de Ayurá motor de la avenida las Vegas, siendo aproximadamente las 7:40 de la mañana el conductor de flota propia JUAN CAMILO SEPULVEDA MORALES CC 1037618189 quien conducía el vehículo de placas FWL446 me reporta que había acabado de tener un accidente por la avenida regional a la altura de la calle 14, indica que el compañero LUIS FERNANDO GAVIRIA DURANGO cc 71753945 del vehículo de placas LKL570 que iba adelante de él freno y que no alcanzó a frenar el carro chocando contra el carro del compañero. Ambos vehículos sufren afectaciones en su estructura, el carro de placas FWL446 es quien tiene mas afectaciones, pues se generan daños de bómper delantero, persiana, nave delantera, capot, calandria, radiador, farolas; por otro lado el vehículo de placas LKL570 sufre daños en bómper trasero, compuerta, stop y nave trasera. Al momento del accidente en el vehículo de placas FWL446 viajaba nuestro conductor Juan camilo y su esposa, quienes indicaron no haber sufrido ninguna lesión; por otro lado en el carro de placas LKL570 viajaba nuestro conductor Luis Gaviria en compañía de Angie Arzuza, quien luego del evento si manifestó tener sensación de dolor en su cuerpo por el evento. Se valida el GPS y se identifica que al momento del evento el carro FWL446 iba a una velocidad de 38 Km/h. el caso fue reportado a la aseguradora Zurich Colombia Seguros el cual quedo bajo el radicado # -175129. agradezco por favor realicemos el proceso de investigación del evento y dejemos los registros necesarios. @Manuela Jaramillo - @Nancy Arias Antes de iniciar la caravana todos los conductores firmaron un documento llamado exoneración de responsabilidad de la empresa donde ellos asumían cualquier daño o afectación. estos documentos los tenia Angie, por favor vinculemos el documento que debió firmar juan camilo para que realicemos el descuento de nomina del deducible por afectaciones 2 SMMLV. Se anexan fotos de los carros. reporte GPS Se registra evento en el enlace. | V24: NO | W24: SI | X24: NO | Y24: NO | Z24: SI | AA24: Se realiza reporte de la novedad SST - y talento humano, se reporta aseguradora | AB24: SI | AC24: https://emprestur-my.sharepoint.com/personal/alejandra_betancur_emprestur_com/Documents/Aplicaciones/Microsoft%20Forms/INFORMACI%C3%93N%20NOVEDAD%20_%20ACCIDENTES%2026042022%20(2)/SOPORTES%20PARA%20ANEXAR/FOTOS%20DEL%20EVENTO%20FWL446%20-%20LKL570_anonymous.pdf
