Workbook

Sheet 2026 INFRACCIONES 
A1: Cedula | B1: Nombre completo | C1: CLIENTE | D1: Tipo de Contrato | E1: Ciudad | F1: Fecha Infracción | G1: Lugar de la Infraccion | H1: Código infracción | I1: Placa | J1: Descripción Infracciones | K1: Valor Infracción | L1: Mes | M1: Año | N1: Tipo de Acción | O1: Fecha de Notificación | P1: Clase de Capacitación | Q1: Control Infracciones | R1: ESTADO DEL EMPLEADO EN LA EMPRESA | S1: DEVOLUCION NOTIFICACION FIRMADA | T1: CAPACITACION Y EVALUACION | U1: INFRACCIÓN SE DA EN DESARROLLO DE LA LABOR | V1: ENTREGA COMPROBANTE DE PAGO | W1: Observaciones
A2: 1036132399 | B2: =VLOOKUP(A2,'[1] BD CONDUCTORES'!$A$2:$B$691,2,FALSE) -> ARAGON JIMENEZ EDUARD YAIR | C2: UT MEJIA Y ACEVEDO SYE VOLQUET | D2: TERCEROS | E2: MEDELLIN | F2: 45681 | G2: Bello | H2: C02 | I2: TAV412 | J2: =VLOOKUP(H2,VALIDACIONES!$A$2:$B$138,2,0) -> Estacionar un vehículo en los sitios prohibidos por el Código Nacional de Tránsito, reglamentado por la Res.3027. | K2: 603917 | L2: =MONTH(F2) -> 1 | M2: =YEAR(F2) -> 2025 | N2: CAPACITACIÓN | O2: 45747 | P2: CAPACITACIÓN MANEJO DEFENSIVO | Q2: NO PAGO | R2: ACTIVO | S2: NO | T2: SI | U2: SI | V2: NO | W2: Se le envia el mensaje los doccumenos pero solo contesta con un "OK", no se a podido tener una conversacion con el señor ya que no contesta llamadas
A3: 71666329 | B3: =VLOOKUP(A3,'[1] BD CONDUCTORES'!$A$2:$B$691,2,FALSE) -> ORTIZ FORONDA JORGE ALBERTO | C3: EPM NUEVO | D3: TERCEROS | E3: MEDELLIN | F3: 45670 | G3: Medellin | H3: C02 | J3: =VLOOKUP(H3,VALIDACIONES!$A$2:$B$138,2,0) -> Estacionar un vehículo en los sitios prohibidos por el Código Nacional de Tránsito, reglamentado por la Res.3027. | K3: 604054 | L3: =MONTH(F3) -> 1 | M3: =YEAR(F3) -> 2025 | N3: CAPACITACIÓN | O3: 45747 | P3: CAPACITACIÓN MANEJO DEFENSIVO | Q3: PAGO | R3: ACTIVO | S3: SI | T3: SI | U3: SI | V3: NO | W3: el señor tiene una tutela por ese motivo no la a pagado esperando que le quiten este informe, esta con el abogado.
A4: 8152105 | B4: =VLOOKUP(A4,'[1] BD CONDUCTORES'!$A$2:$B$691,2,FALSE) -> RESTREPO MESA CARLOS ALBEIRO | C4: EPM NUEVO | D4: TERCEROS | E4: MEDELLIN | F4: 45677 | G4: Santa Rosa de Osos | H4: C02 | J4: =VLOOKUP(H4,VALIDACIONES!$A$2:$B$138,2,0) -> Estacionar un vehículo en los sitios prohibidos por el Código Nacional de Tránsito, reglamentado por la Res.3027. | K4: 377448 | L4: =MONTH(F4) -> 1 | M4: =YEAR(F4) -> 2025 | N4: CAPACITACIÓN | O4: 45747 | P4: CAPACITACIÓN MANEJO DEFENSIVO | Q4: PAGO | R4: ACTIVO | S4: NO | T4: SI | U4: SI | V4: SI
A5: 98624721 | B5: =VLOOKUP(A5,'[1] BD CONDUCTORES'!$A$2:$B$691,2,FALSE) -> SANCHEZ OTALVARO WILFER ELIECE | C5: CORPORACION AYUDA HUMANITARIA | D5: TERCEROS | E5: MEDELLIN | F5: 45686 | G5: Medellin | H5: C02 | J5: =VLOOKUP(H5,VALIDACIONES!$A$2:$B$138,2,0) -> Estacionar un vehículo en los sitios prohibidos por el Código Nacional de Tránsito, reglamentado por la Res.3027. | K5: 604054 | L5: =MONTH(F5) -> 1 | M5: =YEAR(F5) -> 2025 | N5: CAPACITACIÓN | O5: 45747 | P5: CAPACITACIÓN MANEJO DEFENSIVO | Q5: PAGO | R5: ACTIVO | S5: NO | T5: SI | U5: SI | V5: NO
A6: 70565141 | B6: =VLOOKUP(A6,'[1] BD CONDUCTORES'!$A$2:$B$691,2,FALSE) -> JARAMILLO GIL CARLOS ALBERTO | C6: EPM NUEVO | D6: TERCEROS | E6: MEDELLIN | F6: 45693 | G6: Medellin | H6: C02 | J6: =VLOOKUP(H6,VALIDACIONES!$A$2:$B$138,2,0) -> Estacionar un vehículo en los sitios prohibidos por el Código Nacional de Tránsito, reglamentado por la Res.3027. | K6: 603917 | L6: =MONTH(F6) -> 2 | M6: =YEAR(F6) -> 2025 | N6: CAPACITACIÓN | O6: 45747 | P6: CAPACITACIÓN MANEJO DEFENSIVO | Q6: PAGO | R6: ACTIVO | S6: NO | T6: NO | V6: NO
A7: 71784723 | B7: =VLOOKUP(A7,'[1] BD CONDUCTORES'!$A$2:$B$691,2,FALSE) -> MARIN MUÑOZ JOSE ALEXANDER | C7: EPM NUEVO | D7: TERCEROS | E7: MEDELLIN | F7: 45712 | G7: Medellin | H7: C02 | J7: =VLOOKUP(H7,VALIDACIONES!$A$2:$B$138,2,0) -> Estacionar un vehículo en los sitios prohibidos por el Código Nacional de Tránsito, reglamentado por la Res.3027. | K7: 604054 | L7: =MONTH(F7) -> 2 | M7: =YEAR(F7) -> 2025 | N7: CAPACITACIÓN | O7: 45747 | P7: CAPACITACIÓN MANEJO DEFENSIVO | Q7: NO PAGO | R7: ACTIVO | S7: NO | T7: NO | U7: NO | V7: NO
A8: 1023831141 | B8: =VLOOKUP(A8,'[1] BD CONDUCTORES'!$A$2:$B$691,2,FALSE) -> ARBOLEDA GALLEGO JORGE LUIS | C8: EPM NUEVO | D8: TERCEROS | E8: MEDELLIN | F8: 44745 | G8: Medellin | H8: F | J8: se refiere a la infracción de conducir bajo el influjo del alcohol o bajo los efectos de sustancias psicoactivas | K8: 22485447 | L8: =MONTH(F8) -> 7 | M8: =YEAR(F8) -> 2022 | N8: RETIRO
A9: 75087065 | B9: =VLOOKUP(A9,'[1] BD CONDUCTORES'!$A$2:$B$691,2,FALSE) -> CORTES MONTES JUAN DAVID | C9: CHEC | D9: TERCEROS | E9: MANIZALES | F9: 45728 | G9: Manizales | H9: D04 | I9: AXC30E | J9: =VLOOKUP(H9,VALIDACIONES!$A$2:$B$138,2,0) -> Nodetenerseanteunaluzrojaoamarilladesemáforo,unaseñalde"PARE"ounsemáforointermitenteenrojo.Enelcasodemotocicletaseprocederaasuinmovilizaciónhastatantonosepagueelvalordelamultaolaautoridadcompetentedecidasobresuimposicionenlosterminosdelosarticulos135y136delcódigonacionaldetránsito. | K9: 1207855 | L9: =MONTH(F9) -> 3 | M9: =YEAR(F9) -> 2025 | N9: CAPACITACIÓN | O9: 45777 | P9: CAPACITACIÓN MANEJO DEFENSIVO | Q9: NO PAGO | R9: ACTIVO | S9: SI | T9: SI | U9: NO | V9: NO
A10: 70033808 | B10: LOPEZ ECHEVERRY HECTOR RAMIRO | C10: EPM NUEVO | D10: TERCEROS | E10: MEDELLIN | F10: 45736 | G10: La Dorada | H10: C29 | J10: =VLOOKUP(H10,VALIDACIONES!$A$2:$B$138,2,0) -> Conducir un vehículo a velocidad superior a la máxima permitida, la cual deberá estar señalizada en forma sectorizada, no obstante esta no podrá ser superior a (verlistado) | K10: 603930 | L10: =MONTH(F10) -> 3 | M10: =YEAR(F10) -> 2025 | N10: CAPACITACIÓN | O10: 45777 | P10: CAPACITACIÓN MANEJO DEFENSIVO | Q10: PAGO | R10: ACTIVO | S10: NO | T10: NO | V10: NO
A11: 15509092 | B11: =VLOOKUP(A11,'[1] BD CONDUCTORES'!$A$2:$B$691,2,FALSE) -> MISAS RUEDA LUIS ALBEIRO | C11: GRUPO SURA | D11: TERCEROS | E11: MEDELLIN | F11: 45745 | G11: Medellin | H11: C02 | J11: =VLOOKUP(H11,VALIDACIONES!$A$2:$B$138,2,0) -> Estacionar un vehículo en los sitios prohibidos por el Código Nacional de Tránsito, reglamentado por la Res.3027. | K11: 604054 | L11: =MONTH(F11) -> 3 | M11: =YEAR(F11) -> 2025 | N11: CAPACITACIÓN | O11: 45777 | P11: CAPACITACIÓN MANEJO DEFENSIVO | Q11: PAGO | R11: ACTIVO | S11: NO | T11: NO | V11: NO
A12: 1017153007 | B12: LOPEZ VALENCIA YOJANA | C12: ADMINISTRATIVO | D12: TERCEROS | E12: MEDELLIN | F12: 45766 | G12: Itagui | H12: C29 | I12: FVY741 | J12: =VLOOKUP(H12,VALIDACIONES!$A$2:$B$138,2,0) -> Conducir un vehículo a velocidad superior a la máxima permitida, la cual deberá estar señalizada en forma sectorizada, no obstante esta no podrá ser superior a (verlistado) | K12: 603930 | L12: =MONTH(F12) -> 4 | M12: =YEAR(F12) -> 2025 | N12: CAPACITACIÓN | O12: 45793 | P12: CAPACITACIÓN MANEJO DEFENSIVO | Q12: NO PAGO | R12: ACTIVO | S12: NO | T12: SI | U12: SI | V12: NO
A13: 79909780 | B13: =VLOOKUP(A13,'[1] BD CONDUCTORES'!$A$2:$B$691,2,FALSE) -> LOPEZ MARTINEZ DARLEY | C13: CHEC | D13: TERCEROS | E13: MANIZALES | F13: 45758 | G13: Manizales | H13: D04 | I13: ESL086 | J13: =VLOOKUP(H13,VALIDACIONES!$A$2:$B$138,2,0) -> Nodetenerseanteunaluzrojaoamarilladesemáforo,unaseñalde"PARE"ounsemáforointermitenteenrojo.Enelcasodemotocicletaseprocederaasuinmovilizaciónhastatantonosepagueelvalordelamultaolaautoridadcompetentedecidasobresuimposicionenlosterminosdelosarticulos135y136delcódigonacionaldetránsito. | K13: 1207855 | L13: =MONTH(F13) -> 4 | M13: =YEAR(F13) -> 2025 | N13: CAPACITACIÓN | O13: 45793 | P13: CAPACITACIÓN MANEJO DEFENSIVO | Q13: PAGO | R13: ACTIVO | S13: SI | T13: SI | U13: SI | V13: SI
A14: 71223585 | B14: =VLOOKUP(A14,'[1] BD CONDUCTORES'!$A$2:$B$691,2,FALSE) -> CASTRILLON LOPEZ CARLOS ANDRES | C14: EPM NUEVO | D14: TERCEROS | E14: MEDELLIN | F14: 45754 | G14: Medellin | H14: C02 | I14: JYY056 | J14: =VLOOKUP(H14,VALIDACIONES!$A$2:$B$138,2,0) -> Estacionar un vehículo en los sitios prohibidos por el Código Nacional de Tránsito, reglamentado por la Res.3027. | K14: 604054 | L14: =MONTH(F14) -> 4 | M14: =YEAR(F14) -> 2025 | N14: CAPACITACIÓN | O14: 45793 | P14: CAPACITACIÓN MANEJO DEFENSIVO | Q14: NO PAGO | R14: ACTIVO | S14: SI | T14: SI | U14: SI | V14: NO
A15: 1036638930 | B15: =VLOOKUP(A15,'[1] BD CONDUCTORES'!$A$2:$B$691,2,FALSE) -> GARCIA SEPULVEDA SEBASTIAN | C15: JARDIN BOTANICO | D15: TERCEROS | E15: MEDELLIN | F15: 45749 | G15: Bello | H15: H13 | I15: ABS962 | J15: =VLOOKUP(H15,VALIDACIONES!$A$2:$B$138,2,0) -> Las demas conductas que constituyan infraccion a las normas de transito y que no se encuentren descritas en este acto administrativo. | K15: 201351 | L15: =MONTH(F15) -> 4 | M15: =YEAR(F15) -> 2025 | N15: CAPACITACIÓN | Q15: PAGO | R15: ACTIVO | S15: NO | T15: NO | V15: NO
A16: 1060649387 | B16: =VLOOKUP(A16,'[1] BD CONDUCTORES'!$A$2:$B$691,2,FALSE) -> PATIÑO ALVAREZ JOHAN SEBASTIAN | C16: CHEC | D16: TERCEROS | E16: MANIZALES | F16: 45770 | G16: Manizales | H16: C35 | I16: NQV89F | J16: =VLOOKUP(H16,VALIDACIONES!$A$2:$B$138,2,0) -> No realizar la revisión técnico mecánica y de emisiones en los siguientes plazos o cuando aún portando los certificados correspondientes no cuenta con las siguientes condiciones tecnicomecánica y de emisiones contaminantes, además el vehiculo será inmovilizado.(verlistado) | K16: 603928 | L16: =MONTH(F16) -> 4 | M16: =YEAR(F16) -> 2025 | N16: CAPACITACIÓN | O16: 45793 | P16: CAPACITACIÓN MANEJO DEFENSIVO | Q16: PAGO | R16: ACTIVO | S16: SI | T16: SI | U16: NO | V16: SI
A17: 1060649387 | B17: =VLOOKUP(A17,'[1] BD CONDUCTORES'!$A$2:$B$691,2,FALSE) -> PATIÑO ALVAREZ JOHAN SEBASTIAN | C17: CHEC | D17: TERCEROS | E17: MANIZALES | F17: 45770 | G17: Manizales | H17: D02 | I17: NQV89F | J17: =VLOOKUP(H17,VALIDACIONES!$A$2:$B$138,2,0) -> ConducirsinportarelSeguroObligatoriodeAccidentesdetránsitoordenadoporlaley.Además,elvehículoseráinmovilizado. | K17: 1207855 | L17: =MONTH(F17) -> 4 | M17: =YEAR(F17) -> 2025 | N17: CAPACITACIÓN | O17: 45793 | P17: CAPACITACIÓN MANEJO DEFENSIVO | Q17: PAGO | R17: ACTIVO | S17: SI | T17: SI | U17: NO | V17: SI
A18: 1018376618 | B18: BOLIVAR IBARRA YOVAN ESTEBAN | C18: UT MEJIA Y ACEVEDO SYE VOLQUET | D18: TERCEROS | E18: MEDELLIN | F18: 45806 | G18: Medellin | H18: C35 | J18: =VLOOKUP(H18,VALIDACIONES!$A$2:$B$138,2,0) -> No realizar la revisión técnico mecánica y de emisiones en los siguientes plazos o cuando aún portando los certificados correspondientes no cuenta con las siguientes condiciones tecnicomecánica y de emisiones contaminantes, además el vehiculo será inmovilizado.(verlistado) | K18: 604054 | L18: =MONTH(F18) -> 5 | M18: =YEAR(F18) -> 2025 | N18: CAPACITACIÓN | O18: 45819 | P18: CAPACITACIÓN MANEJO DEFENSIVO | Q18: PAGO | R18: ACTIVO | S18: SI | T18: SI | U18: SI | V18: SI
A19: 75092999 | B19: BURITICA ROJAS LUIS FELIPE | C19: CHEC | D19: TERCEROS | E19: MANIZALES | F19: 45806 | G19: Manizales | H19: C35 | J19: =VLOOKUP(H19,VALIDACIONES!$A$2:$B$138,2,0) -> No realizar la revisión técnico mecánica y de emisiones en los siguientes plazos o cuando aún portando los certificados correspondientes no cuenta con las siguientes condiciones tecnicomecánica y de emisiones contaminantes, además el vehiculo será inmovilizado.(verlistado) | K19: 603939 | L19: =MONTH(F19) -> 5 | M19: =YEAR(F19) -> 2025 | N19: CAPACITACIÓN | O19: 45819 | P19: CAPACITACIÓN MANEJO DEFENSIVO | Q19: PAGO | R19: ACTIVO | S19: NO | T19: NO | U19: SI
A20: 8111021 | B20: ESPINOZA GUZMAN JUAN BAUTISTA | C20: UT MEJIA Y ACEVEDO SYE VOLQUET | D20: TERCEROS | E20: MEDELLIN | F20: 45805 | G20: Manizales | H20: C35 | J20: =VLOOKUP(H20,VALIDACIONES!$A$2:$B$138,2,0) -> No realizar la revisión técnico mecánica y de emisiones en los siguientes plazos o cuando aún portando los certificados correspondientes no cuenta con las siguientes condiciones tecnicomecánica y de emisiones contaminantes, además el vehiculo será inmovilizado.(verlistado) | K20: 604054 | L20: =MONTH(F20) -> 5 | M20: =YEAR(F20) -> 2025 | N20: CAPACITACIÓN | O20: 45819 | P20: CAPACITACIÓN MANEJO DEFENSIVO | Q20: PAGO | R20: ACTIVO | S20: NO | T20: NO | U20: SI
A21: 1144173726 | B21: MURCIA OROZCO JOHN HAWER | C21: ADMINISTRATIVO | D21: TERCEROS | E21: MEDELLIN | F21: 45806 | G21: Medellin | H21: C02 | J21: =VLOOKUP(H21,VALIDACIONES!$A$2:$B$138,2,0) -> Estacionar un vehículo en los sitios prohibidos por el Código Nacional de Tránsito, reglamentado por la Res.3027. | K21: 604054 | L21: =MONTH(F21) -> 5 | M21: =YEAR(F21) -> 2025 | N21: CAPACITACIÓN | O21: 45819 | P21: CAPACITACIÓN MANEJO DEFENSIVO | Q21: PAGO | R21: ACTIVO | S21: SI | T21: NO | U21: NO | V21: SI
A22: 1152466310 | B22: ZULUAGA VASQUEZ STIVEN | C22: UT MEJIA Y ACEVEDO SYE VOLQUET | D22: TERCEROS | E22: MEDELLIN | F22: 45800 | G22: Envigado | H22: C14 | I22: EQX587 | J22: =VLOOKUP(H22,VALIDACIONES!$A$2:$B$138,2,0) -> Transitar por los siguientes sitios restringidos o en horas prohibidas por laautoridad competente. Además, el vehículo será inmovilizado.(verlistado) | K22: 604000 | L22: =MONTH(F22) -> 5 | M22: =YEAR(F22) -> 2025 | N22: CAPACITACIÓN | O22: 45819 | P22: CAPACITACIÓN MANEJO DEFENSIVO | Q22: NO PAGO | R22: ACTIVO | S22: NO | U22: SI
A23: 1089718997 | B23: SANCHEZ JARAMILLO GUSTAVO DE JESUS | C23: CHEC | D23: TERCEROS | E23: MANIZALES | F23: 45826 | G23: La Dorada | H23: C29 | I23: JTY069 | J23: =VLOOKUP(H23,VALIDACIONES!$A$2:$B$138,2,0) -> Conducir un vehículo a velocidad superior a la máxima permitida, la cual deberá estar señalizada en forma sectorizada, no obstante esta no podrá ser superior a (verlistado) | K23: 603930 | L23: =MONTH(F23) -> 6 | M23: =YEAR(F23) -> 2025 | N23: CAPACITACION | O23: 45842 | P23: CAPACITACIÓN MANEJO DEFENSIVO
A24: 1036132399 | B24: SANCHEZ JARAMILLO GUSTAVO DE JESUS | C24: UT MEJIA Y ACEVEDO SYE VOLQUET | D24: TERCEROS | E24: MEDELLIN | F24: 45852 | G24: Barbosa | H24: C11 | I24: TAV412 | J24: =VLOOKUP(H24,VALIDACIONES!$A$2:$B$138,2,0) -> Noportarcomomínimoelsiguienteequipodeprevenciónyseguridad.(verlistado) | K24: 603930 | L24: =MONTH(F24) -> 7 | M24: =YEAR(F24) -> 2025 | N24: CAPACITACION | O24: 45877 | P24: CAPACITACIÓN MANEJO DEFENSIVO | R24: ACTIVO
A25: 10271854 | B25: GUTIERREZ JHON JAIRO | C25: CHEC | D25: TERCEROS | E25: MANIZALES | F25: 45879 | G25: Manizales | H25: D04 | I25: NAH330 | J25: =VLOOKUP(H25,VALIDACIONES!$A$2:$B$138,2,0) -> Nodetenerseanteunaluzrojaoamarilladesemáforo,unaseñalde"PARE"ounsemáforointermitenteenrojo.Enelcasodemotocicletaseprocederaasuinmovilizaciónhastatantonosepagueelvalordelamultaolaautoridadcompetentedecidasobresuimposicionenlosterminosdelosarticulos135y136delcódigonacionaldetránsito. | K25: 1207855 | L25: =MONTH(F25) -> 8 | M25: =YEAR(F25) -> 2025 | N25: CAPACITACION | O25: 45911 | P25: CAPACITACIÓN EN NORMAS DE TRANSITO | Q25: PAGO | R25: ACTIVO | S25: SI | T25: NO | U25: SI | V25: SI
A26: 71692190 | B26: LEON MEJIA DARIO | C26: FLOTA PROPIA | D26: FLOTA PROPIA | E26: MEDELLIN | F26: 45898 | G26: Bello | H26: H13 | I26: TDK561 | J26: =VLOOKUP(H26,VALIDACIONES!$A$2:$B$138,2,0) -> Las demas conductas que constituyan infraccion a las normas de transito y que no se encuentren descritas en este acto administrativo. | K26: 201351 | L26: 8 | M26: 2025 | N26: CAPACITACION | O26: 45911 | P26: CAPACITACIÓN EN NORMAS DE TRANSITO | Q26: ACUERDO DE PAGO | R26: ACTIVO | U26: Si | V26: No | W26: No tiene que realizar pago, solo curso
A27: 8402361 | B27: LLANO PEREZ ARMANDO ELADIO | C27: FUNDACION EPM | D27: TERCEROS | E27: MEDELLIN | F27: 45892 | G27: La Dorada | H27: C29 | I27: WCQ092 | J27: =VLOOKUP(H27,VALIDACIONES!$A$2:$B$138,2,0) -> Conducir un vehículo a velocidad superior a la máxima permitida, la cual deberá estar señalizada en forma sectorizada, no obstante esta no podrá ser superior a (verlistado) | K27: 603930 | L27: =MONTH(F27) -> 8 | M27: =YEAR(F27) -> 2025 | N27: CAPACITACION | O27: 45911 | P27: CAPACITACIÓN MANEJO DEFENSIVO | R27: ACTIVO
A28: 98570609 | B28: RODRIGUEZ CASTANO SERGIO | C28: GRUPO SURA | D28: TERCEROS | E28: MEDELLIN | F28: 45878 | G28: Medellin | H28: C35 | J28: =VLOOKUP(H28,VALIDACIONES!$A$2:$B$138,2,0) -> No realizar la revisión técnico mecánica y de emisiones en los siguientes plazos o cuando aún portando los certificados correspondientes no cuenta con las siguientes condiciones tecnicomecánica y de emisiones contaminantes, además el vehiculo será inmovilizado.(verlistado) | K28: 604054 | L28: =MONTH(F28) -> 8 | M28: =YEAR(F28) -> 2025 | N28: CAPACITACION | O28: 45911 | P28: CAPACITACIÓN EN NORMAS DE TRANSITO | Q28: PAGO | R28: ACTIVO | S28: SI | T28: NO | U28: SI | V28: SI
A29: 71613262 | B29: VELEZ VELEZ LUIS ORLANDO | C29: UT MEJIA Y ACEVEDO SYE VOLQUET | D29: TERCEROS | E29: MEDELLIN | F29: 45873 | G29: Sabaneta | H29: C26 | I29: SLP053 | J29: =VLOOKUP(H29,VALIDACIONES!$A$2:$B$138,2,0) -> Transitarenvehículosde3.5omástoneladasporelcarrilizquierdodelavíacuandohubieremásdeuncarril. | K29: 603939 | L29: =MONTH(F29) -> 8 | M29: =YEAR(F29) -> 2025 | N29: CAPACITACION | O29: 45911 | P29: CAPACITACIÓN EN NORMAS DE TRANSITO | Q29: PAGO | R29: ACTIVO | S29: NO | T29: NO | U29: SI | V29: NO
A30: 71268105 | B30: TORO LONDONO ANDRES ANTONIO | C30: ISAGEN - JAGUAS | D30: FLOTA PROPIA | E30: MEDELLIN | F30: 45887 | G30: BUGALAGRANDE - DEPT VALLE | H30: C29 | I30: YBE02E | J30: =VLOOKUP(H30,VALIDACIONES!$A$2:$B$138,2,0) -> Conducir un vehículo a velocidad superior a la máxima permitida, la cual deberá estar señalizada en forma sectorizada, no obstante esta no podrá ser superior a (verlistado) | K30: 603939 | L30: =MONTH(F30) -> 8 | M30: =YEAR(F30) -> 2025 | N30: CAPACITACION | O30: 45911 | P30: CAPACITACIÓN MANEJO DEFENSIVO | Q30: NO PAGO | R30: ACTIVO | S30: SI | T30: SI | U30: SI | V30: NO
A31: 1070603395 | B31: UGHETTI ECHEVERRIA DAVID | C31: EPM NUEVO | D31: TERCEROS | E31: MEDELLIN | F31: 45884 | G31: San Jeronimo - Dept Antioquia | H31: C02 | I31: SNX263 | J31: =VLOOKUP(H31,VALIDACIONES!$A$2:$B$138,2,0) -> Estacionar un vehículo en los sitios prohibidos por el Código Nacional de Tránsito, reglamentado por la Res.3027. | K31: 603939 | L31: =MONTH(F31) -> 8 | M31: =YEAR(F31) -> 2025 | N31: CAPACITACION | O31: 45911 | P31: CAPACITACIÓN EN NORMAS DE TRANSITO | Q31: NO PAGO | R31: ACTIVO | U31: SI
A32: 1001237255 | B32: AGUIRRE OSORIO JUAN CAMILO | C32: UT MEJIA Y ACEVEDO SYE VOLQUET | D32: TERCEROS | E32: MEDELLIN | F32: 45909 | G32: Bello | H32: C06 | I32: STE056 | J32: =VLOOKUP(H32,VALIDACIONES!$A$2:$B$138,2,0) -> Noutilizarelcinturóndeseguridadporpartedelosocupantesdelvehículoyloscinturonesdeseguridadenlosasientostraserosenlosvehículosfabricadosapartirdelaño2004. | K32: 603939 | L32: =MONTH(F32) -> 9 | M32: =YEAR(F32) -> 2025 | N32: CAPACITACION | O32: 45939 | P32: CAPACITACIÓN POLITICAS DE SEGURIDAD VIAL | Q32: NO PAGO | R32: ACTIVO
A33: 1001237255 | B33: AGUIRRE OSORIO JUAN CAMILO | C33: UT MEJIA Y ACEVEDO SYE VOLQUET | D33: TERCEROS | E33: MEDELLIN | F33: 45902 | G33: Bello | H33: H13 | I33: STE056 | J33: =VLOOKUP(H33,VALIDACIONES!$A$2:$B$138,2,0) -> Las demas conductas que constituyan infraccion a las normas de transito y que no se encuentren descritas en este acto administrativo. | K33: 201351 | L33: =MONTH(F33) -> 9 | M33: =YEAR(F33) -> 2025 | N33: CAPACITACION | O33: 45939 | P33: CAPACITACIÓN MANEJO DEFENSIVO | Q33: PAGO | R33: ACTIVO
A34: 75108007 | B34: OSPINA LOPEZ JHON FREDY | C34: CHEC | D34: TERCEROS | E34: MANIZALES | F34: 45906 | G34: Anserma | H34: C02 | I34: GTU941 | J34: =VLOOKUP(H34,VALIDACIONES!$A$2:$B$138,2,0) -> Estacionar un vehículo en los sitios prohibidos por el Código Nacional de Tránsito, reglamentado por la Res.3027. | K34: 603930 | L34: =MONTH(F34) -> 9 | M34: =YEAR(F34) -> 2025 | N34: CAPACITACION | O34: 45939 | P34: CAPACITACIÓN EN NORMAS DE TRANSITO | Q34: NO PAGO | R34: ACTIVO
A35: 8433989 | B35: CORREA GUZMAN JULIO EDUARDO | C35: ADMINISTRATIVO | D35: ADMINISTRATIVOS | E35: MEDELLIN | F35: 45961 | G35: Medellin | H35: C24 | I35: ANV39H | J35: =VLOOKUP(H35,VALIDACIONES!$A$2:$B$138,2,0) -> Conducir motocicleta sin observar las siguientes normas.(verlistadodesituaciones) | K35: 604054 | L35: =MONTH(F35) -> 10 | M35: =YEAR(F35) -> 2025 | N35: CAPACITACION | O35: 45967 | P35: CAPACITACIÓN EN NORMAS DE TRANSITO
A36: 1017154790 | B36: GUZMAN LOTERO CARLOS MARIO | C36: FLOTA PROPIA | D36: FLOTA PROPIA | E36: MEDELLIN | F36: 45946 | G36: Medellin | H36: C02 | I36: LKL764 | J36: =VLOOKUP(H36,VALIDACIONES!$A$2:$B$138,2,0) -> Estacionar un vehículo en los sitios prohibidos por el Código Nacional de Tránsito, reglamentado por la Res.3027. | K36: 604054 | L36: =MONTH(F36) -> 10 | M36: =YEAR(F36) -> 2025 | N36: CAPACITACION
A37: 1152450531 | B37: IZQUIERDO ACEVEDO DANIEL | C37: FLOTA PROPIA | D37: FLOTA PROPIA | E37: MEDELLIN | F37: 45939 | G37: Itaguí | H37: C14 | I37: JLM04H | J37: =VLOOKUP(H37,VALIDACIONES!$A$2:$B$138,2,0) -> Transitar por los siguientes sitios restringidos o en horas prohibidas por laautoridad competente. Además, el vehículo será inmovilizado.(verlistado) | K37: 603930 | L37: =MONTH(F37) -> 10 | M37: =YEAR(F37) -> 2025 | N37: CAPACITACION
A38: 70033808 | B38: LOPEZ ECHEVERRY HECTOR RAMIRO | C38: EPM NUEVO | D38: TERCEROS | E38: MEDELLIN | F38: 45952 | G38: Medellin | H38: D03 | I38: GDW677 | J38: =VLOOKUP(H38,VALIDACIONES!$A$2:$B$138,2,0) -> Transitarensentidocontrarioalestipuladoparalavía,calzadaocarril.Enelcasodemotocicletaseprocederaasuinmovilizaciónhastatantonosepagueelvalordelamultaolaautoridadcompetentedecidasobresuimposicionenlosterminosdelosarticulos135y136delcódigonacionaldetránsito. | K38: 1207762 | L38: =MONTH(F38) -> 10 | M38: =YEAR(F38) -> 2025 | N38: CAPACITACION | O38: 45967 | P38: CAPACITACIÓN EN NORMAS DE TRANSITO
A39: 1017139302 | B39: SANCHEZ AGUDELO DEISY MIRELLA | C39: GRUPO SURA | D39: TERCEROS | E39: MEDELLIN | F39: 45936 | G39: Itaguí | H39: C14 | J39: =VLOOKUP(H39,VALIDACIONES!$A$2:$B$138,2,0) -> Transitar por los siguientes sitios restringidos o en horas prohibidas por laautoridad competente. Además, el vehículo será inmovilizado.(verlistado) | K39: 603930 | L39: =MONTH(F39) -> 10 | M39: =YEAR(F39) -> 2025 | N39: CAPACITACION
A40: 71315786 | B40: TAMAYO PEREZ GUILLERMO LEON | C40: EPM NUEVO | D40: TERCEROS | E40: MEDELLIN | F40: 45950 | G40: Sabaneta | H40: C35 | I40: RAS977 | J40: =VLOOKUP(H40,VALIDACIONES!$A$2:$B$138,2,0) -> No realizar la revisión técnico mecánica y de emisiones en los siguientes plazos o cuando aún portando los certificados correspondientes no cuenta con las siguientes condiciones tecnicomecánica y de emisiones contaminantes, además el vehiculo será inmovilizado.(verlistado) | K40: 603939 | L40: =MONTH(F40) -> 10 | M40: =YEAR(F40) -> 2025 | N40: CAPACITACION | O40: 45967 | P40: CAPACITACIÓN EN NORMAS DE TRANSITO
...

Sheet CORRESPONDENCIA
A1: CEDULA | B1: NOMBRE | C1: MES | D1: AÑO | E1: CODIGO INFRACCIÓN | F1: TEXTO | G1: DESCRIPICIÓN | H1: VALOR LETRAS | I1: VALOR
A2: 98613966 | B2: JHON FREDY CANO GOMEZ | C2: Diciembre | D2: 2024 | E2: C02 | F2: Estacionar un vehículo en los sitios prohibidos por el Código Nacional de Tránsito, reglamentado por la Res.3027. | G2: Estacionar un vehículo en los sitios prohibidos | H2: Quinientos dos mil seiscientos veintiocho pesos moneda legal colombiana | I2: $ 572.628,00
A3: 10271854 | B3: JHON JAIRO GUTIERREZ | C3: Diciembre | D3: 2024 | E3: D04 | F3: Nodetenerseanteunaluzrojaoamarilladesemáforo,unaseñalde"PARE"ounsemáforointermitenteenrojo.Enelcasodemotocicletaseprocederaasuinmovilizaciónhastatantonosepagueelvalordelamultaolaautoridadcompetentedecidasobresuimposicionenlosterminosdelosarticulos135y136delcódigonacionaldetránsito. | G3: No detenerse ante luz roja o PARE | H3: Quinientos dos mil seiscientos veintiocho pesos moneda legal colombiana | I3: $ 1.145.029,00
A4: 98514320 | B4: ALBERTO MUNOZ DIEZ | C4: Diciembre | D4: 2024 | E4: D02 | F4: ConducirsinportarelSeguroObligatoriodeAccidentesdetránsitoordenadoporlaley.Además,elvehículoseráinmovilizado. | G4: No portaba SOAT | H4: Quinientos dos mil seiscientos veintiocho pesos moneda legal colombiana | I4: $ 1.145.040,00
A5: 71947379 | B5: EDISON B SALDARRIAGA GUTIERREZ | C5: Diciembre | D5: 2024 | E5: C29 | F5: Conducir un vehículo a velocidad superior a la máxima permitida, la cual deberá estar señalizada en forma sectorizada, no obstante esta no podrá ser superior a (verlistado) | G5: Excesos de velocidad | H5: Quinientos dos mil seiscientos veintiocho pesos moneda legal colombiana | I5: $ 572.520,00
A6: 98646700 | B6: JAIME ANDRES ZAPATA RUA | C6: Diciembre | D6: 2024 | E6: C02 | F6: Estacionar un vehículo en los sitios prohibidos por el Código Nacional de Tránsito, reglamentado por la Res.3027. | G6: Estacionar un vehículo en los sitios prohibidos | H6: Quinientos dos mil seiscientos veintiocho pesos moneda legal colombiana | I6: $ 572.628,00
A7: 1002643041 | B7: MATEO GIRALDO GUTIERREZ | C7: Diciembre | D7: 2024 | E7: D04 | F7: Nodetenerseanteunaluzrojaoamarilladesemáforo,unaseñalde"PARE"ounsemáforointermitenteenrojo.Enelcasodemotocicletaseprocederaasuinmovilizaciónhastatantonosepagueelvalordelamultaolaautoridadcompetentedecidasobresuimposicionenlosterminosdelosarticulos135y136delcódigonacionaldetránsito. | G7: No detenerse ante luz roja o PARE | H7: Quinientos dos mil seiscientos veintiocho pesos moneda legal colombiana | I7: $ 1.145.040,00
A8: 71601030 | B8: JAIME ALBERTO ESCOBAR POSADA | C8: Diciembre | D8: 2024 | E8: C29 | F8: Conducir un vehículo a velocidad superior a la máxima permitida, la cual deberá estar señalizada en forma sectorizada, no obstante esta no podrá ser superior a (verlistado) | G8: Excesos de velocidad | H8: Quinientos dos mil seiscientos veintiocho pesos moneda legal colombiana | I8: $ 572.498,00

Sheet VALIDACIONES
A1: Código Infracción | B1: Infracción | C1: SMLDV | D1: Columna1 | E1: Moto | F1: Carro | G1: NoAutomotor | I1: Tipo Contrato | J1: Ciudad | K1: Capacitación | L1: Control infracciones | M1: Tipo de Accion | N1: ESTADO | O1: SI/NO
A2: A01 | B2: No transitar por la derecha de la vía. | C2: 4 | D2: $ 91,927 | I2: ADMINISTRATIVOS | J2: ARMENIA | K2: CAPACITACIÓN SEGURIDAD VIAL Y MOVILIDAD | L2: PAGO | M2: CAPACITACION | N2: ACTIVO | O2: SI
A3: A02 | B3: Agarrarse de otro vehículo en movimiento. | C3: 4 | D3: $ 91,927 | I3: FLOTA PROPIA | J3: BOGOTA | K3: CAPACITACIÓN CONTROL DE EXCESOS DE VELOCIDAD | L3: NO PAGO | M3: SUSPENSION | N3: INACTIVO | O3: NO
A4: A03 | B4: Transportar personas o cosas que disminuyen su visibilidad o incomoden la conducción. | C4: 4 | D4: $ 91,927 | I4: TERCEROS | J4: BUGA | K4: CAPACITACIÓN EN NORMAS DE TRANSITO | L4: ACUERDO DE PAGO | M4: RETIRO
A5: A04 | B5: Transitar por andenes,aceras,puentes o demás lugares de uso exclusivo para el tránsito de personas. | C5: 4 | D5: $ 91,927 | J5: CALI | K5: CAPACITACIÓN POLITICAS DE SEGURIDAD VIAL | M5: N/A
A6: A05 | B6: No respetar las señales de tránsito. | C6: 4 | D6: $ 91,927 | J6: IBAGUE | K6: CAPACITACIÓN MANEJO DEFENSIVO
A7: A06 | B7: Transitar sin los dispositivos luminosos requeridos. | C7: 4 | D7: $ 91,927 | J7: MANIZALES
A8: A07 | B8: Transitar sin dispositivos que permitan la parada inmediata o con ellos, pero en estado de fectuoso. | C8: 4 | D8: $ 91,927 | J8: MEDELLIN
A9: A08 | B9: Transitarporzonasprohibidaso,poraquellasvíasendondelasautoridadescompetentesloprohíbano,conducirporvíasdiferentesaaquellasdiseñadasparaello,cuandolashubiere. | C9: 4 | D9: $ 91,927 | J9: PEREIRA
A10: A09 | B10: Adelantar entre dos vehículos automotores que estén en sus respectivos carriles. | C10: 4 | D10: $ 91,927 | J10: POPAYAN
A11: A10 | B11: Conducir por la vía férrea o por zonas de protección y seguridad. | C11: 4 | D11: $ 91,927 | J11: RIONEGRO
A12: A11 | B12: Transitar por zonas restringidas o por vías de alta velocidad como autopistas y arterias. | C12: 4 | D12: $ 91,927 | G12: X | J12: SOGAMOSO
A13: A12 | B13: Prestar servicio público con este tipo de vehículos. Además, el vehículo será inmovilizado por primera vez por 5días, 20 días por segunda vez y 40 días por tercera vez. | C13: 4 | D13: $ 91,927 | G13: X | J13: MIEL
A14: B01 | B14: Conducir un vehículo sin llevar consigo la licencia de conducción. | C14: 8 | D14: $ 183,854 | J14: SAN CARLOS
A15: B02 | B15: Conducir un vehículo con la licencia de conducción vencida. | C15: 8 | D15: $ 183,854 | E15: X | F15: X | J15: JAGUAS
A16: B03 | B16: Conducir un vehículo sin placas, no portar la senel extremo delantero o trasero, portarlas con obstáculos o encondiciones que dificulten su plena identificación, portar en el lugar destinado a las placas, distintivos similares a éstas o que la imiten o que correspondan a placas de otros países o, sin el permiso vigente expedido por autoridad de tránsito. Realizar cambio en las características que identifican un vehículo automotor, cambiar, modificar o adulterar los números de identificación del motor, chasis o serie de un vehículo. | C16: 8 | D16: $ 183,854 | E16: X | F16: X | J16: CALDERAS
A17: B04 | B17: Conducir un vehículo con placas adulteradas, retocadas o alteradas. | C17: 8 | D17: $ 183,854 | E17: X | F17: X | J17: AMOYA
A18: B05 | B18: Conducir un vehículo con una sola placa, o sin el permiso vigente expedido por autoridad de tránsito. | C18: 8 | D18: $ 183,854 | E18: X | F18: X
A19: B06 | B19: Conducir un vehículo con placas falsas. | C19: 8 | D19: $ 183,854 | E19: X | F19: X
A20: B07 | B20: No informar a la autoridad de tránsito competente el cambio de motor o color de un vehículo. En ambos casos, el vehículo será inmovilizado. | C20: 8 | D20: $ 183,854 | E20: X | F20: X
A21: B08 | B21: No pagar el peaje en los sitios establecidos. | C21: 8 | D21: $ 183,854 | E21: X | F21: X
A22: B09 | B22: Utilizar equipos de sonido a volúmenes que incomoden a los pasajeros de un vehículo de servicio público. | C22: 8 | D22: $ 183,854
A23: B10 | B23: Conducirunvehículoconvidriospolarizados,entintadosuoscurecidos,sinportarelpermisorespectivo,deacuerdoalareglamentaciónexistenteo,nollevarelvehículodeserviciopúblicocolectivourbanoconlosvidriostransparentes. | C23: 8 | D23: $ 183,854
A24: B11 | B24: Conducirunvehículoconpropaganda,publicidadoadhesivosensusvidriosqueobstaculicenlavisibilidad. | C24: 8 | D24: $ 183,854
A25: B12 | B25: No respetar las normas establecidas por la autoridad competente para el tránsito de cortejos fúnebres. | C25: 8 | D25: $ 183,854
A26: B13 | B26: Norespetarlasformacionesdetropas,lamarchadedesfiles,procesiones,entierros,filasestudiantilesylasmanifestacionespúblicasyactividadesdeportivas,debidamenteautorizadasporlasautoridadesdetránsito. | C26: 8 | D26: $ 183,854
A27: B14 | B27: RemolcarotrovehículoviolandolodispuestoenelArtículo72delCódigoNacionaldeTránsito. | C27: 8 | D27: $ 183,854
A28: B15 | B28: Conducirunvehículodeserviciopúblicoquenolleveelavisodetarifasoficialesencondicionesdefácillecturaparalospasajerosoposeeresteavisodeterioradooadulterado. | C28: 8 | D28: $ 183,854
A29: B16 | B29: Permitirqueenunvehículodeserviciopúblicoparatransportedepasajerossellevenanimalesuobjetosqueincomodenalospasajeros. | C29: 8 | D29: $ 183,854
A30: B17 | B30: Abandonarunvehículodeserviciopúblicoconpasajeros. | C30: 8 | D30: $ 183,854
A31: B18 | B31: Notransitarporelcarrilderechoelvehículodetransportepúblicoindividualcuandotransitasinpasajerosindicandoladisponibilidadparaprestarelservicio,medianteluzespecialolaseñalluminosadeestarlibre. | C31: 8 | D31: $ 183,854
A32: B19 | B32: Realizarelcargueodescarguedeunvehículoensitiosyhorasprohibidasporlasautoridadescompetentes,deacuerdoconloestablecidoenlasnormascorrespondientes. | C32: 8 | D32: $ 183,854
A33: B20 | B33: Transportarcarne,pescadooalimentosfácilmentecorruptibles,envehículosquenocumplanlascondicionesfijadasporelMinisteriodeTransporte. | C33: 8 | D33: $ 183,854
... A37: C01 | B37: Presentarlicenciadeconducciónadulteradaoajena,locualdarálugaralainmovilizacióndelvehículo. | C37: 15 | D37: $ 344,727
A38: C02 | B38: Estacionar un vehículo en los sitios prohibidos por el Código Nacional de Tránsito, reglamentado por la Res.3027. | C38: 15 | D38: $ 344,727 | E38: X | F38: X
A39: C03 | B39: Bloquearunacalzadaointersecciónconunvehículo,salvocuandoelbloqueoobedezcaalaocurrenciadeunaccidente. | C39: 15 | D39: $ 344,727
A40: C04 | B40: Estacionarunvehículosintomarlassiguientesprecauciones:(verlistado) | C40: 15 | D40: $ 344,727
A41: C05 | B41: Noreducirlavelocidada30kilómetrosporhoraenlossiguientescasos:(Verlistado) | C41: 15 | D41: $ 344,727
A42: C06 | B42: Noutilizarelcinturóndeseguridadporpartedelosocupantesdelvehículoyloscinturonesdeseguridadenlosasientostraserosenlosvehículosfabricadosapartirdelaño2004. | C42: 15 | D42: $ 344,727
A43: C07 | B43: Dejardeseñalizar(verlistadodesituaciones) | C43: 15 | D43: $ 344,727
...

Sheet INFRACCIONES 2017-2024
A1: Cedula | B1: Nombre completo | C1: Centros de Costos | D1: Tipo de Contrato | E1: Ciudad | F1: Fecha Infracción | G1: Lugar de la Infraccion | H1: Código infracción | I1: Descripción Infracciones | J1: Valor Infracción | K1: Tipo de Acción | L1: Fecha de Notificación | M1: Clase de Capacitación | N1: Mes | O1: Año | P1: Control Infracciones | Q1: ESTADO | R1: DEVOLUCION NOTIFICACION | S1: DEVOLUCION REGISTRO DE FORMACION | T1: CAPACITACION Y EVALUACION | U1: Observaciones
A2: 98534209 | B2: JUAN MANUEL LOPEZ CUESTA | C2: EMTELCO | D2: TERCEROS | E2: MEDELLIN | F2: 42761 | G2: 05088000 Bello | H2: H13 | I2: =VLOOKUP(H2,VALIDACIONES!$A$2:$B$138,2,0) -> Las demas conductas que constituyan infraccion a las normas de transito y que no se encuentren descritas en este acto administrativo. | J2: 0 | K2: CAPACITACION | M2: CAPACITACIÓN SEGURIDAD VIAL Y MOVILIDAD | N2: =MONTH(F2) -> 1 | O2: =YEAR(F2) -> 2017
A3: 10142350 | B3: JULIAN ANDRES NARANJO GARCIA | C3: TELEFONICA DE PEREIRA | D3: TERCEROS | E3: PEREIRA | F3: 42738 | G3: 76147000 Cartago | H3: C29 | I3: =VLOOKUP(H3,VALIDACIONES!$A$2:$B$138,2,0) -> Conducir un vehículo a velocidad superior a la máxima permitida, la cual deberá estar señalizada en forma sectorizada, no obstante esta no podrá ser superior a (verlistado) | J3: 368858 | K3: CAPACITACION | M3: CAPACITACIÓN SEGURIDAD VIAL Y MOVILIDAD | N3: =MONTH(F3) -> 1 | O3: =YEAR(F3) -> 2017
A4: 71607384 | B4: WILFREDO DE JESUS ALARCA MEDINA | C4: EPM | D4: TERCEROS | E4: MEDELLIN | F4: 42752 | G4: 05847000 Urrao | H4: B01 | I4: =VLOOKUP(H4,VALIDACIONES!$A$2:$B$138,2,0) -> Conducir un vehículo sin llevar consigo la licencia de conducción. | J4: 98364 | K4: CAPACITACION | M4: CAPACITACIÓN EN NORMAS DE TRANSITO | N4: =MONTH(F4) -> 1 | O4: =YEAR(F4) -> 2017
A5: 15481162 | B5: RUBEN DARIO HIGUITA DURAN | C5: FLOTA PROPIA | D5: FLOTA PROPIA | E5: MEDELLIN | F5: 42790 | G5: 05360000 Itaguí | H5: B19 | I5: =VLOOKUP(H5,VALIDACIONES!$A$2:$B$138,2,0) -> Realizarelcargueodescarguedeunvehículoensitiosyhorasprohibidasporlasautoridadescompetentes,deacuerdoconloestablecidoenlasnormascorrespondientes. | J5: 196728 | K5: CAPACITACIÓN | N5: =MONTH(F5) -> 2 | O5: =YEAR(F5) -> 2017
A6: 18502611 | B6: ALVARO SALAZAR GOMEZ | C6: TELEFONICA DE PEREIRA | D6: TERCEROS | E6: PEREIRA | F6: 42772 | G6: 66001000 Pereira | H6: C38 | I6: =VLOOKUP(H6,VALIDACIONES!$A$2:$B$138,2,0) -> Usar sistemas móviles de comunicación o teléfonos instalados en los vehículos al momento de conducir, exceptuando si éstos son utilizados con accesorios o equipos auxiliares que permitan tener las manos libres. | J6: 368859 | K6: CAPACITACIÓN | N6: =MONTH(F6) -> 2 | O6: =YEAR(F6) -> 2017
A7: 71294662 | B7: HECTOR MAURICIO BOHORQUEZ CHICA | C7: SERV AMBIENTALES GEOGRAFICOS | D7: TERCEROS | E7: MEDELLIN | F7: 42772 | G7: 05266000 Envigado | H7: C24 | I7: =VLOOKUP(H7,VALIDACIONES!$A$2:$B$138,2,0) -> Conducir motocicleta sin observar las siguientes normas.(verlistadodesituaciones) | J7: 368865 | K7: CAPACITACIÓN | N7: =MONTH(F7) -> 2 | O7: =YEAR(F7) -> 2017
A8: 71741519 | B8: JUAN CARLOS LALINDE CASTRILLON | C8: EMTELCO | D8: TERCEROS | E8: MEDELLIN | F8: 42787 | G8: 05360000 Itaguí | H8: C38 | I8: =VLOOKUP(H8,VALIDACIONES!$A$2:$B$138,2,0) -> Usar sistemas móviles de comunicación o teléfonos instalados en los vehículos al momento de conducir, exceptuando si éstos son utilizados con accesorios o equipos auxiliares que permitan tener las manos libres. | J8: 368865 | K8: CAPACITACIÓN | N8: =MONTH(F8) -> 2 | O8: =YEAR(F8) -> 2017
A9: 98567164 | B9: DIEGO ARMANDO MONTOYA ARANGO | C9: EPM | D9: TERCEROS | E9: MEDELLIN | F9: 42770 | G9: 05001000 Medellin | H9: C06 | I9: =VLOOKUP(H9,VALIDACIONES!$A$2:$B$138,2,0) -> Noutilizarelcinturóndeseguridadporpartedelosocupantesdelvehículoyloscinturonesdeseguridadenlosasientostraserosenlosvehículosfabricadosapartirdelaño2004. | J9: 368865 | K9: CAPACITACIÓN | N9: =MONTH(F9) -> 2 | O9: =YEAR(F9) -> 2017
A10: 1107055509 | B10: FRANKLY MARINO OROZCO | C10: EMTELCO | D10: TERCEROS | E10: CALI | F10: 42776 | G10: 76001000 Cali | H10: D02 | I10: =VLOOKUP(H10,VALIDACIONES!$A$2:$B$138,2,0) -> ConducirsinportarelSeguroObligatoriodeAccidentesdetránsitoordenadoporlaley.Además,elvehículoseráinmovilizado. | J10: 762.33 | K10: CAPACITACIÓN | N10: =MONTH(F10) -> 2 | O10: =YEAR(F10) -> 2017
A11: 1128267059 | B11: JHOVANNY ESNEIDER RAMIREZ RAMIREZ | C11: EPM | D11: TERCEROS | E11: MEDELLIN | F11: 42783 | G11: 05001000 Medellin | H11: C38 | I11: =VLOOKUP(H11,VALIDACIONES!$A$2:$B$138,2,0) -> Usar sistemas móviles de comunicación o teléfonos instalados en los vehículos al momento de conducir, exceptuando si éstos son utilizados con accesorios o equipos auxiliares que permitan tener las manos libres. | J11: 368865 | K11: CAPACITACIÓN | N11: =MONTH(F11) -> 2 | O11: =YEAR(F11) -> 2017
A12: 4403863 | B12: LUIS FERNANDO CARDONA RIVERA | C12: EMTELCO | D12: TERCEROS | E12: ARMENIA | F12: 42822 | G12: 63001000 Armenia | H12: C38 | I12: =VLOOKUP(H12,VALIDACIONES!$A$2:$B$138,2,0) -> Usar sistemas móviles de comunicación o teléfonos instalados en los vehículos al momento de conducir, exceptuando si éstos son utilizados con accesorios o equipos auxiliares que permitan tener las manos libres. | J12: 368865 | K12: CAPACITACIÓN | M12: CAPACITACIÓN SEGURIDAD VIAL Y MOVILIDAD | N12: =MONTH(F12) -> 3 | O12: =YEAR(F12) -> 2017
A13: 10139971 | B13: JAVIER DUQUE VARGAS | C13: TELEFONICA DE PEREIRA | D13: TERCEROS | E13: PEREIRA | F13: 42808 | G13: 76147000 Cartago | H13: C29 | I13: =VLOOKUP(H13,VALIDACIONES!$A$2:$B$138,2,0) -> Conducir un vehículo a velocidad superior a la máxima permitida, la cual deberá estar señalizada en forma sectorizada, no obstante esta no podrá ser superior a (verlistado) | J13: 368858 | K13: CAPACITACIÓN | M13: CAPACITACIÓN SEGURIDAD VIAL Y MOVILIDAD | N13: =MONTH(F13) -> 3 | O13: =YEAR(F13) -> 2017
A14: 10258031 | B14: LUIS MIGUEL GOMEZ CARO | C14: EMTELCO | D14: TERCEROS | E14: MEDELLIN | F14: 42824 | G14: 05380000 La Estrella | H14: C31 | I14: =VLOOKUP(H14,VALIDACIONES!$A$2:$B$138,2,0) -> No acatar las señales o requerimientos impartidos por los agentes de Tránsito. | J14: 368865 | K14: CAPACITACIÓN | M14: CAPACITACIÓN SEGURIDAD VIAL Y MOVILIDAD | N14: =MONTH(F14) -> 3 | O14: =YEAR(F14) -> 2017
A15: 16219255 | B15: ALVARO HERNAN LONDO¿O BETANCURT | C15: TELEFONICA DE PEREIRA | D15: TERCEROS | E15: PEREIRA | F15: 42795 | G15: 68276000 Floridablanca | H15: C02 | I15: =VLOOKUP(H15,VALIDACIONES!$A$2:$B$138,2,0) -> Estacionar un vehículo en los sitios prohibidos por el Código Nacional de Tránsito, reglamentado por la Res.3027. | J15: 368859 | K15: CAPACITACIÓN | M15: CAPACITACIÓN SEGURIDAD VIAL Y MOVILIDAD | N15: =MONTH(F15) -> 3 | O15: =YEAR(F15) -> 2017
A16: 71663939 | B16: ILDEBRANDO GIRALDO GOMEZ | C16: EPM | D16: TERCEROS | E16: MEDELLIN | F16: 42801 | G16: 05887000 Yarumal (Polca) | H16: D06 | I16: =VLOOKUP(H16,VALIDACIONES!$A$2:$B$138,2,0) -> Adelantaraotrovehículoenberma,túnel,puente,curva,pasosanivelycrucesnoreguladosoalaproximarsealacimadeunacuestaodondelaseñaldetránsitocorrespondienteloindique.Enelcasodemotocicletaseprocederaasuinmovilizaciónhastatantonosepagueelvalordelamultaolaautoridadcompetentedecidasobresuimposicionenlosterminosdelosarticulos135y136delcódigonacionaldetránsito. | J16: 737717 | K16: CAPACITACIÓN | M16: CAPACITACIÓN SEGURIDAD VIAL Y MOVILIDAD | N16: =MONTH(F16) -> 3 | O16: =YEAR(F16) -> 2017
A17: 98676634 | B17: RAMIRO FLOREZ NIETO | C17: SERV AMBIENTALES GEOGRAFICOS | D17: TERCEROS | E17: MEDELLIN | F17: 42796 | G17: 05001000 Medellin | H17: C35 | I17: =VLOOKUP(H17,VALIDACIONES!$A$2:$B$138,2,0) -> No realizar la revisión técnico mecánica y de emisiones en los siguientes plazos o cuando aún portando los certificados correspondientes no cuenta con las siguientes condiciones tecnicomecánica y de emisiones contaminantes, además el vehiculo será inmovilizado.(verlistado) | J17: 368865 | K17: CAPACITACIÓN | M17: CAPACITACIÓN SEGURIDAD VIAL Y MOVILIDAD | N17: =MONTH(F17) -> 3 | O17: =YEAR(F17) -> 2017
A18: 18154430 | B18: JHON JAIRO SALAZAR BERRIO | C18: EMPRESA ENERGIA DE PEREIRA | D18: TERCEROS | E18: PEREIRA | F18: 42826 | G18: 66001000 Pereira | H18: C02 | I18: =VLOOKUP(H18,VALIDACIONES!$A$2:$B$138,2,0) -> Estacionar un vehículo en los sitios prohibidos por el Código Nacional de Tránsito, reglamentado por la Res.3027. | J18: 230537 | K18: CAPACITACIÓN | N18: =MONTH(F18) -> 4 | O18: =YEAR(F18) -> 2017
A19: 70117652 | B19: FRANCISCO JAVIER NORE¿A HURTADO | C19: TELEMEDELLIN | D19: TERCEROS | E19: MEDELLIN | F19: 42850 | G19: 05001000 Medellin | H19: B10 | I19: =VLOOKUP(H19,VALIDACIONES!$A$2:$B$138,2,0) -> Conducirunvehículoconvidriospolarizados,entintadosuoscurecidos,sinportarelpermisorespectivo,deacuerdoalareglamentaciónexistenteo,nollevarelvehículodeserviciopúblicocolectivourbanoconlosvidriostransparentes. | J19: 196728 | K19: CAPACITACIÓN | N19: =MONTH(F19) -> 4 | O19: =YEAR(F19) -> 2017
A20: 70555881 | B20: JAIR DE JESUS DIOSA MONCADA | C20: EPM | D20: TERCEROS | E20: MEDELLIN | F20: 42836 | G20: 05380000 La Estrella | H20: D04 | I20: =VLOOKUP(H20,VALIDACIONES!$A$2:$B$138,2,0) -> Nodetenerseanteunaluzrojaoamarilladesemáforo,unaseñalde"PARE"ounsemáforointermitenteenrojo.Enelcasodemotocicletaseprocederaasuinmovilizaciónhastatantonosepagueelvalordelamultaolaautoridadcompetentedecidasobresuimposicionenlosterminosdelosarticulos135y136delcódigonacionaldetránsito. | J20: 737717 | K20: CAPACITACIÓN | N20: =MONTH(F20) -> 4 | O20: =YEAR(F20) -> 2017
A21: 1128405439 | B21: JUAN ESTEBAN AGUDELO | C21: EPM | D21: TERCEROS | E21: MEDELLIN | F21: 42852 | G21: 05079000 Barbosa | H21: C29 | I21: =VLOOKUP(H21,VALIDACIONES!$A$2:$B$138,2,0) -> Conducir un vehículo a velocidad superior a la máxima permitida, la cual deberá estar señalizada en forma sectorizada, no obstante esta no podrá ser superior a (verlistado) | J21: 230537 | K21: CAPACITACIÓN | N21: =MONTH(F21) -> 4 | O21: =YEAR(F21) -> 2017
A22: 1152703369 | B22: JOHAN E HERRERA VARGAS | C22: INMEL | D22: TERCEROS | E22: MEDELLIN | F22: 42844 | G22: 05631000 Sabaneta | H22: D17 | I22: =VLOOKUP(H22,VALIDACIONES!$A$2:$B$138,2,0) -> Cuandosedetecteoadviertaunainfracciónalasnormasdeemisióncontaminantesodegeneraciónderuidoporvehículosautomotores | J22: 73773 | K22: CAPACITACIÓN | N22: =MONTH(F22) -> 4 | O22: =YEAR(F22) -> 2017
A23: 10032356 | B23: JOHN EDWIN HERNANDEZ PUERTA | C23: EMPRESA ENERGIA DE PEREIRA | D23: TERCEROS | E23: PEREIRA | F23: 42870 | G23: 66001000 Pereira | H23: C06 | I23: =VLOOKUP(H23,VALIDACIONES!$A$2:$B$138,2,0) -> Noutilizarelcinturóndeseguridadporpartedelosocupantesdelvehículoyloscinturonesdeseguridadenlosasientostraserosenlosvehículosfabricadosapartirdelaño2004. | J23: 368859 | K23: CAPACITACIÓN | N23: =MONTH(F23) -> 5 | O23: =YEAR(F23) -> 2017
A24: 43907795 | B24: LEIDY VIVIANA PRECIADO ORTEGA | C24: ADMINISTRATIVO | D24: ADMINISTRATIVOS | E24: MEDELLIN | F24: 42873 | G24: 05380000 La Estrella | H24: C24 | I24: =VLOOKUP(H24,VALIDACIONES!$A$2:$B$138,2,0) -> Conducir motocicleta sin observar las siguientes normas.(verlistadodesituaciones) | J24: 368858 | K24: CAPACITACIÓN | N24: =MONTH(F24) -> 5 | O24: =YEAR(F24) -> 2017
A25: 70059512 | B25: WILLIAM DE JESUS RESTREPO SALAZAR | C25: EPM | D25: TERCEROS | E25: MEDELLIN | F25: 42882 | G25: 05001000 Medellin | H25: B02 | I25: =VLOOKUP(H25,VALIDACIONES!$A$2:$B$138,2,0) -> Conducir un vehículo con la licencia de conducción vencida. | J25: 196728 | K25: CAPACITACIÓN | N25: =MONTH(F25) -> 5 | O25: =YEAR(F25) -> 2017
A26: 71333282 | B26: WVLADIMIR RIVERA SUAREZ | C26: EMTELCO | D26: TERCEROS | E26: MEDELLIN | F26: 42873 | G26: 05088000 Bello | H26: C06 | I26: =VLOOKUP(H26,VALIDACIONES!$A$2:$B$138,2,0) -> Noutilizarelcinturóndeseguridadporpartedelosocupantesdelvehículoyloscinturonesdeseguridadenlosasientostraserosenlosvehículosfabricadosapartirdelaño2004. | J26: 368865 | K26: CAPACITACIÓN | N26: =MONTH(F26) -> 5 | O26: =YEAR(F26) -> 2017
A27: 71531701 | B27: LUIS FERNANDO MAYA ORTIZ | C27: COMERCIALIZADORA SYE | D27: TERCEROS | E27: MEDELLIN | F27: 42875 | G27: 05308000 Girardota | H27: C02 | I27: =VLOOKUP(H27,VALIDACIONES!$A$2:$B$138,2,0) -> Estacionar un vehículo en los sitios prohibidos por el Código Nacional de Tránsito, reglamentado por la Res.3027. | J27: 368859 | K27: CAPACITACIÓN | N27: =MONTH(F27) -> 5 | O27: =YEAR(F27) -> 2017
A28: 71727551 | B28: JULIO ZULUAGA PALACIO | C28: EPM | D28: TERCEROS | E28: MEDELLIN | F28: 42860 | G28: 05031000 Amalfi | H28: C11 | I28: =VLOOKUP(H28,VALIDACIONES!$A$2:$B$138,2,0) -> Noportarcomomínimoelsiguienteequipodeprevenciónyseguridad.(verlistado) | J28: 368865 | K28: CAPACITACIÓN | N28: =MONTH(F28) -> 5 | O28: =YEAR(F28) -> 2017
A29: 1107055509 | B29: FRANKLY MARINO OROZCO | C29: EMTELCO | D29: TERCEROS | E29: CALI | F29: 42878 | G29: 76001000 Cali | H29: C06 | I29: =VLOOKUP(H29,VALIDACIONES!$A$2:$B$138,2,0) -> Noutilizarelcinturóndeseguridadporpartedelosocupantesdelvehículoyloscinturonesdeseguridadenlosasientostraserosenlosvehículosfabricadosapartirdelaño2004. | J29: 393465 | K29: CAPACITACIÓN | N29: =MONTH(F29) -> 5 | O29: =YEAR(F29) -> 2017
... A35: 98530767 | B35: JOSE ALBERTO TIRADO MONTOYA | C35: EPM | D35: TERCEROS | E35: MEDELLIN | F35: 42898 | G35: 25875000 Villeta | H35: D06 | I35: =VLOOKUP(H35,VALIDACIONES!$A$2:$B$138,2,0) -> Adelantaraotrovehículoenberma,túnel,puente,curva,pasosanivelycrucesnoreguladosoalaproximarsealacimadeunacuestaodondelaseñaldetránsitocorrespondienteloindique.Enelcasodemotocicletaseprocederaasuinmovilizaciónhastatantonosepagueelvalordelamultaolaautoridadcompetentedecidasobresuimposicionenlosterminosdelosarticulos135y136delcódigonacionaldetránsito. | J35: 737717 | K35: CAPACITACIÓN | N35: =MONTH(F35) -> 6 | O35: =YEAR(F35) -> 2017
A36: 98566893 | B36: ELKIN ANDRES ESPINOSA CALDERON | C36: EMTELCO | D36: TERCEROS | E36: MEDELLIN | F36: 42895 | G36: 08001000 Barranquilla | H36: C29 | I36: =VLOOKUP(H36,VALIDACIONES!$A$2:$B$138,2,0) -> Conducir un vehículo a velocidad superior a la máxima permitida, la cual deberá estar señalizada en forma sectorizada, no obstante esta no podrá ser superior a (verlistado) | J36: 368.87 | K36: CAPACITACIÓN | N36: =MONTH(F36) -> 6 | O36: =YEAR(F36) -> 2017
A37: 1053797412 | B37: HERMES OLMEDO BARRIOS ORDO¿EZ | C37: EMPRESA ENERGIA DE PEREIRA | D37: TERCEROS | E37: PEREIRA | F37: 42896 | G37: 66001000 Pereira | H37: C02 | I37: =VLOOKUP(H37,VALIDACIONES!$A$2:$B$138,2,0) -> Estacionar un vehículo en los sitios prohibidos por el Código Nacional de Tránsito, reglamentado por la Res.3027. | J37: 368859 | K37: CAPACITACIÓN | N37: =MONTH(F37) -> 6 | O37: =YEAR(F37) -> 2017
A38: 1039023563 | B38: DIEGO ANDRES ALVAREZ ALVAREZ | C38: COMERCIALIZADORA SYE | D38: TERCEROS | E38: MEDELLIN | F38: 42929 | G38: 05001000 Medellin | H38: D04 | I38: =VLOOKUP(H38,VALIDACIONES!$A$2:$B$138,2,0) -> Nodetenerseanteunaluzrojaoamarilladesemáforo,unaseñalde"PARE"ounsemáforointermitenteenrojo.Enelcasodemotocicletaseprocederaasuinmovilizaciónhastatantonosepagueelvalordelamultaolaautoridadcompetentedecidasobresuimposicionenlosterminosdelosarticulos135y136delcódigonacionaldetránsito. | J38: 737730 | K38: CAPACITACIÓN | N38: =MONTH(F38) -> 7 | O38: =YEAR(F38) -> 2017
A39: 10125296 | B39: JESUS ALONSO LOAIZA RINCON | C39: EMTELCO | D39: TERCEROS | E39: PEREIRA | F39: 42943 | G39: 66001000 Pereira | H39: C35 | I39: =VLOOKUP(H39,VALIDACIONES!$A$2:$B$138,2,0) -> No realizar la revisión técnico mecánica y de emisiones en los siguientes plazos o cuando aún portando los certificados correspondientes no cuenta con las siguientes condiciones tecnicomecánica y de emisiones contaminantes, además el vehiculo será inmovilizado.(verlistado) | J39: 230537 | K39: CAPACITACIÓN | N39: =MONTH(F39) -> 7 | O39: =YEAR(F39) -> 2017
A40: 8399689 | B40: JAIME ALBEIRO RENDON OCAMPO | C40: FLOTA PROPIA | D40: FLOTA PROPIA | E40: MEDELLIN | F40: 42941 | G40: 05380000 La Estrella | H40: C24 | I40: =VLOOKUP(H40,VALIDACIONES!$A$2:$B$138,2,0) -> Conducir motocicleta sin observar las siguientes normas.(verlistadodesituaciones) | J40: 368858 | K40: CAPACITACIÓN | N40: =MONTH(F40) -> 7 | O40: =YEAR(F40) -> 2017
A41: 4519142 | B41: CESAR VILLA | C41: TELEFONICA DE PEREIRA | D41: TERCEROS | E41: PEREIRA | F41: 42937 | G41: 66001000 Pereira | H41: C02 | I41: =VLOOKUP(H41,VALIDACIONES!$A$2:$B$138,2,0) -> Estacionar un vehículo en los sitios prohibidos por el Código Nacional de Tránsito, reglamentado por la Res.3027. | J41: 368859 | K41: CAPACITACIÓN | N41: =MONTH(F41) -> 7 | O41: =YEAR(F41) -> 2017
A42: 10131845 | B42: CARLOS ALBERTO CARMONA HERNANDEZ | C42: TELEFONICA DE PEREIRA | D42: TERCEROS | E42: PEREIRA | F42: 42950 | G42: 66001000 Pereira | H42: C35 | I42: =VLOOKUP(H42,VALIDACIONES!$A$2:$B$138,2,0) -> No realizar la revisión técnico mecánica y de emisiones en los siguientes plazos o cuando aún portando los certificados correspondientes no cuenta con las siguientes condiciones tecnicomecánica y de emisiones contaminantes, además el vehiculo será inmovilizado.(verlistado) | J42: 368859 | K42: CAPACITACIÓN | N42: =MONTH(F42) -> 8 | O42: =YEAR(F42) -> 2017
A43: 1033679693 | B43: GABRIEL FERNANDO CORREDOR ALDANA | C43: EPM | D43: TERCEROS | E43: BOGOTA | F43: 42958 | G43: 11001000 Bogotá D.C. | H43: B10 | I43: =VLOOKUP(H43,VALIDACIONES!$A$2:$B$138,2,0) -> Conducirunvehículoconvidriospolarizados,entintadosuoscurecidos,sinportarelpermisorespectivo,deacuerdoalareglamentaciónexistenteo,nollevarelvehículodeserviciopúblicocolectivourbanoconlosvidriostransparentes. | J43: 98.3 | K43: CAPACITACIÓN | N43: =MONTH(F43) -> 8 | O43: =YEAR(F43) -> 2017
A44: 10139971 | B44: JAVIER DUQUE VARGAS | C44: TELEFONICA DE PEREIRA | D44: TERCEROS | E44: PEREIRA | F44: 42967 | G44: 76147000 Cartago | H44: C29 | I44: =VLOOKUP(H44,VALIDACIONES!$A$2:$B$138,2,0) -> Conducir un vehículo a velocidad superior a la máxima permitida, la cual deberá estar señalizada en forma sectorizada, no obstante esta no podrá ser superior a (verlistado) | J44: 368858 | K44: CAPACITACIÓN | N44: =MONTH(F44) -> 8 | O44: =YEAR(F44) -> 2017
A45: 1152191464 | B45: JUAN ESTEBAN GIRALDO RODRIGUEZ | C45: EPM | D45: TERCEROS | E45: MEDELLIN | F45: 42957 | G45: 54405000 Los Patios | H45: D04 | I45: =VLOOKUP(H45,VALIDACIONES!$A$2:$B$138,2,0) -> Nodetenerseanteunaluzrojaoamarilladesemáforo,unaseñalde"PARE"ounsemáforointermitenteenrojo.Enelcasodemotocicletaseprocederaasuinmovilizaciónhastatantonosepagueelvalordelamultaolaautoridadcompetentedecidasobresuimposicionenlosterminosdelosarticulos135y136delcódigonacionaldetránsito. | J45: 737717 | K45: CAPACITACIÓN | N45: =MONTH(F45) -> 8 | O45: =YEAR(F45) -> 2017
...
